Workbook
Name Home_edge: 'Offense Defense'!$G$1
Name mean: 'Offense Defense'!$G$2

Sheet Real23
F1: 2023 Season Rankings
B2: 0
A3: Mean: | B3: =AVERAGE(B6:B17) -> 2.2193465e-08 | F3: Home Edge: | G3: 3.3020813
O4: =SUM($O$6:$O300) -> 13811.341
A5: Team | B5: Rating | C5: Rank | G5: Rnd | H5: HomeTeam | I5: HomeScore | J5: AwayTeam | K5: AwayScore | M5: Home Margin | N5: Forecast | O5: Squared Error
A6: SD | B6: 15.754628 | C6: =RANK($B6,$B$6:$B$17,0) -> 1 | G6: 1 | H6: ATL | I6: 17 | J6: TOR | K6: 10 | M6: =$I6-$K6 -> 7 | N6: =$G$3+VLOOKUP($H6,$A$6:$B$17,2,FALSE)-VLOOKUP($J6,$A$6:$B$17,2,FALSE) -> 15.635417 | O6: =($M6-$N6)^2 -> 74.570426
A7: NEFJ | B7: 14.912036 | C7: =RANK($B7,$B$6:$B$17,0) -> 2 | G7: 1 | H7: NOLA | I7: 12 | J7: NEFJ | K7: 36 | M7: =$I7-$K7 -> -24 | N7: =$G$3+VLOOKUP($H7,$A$6:$B$17,2,FALSE)-VLOOKUP($J7,$A$6:$B$17,2,FALSE) -> -17.753467 | O7: =($M7-$N7)^2 -> 39.019171
A8: SEA | B8: 9.7546279 | C8: =RANK($B8,$B$6:$B$17,0) -> 3 | G8: 1 | H8: OGDC | I8: 42 | J8: CHI | K8: 27 | M8: =$I8-$K8 -> 15 | N8: =$G$3+VLOOKUP($H8,$A$6:$B$17,2,FALSE)-VLOOKUP($J8,$A$6:$B$17,2,FALSE) -> 9.1817234 | O8: =($M8-$N8)^2 -> 33.852342
A9: HOU | B9: 4.7546283 | C9: =RANK($B9,$B$6:$B$17,0) -> 4 | G9: 1 | H9: SD | I9: 33 | J9: UTA | K9: 17 | M9: =$I9-$K9 -> 16 | N9: =$G$3+VLOOKUP($H9,$A$6:$B$17,2,FALSE)-VLOOKUP($J9,$A$6:$B$17,2,FALSE) -> 16.913193 | O9: =($M9-$N9)^2 -> 0.83392085
A10: UTA | B10: 2.1435167 | C10: =RANK($B10,$B$6:$B$17,0) -> 5 | G10: 1 | H10: SEA | I10: 25 | J10: RUNY | K10: 11 | M10: =$I10-$K10 -> 14 | N10: =$G$3+VLOOKUP($H10,$A$6:$B$17,2,FALSE)-VLOOKUP($J10,$A$6:$B$17,2,FALSE) -> 11.589114 | O10: =($M10-$N10)^2 -> 5.812373
A11: RUNY | B11: 1.4675955 | C11: =RANK($B11,$B$6:$B$17,0) -> 6 | G11: 1 | H11: DAL | I11: 12 | J11: HOU | K11: 33 | M11: =$I11-$K11 -> -21 | N11: =$G$3+VLOOKUP($H11,$A$6:$B$17,2,FALSE)-VLOOKUP($J11,$A$6:$B$17,2,FALSE) -> -10.642362 | O11: =($M11-$N11)^2 -> 107.28067
A12: OGDC | B12: -2.7546217 | C12: =RANK($B12,$B$6:$B$17,0) -> 7 | G12: 2 | H12: SEA | I12: 28 | J12: ATL | K12: 22 | M12: =$I12-$K12 -> 6 | N12: =$G$3+VLOOKUP($H12,$A$6:$B$17,2,FALSE)-VLOOKUP($J12,$A$6:$B$17,2,FALSE) -> 17.922451 | O12: =($M12-$N12)^2 -> 142.14483
A13: ATL | B13: -4.8657416 | C13: =RANK($B13,$B$6:$B$17,0) -> 8 | G13: 2 | H13: UTA | I13: 33 | J13: DAL | K13: 25 | M13: =$I13-$K13 -> 8 | N13: =$G$3+VLOOKUP($H13,$A$6:$B$17,2,FALSE)-VLOOKUP($J13,$A$6:$B$17,2,FALSE) -> 14.635413 | O13: =($M13-$N13)^2 -> 44.028702
A14: NOLA | B14: -6.1435127 | C14: =RANK($B14,$B$6:$B$17,0) -> 9 | G14: 2 | H14: HOU | I14: 35 | J14: NOLA | K14: 14 | M14: =$I14-$K14 -> 21 | N14: =$G$3+VLOOKUP($H14,$A$6:$B$17,2,FALSE)-VLOOKUP($J14,$A$6:$B$17,2,FALSE) -> 14.200222 | O14: =($M14-$N14)^2 -> 46.236978
A15: CHI | B15: -8.6342639 | C15: =RANK($B15,$B$6:$B$17,0) -> 10 | G15: 2 | H15: RUNY | I15: 39 | J15: TOR | K15: 3 | M15: =$I15-$K15 -> 36 | N15: =$G$3+VLOOKUP($H15,$A$6:$B$17,2,FALSE)-VLOOKUP($J15,$A$6:$B$17,2,FALSE) -> 21.968754 | O15: =($M15-$N15)^2 -> 196.87586
A16: DAL | B16: -9.1898148 | C16: =RANK($B16,$B$6:$B$17,0) -> 11 | G16: 2 | H16: SD | I16: 29 | J16: NEFJ | K16: 12 | M16: =$I16-$K16 -> 17 | N16: =$G$3+VLOOKUP($H16,$A$6:$B$17,2,FALSE)-VLOOKUP($J16,$A$6:$B$17,2,FALSE) -> 4.1446735 | O16: =($M16-$N16)^2 -> 165.25942
A17: TOR | B17: -17.199077 | C17: =RANK($B17,$B$6:$B$17,0) -> 12 | G17: 3 | H17: DAL | I17: 10 | J17: SEA | K17: 35 | M17: =$I17-$K17 -> -25 | N17: =$G$3+VLOOKUP($H17,$A$6:$B$17,2,FALSE)-VLOOKUP($J17,$A$6:$B$17,2,FALSE) -> -15.642361 | O17: =($M17-$N17)^2 -> 87.565399
G18: 3 | H18: ATL | I18: 29 | J18: NOLA | K18: 16 | M18: =$I18-$K18 -> 13 | N18: =$G$3+VLOOKUP($H18,$A$6:$B$17,2,FALSE)-VLOOKUP($J18,$A$6:$B$17,2,FALSE) -> 4.5798524 | O18: =($M18-$N18)^2 -> 70.898886
G19: 3 | H19: CHI | I19: 10 | J19: UTA | K19: 14 | M19: =$I19-$K19 -> -4 | N19: =$G$3+VLOOKUP($H19,$A$6:$B$17,2,FALSE)-VLOOKUP($J19,$A$6:$B$17,2,FALSE) -> -7.4756993 | O19: =($M19-$N19)^2 -> 12.080485
G20: 3 | H20: HOU | I20: 31 | J20: SD | K20: 26 | M20: =$I20-$K20 -> 5 | N20: =$G$3+VLOOKUP($H20,$A$6:$B$17,2,FALSE)-VLOOKUP($J20,$A$6:$B$17,2,FALSE) -> -7.6979186 | O20: =($M20-$N20)^2 -> 161.23714
G21: 3 | H21: RUNY | I21: 34 | J21: OGDC | K21: 8 | M21: =$I21-$K21 -> 26 | N21: =$G$3+VLOOKUP($H21,$A$6:$B$17,2,FALSE)-VLOOKUP($J21,$A$6:$B$17,2,FALSE) -> 7.5242985 | O21: =($M21-$N21)^2 -> 341.35155
G22: 4 | H22: NEFJ | I22: 34 | J22: OGDC | K22: 31 | M22: =$I22-$K22 -> 3 | N22: =$G$3+VLOOKUP($H22,$A$6:$B$17,2,FALSE)-VLOOKUP($J22,$A$6:$B$17,2,FALSE) -> 20.968739 | O22: =($M22-$N22)^2 -> 322.87557
G23: 4 | H23: CHI | I23: 26 | J23: TOR | K23: 27 | M23: =$I23-$K23 -> -1 | N23: =$G$3+VLOOKUP($H23,$A$6:$B$17,2,FALSE)-VLOOKUP($J23,$A$6:$B$17,2,FALSE) -> 11.866895 | O23: =($M23-$N23)^2 -> 165.55698
G24: 4 | H24: SD | I24: 22 | J24: DAL | K24: 0 | M24: =$I24-$K24 -> 22 | N24: =$G$3+VLOOKUP($H24,$A$6:$B$17,2,FALSE)-VLOOKUP($J24,$A$6:$B$17,2,FALSE) -> 28.246524 | O24: =($M24-$N24)^2 -> 39.019064
G25: 4 | H25: SEA | I25: 24 | J25: HOU | K25: 12 | M25: =$I25-$K25 -> 12 | N25: =$G$3+VLOOKUP($H25,$A$6:$B$17,2,FALSE)-VLOOKUP($J25,$A$6:$B$17,2,FALSE) -> 8.3020809 | O25: =($M25-$N25)^2 -> 13.674606
G26: 4 | H26: NOLA | I26: 31 | J26: RUNY | K26: 5 | M26: =$I26-$K26 -> 26 | N26: =$G$3+VLOOKUP($H26,$A$6:$B$17,2,FALSE)-VLOOKUP($J26,$A$6:$B$17,2,FALSE) -> -4.309027 | O26: =($M26-$N26)^2 -> 918.63712
G27: 5 | H27: NOLA | I27: 37 | J27: UTA | K27: 14 | M27: =$I27-$K27 -> 23 | N27: =$G$3+VLOOKUP($H27,$A$6:$B$17,2,FALSE)-VLOOKUP($J27,$A$6:$B$17,2,FALSE) -> -4.9849481 | O27: =($M27-$N27)^2 -> 783.15732
G28: 5 | H28: ATL | I28: 10 | J28: SD | K28: 35 | M28: =$I28-$K28 -> -25 | N28: =$G$3+VLOOKUP($H28,$A$6:$B$17,2,FALSE)-VLOOKUP($J28,$A$6:$B$17,2,FALSE) -> -17.318288 | O28: =($M28-$N28)^2 -> 59.008693
G29: 5 | H29: CHI | I29: 24 | J29: DAL | K29: 22 | M29: =$I29-$K29 -> 2 | N29: =$G$3+VLOOKUP($H29,$A$6:$B$17,2,FALSE)-VLOOKUP($J29,$A$6:$B$17,2,FALSE) -> 3.8576322 | O29: =($M29-$N29)^2 -> 3.4507975
... G101: 18 | H101: SD | I101: 40 | J101: SEA | K101: 19 | M101: =$I101-$K101 -> 21 | N101: =$G$3+VLOOKUP($H101,$A$6:$B$17,2,FALSE)-VLOOKUP($J101,$A$6:$B$17,2,FALSE) -> 9.3020814 | O101: =($M101-$N101)^2 -> 136.8413

Sheet PosVsTeam23_BackRow
A1: Revamped Pos vs Team | F1: 2023 Season Rankings
B2: 0
A3: Mean: | B3: =AVERAGE(B6:B17) -> 7.8676884e-08 | F3: Home | G3: 0.83257468
F4: Away | G4: =-G3 -> -0.83257468
A5: Team | B5: Rating | C5: Rank | N5: =SUM($N$7:$N301) -> 1340.8045
A6: HOU | B6: -2.3098272 | C6: =RANK($B6,$B$6:$B$17,1) -> 1 | G6: Rnd | H6: Pos | I6: Player1 | J6: Player1_Points | K6: home | L6: Opp | M6: Forecast | N6: Squared Error
A7: OGDC | B7: -1.7595438 | C7: =RANK($B7,$B$6:$B$17,1) -> 2 | G7: 1 | H7: Back row | I7: Adriaan Booysen | J7: 19.6 | K7: Home | L7: HOU | M7: =VLOOKUP($K7,$F$3:$G$4,2,FALSE)+VLOOKUP($I7,$A$20:$B$24,2,FALSE)-VLOOKUP($L7,$A$6:$B$17,2,FALSE) -> 13.87235 | N7: =($J7-$M7)^2 -> 32.80598
A8: SEA | B8: -1.3291027 | C8: =RANK($B8,$B$6:$B$17,1) -> 3 | G8: 1 | H8: Back row | I8: Charles Elton | J8: 13.7 | K8: Home | L8: RUNY | M8: =VLOOKUP($K8,$F$3:$G$4,2,FALSE)+VLOOKUP($I8,$A$20:$B$24,2,FALSE)-VLOOKUP($L8,$A$6:$B$17,2,FALSE) -> 11.327387 | N8: =($J8-$M8)^2 -> 5.6292923
A9: TOR | B9: -0.51870236 | C9: =RANK($B9,$B$6:$B$17,1) -> 4 | G9: 1 | H9: Back row | I9: Jamason Fa'anana-Schultz | J9: 9.9 | K9: Home | L9: CHI | M9: =VLOOKUP($K9,$F$3:$G$4,2,FALSE)+VLOOKUP($I9,$A$20:$B$24,2,FALSE)-VLOOKUP($L9,$A$6:$B$17,2,FALSE) -> 9.8379158 | N9: =($J9-$M9)^2 -> 0.0038544493
A10: ATL | B10: -0.052720192 | C10: =RANK($B10,$B$6:$B$17,1) -> 5 | G10: 1 | H10: Back row | I10: Riekert Hattingh | J10: 9.7 | K10: Home | L10: RUNY | M10: =VLOOKUP($K10,$F$3:$G$4,2,FALSE)+VLOOKUP($I10,$A$20:$B$24,2,FALSE)-VLOOKUP($L10,$A$6:$B$17,2,FALSE) -> 14.802723 | N10: =($J10-$M10)^2 -> 26.037784
A11: NEFJ | B11: 0.12546469 | C11: =RANK($B11,$B$6:$B$17,1) -> 6 | G11: 1 | H11: Back row | I11: Wian Conradie | J11: 11.9 | K11: Away | L11: NOLA | M11: =VLOOKUP($K11,$F$3:$G$4,2,FALSE)+VLOOKUP($I11,$A$20:$B$24,2,FALSE)-VLOOKUP($L11,$A$6:$B$17,2,FALSE) -> 13.618689 | N11: =($J11-$M11)^2 -> 2.9538927
A12: SD | B12: 0.15948816 | C12: =RANK($B12,$B$6:$B$17,1) -> 7 | G12: 2 | H12: Back row | I12: Adriaan Booysen | J12: 6.7 | K12: Away | L12: UTA | M12: =VLOOKUP($K12,$F$3:$G$4,2,FALSE)+VLOOKUP($I12,$A$20:$B$24,2,FALSE)-VLOOKUP($L12,$A$6:$B$17,2,FALSE) -> 8.6318939 | N12: =($J12-$M12)^2 -> 3.7322139
A13: RUNY | B13: 0.23396844 | C13: =RANK($B13,$B$6:$B$17,1) -> 8 | G13: 2 | H13: Back row | I13: Charles Elton | J13: 6 | K13: Home | L13: ATL | M13: =VLOOKUP($K13,$F$3:$G$4,2,FALSE)+VLOOKUP($I13,$A$20:$B$24,2,FALSE)-VLOOKUP($L13,$A$6:$B$17,2,FALSE) -> 11.614076 | N13: =($J13-$M13)^2 -> 31.517845
A14: DAL | B14: 0.37270166 | C14: =RANK($B14,$B$6:$B$17,1) -> 9 | G14: 2 | H14: Back row | I14: Riekert Hattingh | J14: 22.7 | K14: Home | L14: ATL | M14: =VLOOKUP($K14,$F$3:$G$4,2,FALSE)+VLOOKUP($I14,$A$20:$B$24,2,FALSE)-VLOOKUP($L14,$A$6:$B$17,2,FALSE) -> 15.089412 | N14: =($J14-$M14)^2 -> 57.921053
A15: NOLA | B15: 0.39686671 | C15: =RANK($B15,$B$6:$B$17,1) -> 10 | G15: 2 | H15: Back row | I15: Wian Conradie | J15: 14.7 | K15: Away | L15: SD | M15: =VLOOKUP($K15,$F$3:$G$4,2,FALSE)+VLOOKUP($I15,$A$20:$B$24,2,FALSE)-VLOOKUP($L15,$A$6:$B$17,2,FALSE) -> 13.856068 | N15: =($J15-$M15)^2 -> 0.71222155
A16: UTA | B16: 1.265479 | C16: =RANK($B16,$B$6:$B$17,1) -> 11 | G16: 3 | H16: Back row | I16: Adriaan Booysen | J16: 13.3 | K16: Home | L16: SEA | M16: =VLOOKUP($K16,$F$3:$G$4,2,FALSE)+VLOOKUP($I16,$A$20:$B$24,2,FALSE)-VLOOKUP($L16,$A$6:$B$17,2,FALSE) -> 12.891625 | N16: =($J16-$M16)^2 -> 0.16677021
A17: CHI | B17: 3.4159285 | C17: =RANK($B17,$B$6:$B$17,1) -> 12 | G17: 3 | H17: Back row | I17: Charles Elton | J17: 11.9 | K17: Away | L17: DAL | M17: =VLOOKUP($K17,$F$3:$G$4,2,FALSE)+VLOOKUP($I17,$A$20:$B$24,2,FALSE)-VLOOKUP($L17,$A$6:$B$17,2,FALSE) -> 9.5235044 | N17: =($J17-$M17)^2 -> 5.6477312
G18: 3 | H18: Back row | I18: Jamason Fa'anana-Schultz | J18: 12 | K18: Away | L18: RUNY | M18: =VLOOKUP($K18,$F$3:$G$4,2,FALSE)+VLOOKUP($I18,$A$20:$B$24,2,FALSE)-VLOOKUP($L18,$A$6:$B$17,2,FALSE) -> 11.354726 | N18: =($J18-$M18)^2 -> 0.41637793
A19: Player | B19: Rating | G19: 3 | H19: Back row | I19: Riekert Hattingh | J19: 19.8 | K19: Away | L19: DAL | M19: =VLOOKUP($K19,$F$3:$G$4,2,FALSE)+VLOOKUP($I19,$A$20:$B$24,2,FALSE)-VLOOKUP($L19,$A$6:$B$17,2,FALSE) -> 12.998841 | N19: =($J19-$M19)^2 -> 46.255769
A20: Wian Conradie | B20: 14.848131 | G20: 4 | H20: Back row | I20: Adriaan Booysen | J20: 6.6 | K20: Away | L20: SD | M20: =VLOOKUP($K20,$F$3:$G$4,2,FALSE)+VLOOKUP($I20,$A$20:$B$24,2,FALSE)-VLOOKUP($L20,$A$6:$B$17,2,FALSE) -> 9.7378847 | N20: =($J20-$M20)^2 -> 9.8463206
A21: Riekert Hattingh | B21: 14.204117 | G21: 4 | H21: Back row | I21: Charles Elton | J21: 9.9 | K21: Home | L21: HOU | M21: =VLOOKUP($K21,$F$3:$G$4,2,FALSE)+VLOOKUP($I21,$A$20:$B$24,2,FALSE)-VLOOKUP($L21,$A$6:$B$17,2,FALSE) -> 13.871183 | N21: =($J21-$M21)^2 -> 15.770292
A22: Jamason Fa'anana-Schultz | B22: 12.42127 | G22: 4 | H22: Back row | I22: Jamason Fa'anana-Schultz | J22: 7.9 | K22: Away | L22: NEFJ | M22: =VLOOKUP($K22,$F$3:$G$4,2,FALSE)+VLOOKUP($I22,$A$20:$B$24,2,FALSE)-VLOOKUP($L22,$A$6:$B$17,2,FALSE) -> 11.46323 | N22: =($J22-$M22)^2 -> 12.69661
A23: Adriaan Booysen | B23: 10.729948 | G23: 4 | H23: Back row | I23: Riekert Hattingh | J23: 15.2 | K23: Home | L23: HOU | M23: =VLOOKUP($K23,$F$3:$G$4,2,FALSE)+VLOOKUP($I23,$A$20:$B$24,2,FALSE)-VLOOKUP($L23,$A$6:$B$17,2,FALSE) -> 17.346519 | N23: =($J23-$M23)^2 -> 4.6075433
A24: Charles Elton | B24: 10.728781 | G24: 4 | H24: Back row | I24: Wian Conradie | J24: 22.8 | K24: Home | L24: OGDC | M24: =VLOOKUP($K24,$F$3:$G$4,2,FALSE)+VLOOKUP($I24,$A$20:$B$24,2,FALSE)-VLOOKUP($L24,$A$6:$B$17,2,FALSE) -> 17.440249 | N24: =($J24-$M24)^2 -> 28.72693
G25: 5 | H25: Back row | I25: Adriaan Booysen | J25: 11.2 | K25: Away | L25: CHI | M25: =VLOOKUP($K25,$F$3:$G$4,2,FALSE)+VLOOKUP($I25,$A$20:$B$24,2,FALSE)-VLOOKUP($L25,$A$6:$B$17,2,FALSE) -> 6.4814444 | N25: =($J25-$M25)^2 -> 22.264767
G26: 5 | H26: Back row | I26: Jamason Fa'anana-Schultz | J26: 17.1 | K26: Home | L26: TOR | M26: =VLOOKUP($K26,$F$3:$G$4,2,FALSE)+VLOOKUP($I26,$A$20:$B$24,2,FALSE)-VLOOKUP($L26,$A$6:$B$17,2,FALSE) -> 13.772547 | N26: =($J26-$M26)^2 -> 11.071946
G27: 5 | H27: Back row | I27: Wian Conradie | J27: 11.2 | K27: Away | L27: RUNY | M27: =VLOOKUP($K27,$F$3:$G$4,2,FALSE)+VLOOKUP($I27,$A$20:$B$24,2,FALSE)-VLOOKUP($L27,$A$6:$B$17,2,FALSE) -> 13.781588 | N27: =($J27-$M27)^2 -> 6.6645941
G28: 6 | H28: Back row | I28: Adriaan Booysen | J28: 8.7 | K28: Away | L28: NEFJ | M28: =VLOOKUP($K28,$F$3:$G$4,2,FALSE)+VLOOKUP($I28,$A$20:$B$24,2,FALSE)-VLOOKUP($L28,$A$6:$B$17,2,FALSE) -> 9.7719082 | N28: =($J28-$M28)^2 -> 1.1489872
G29: 6 | H29: Back row | I29: Charles Elton | J29: 5.3 | K29: Away | L29: CHI | M29: =VLOOKUP($K29,$F$3:$G$4,2,FALSE)+VLOOKUP($I29,$A$20:$B$24,2,FALSE)-VLOOKUP($L29,$A$6:$B$17,2,FALSE) -> 6.4802776 | N29: =($J29-$M29)^2 -> 1.3930553
G30: 6 | H30: Back row | I30: Jamason Fa'anana-Schultz | J30: 12.6 | K30: Home | L30: NOLA | M30: =VLOOKUP($K30,$F$3:$G$4,2,FALSE)+VLOOKUP($I30,$A$20:$B$24,2,FALSE)-VLOOKUP($L30,$A$6:$B$17,2,FALSE) -> 12.856978 | N30: =($J30-$M30)^2 -> 0.066037463
G31: 6 | H31: Back row | I31: Riekert Hattingh | J31: 8.8 | K31: Away | L31: CHI | M31: =VLOOKUP($K31,$F$3:$G$4,2,FALSE)+VLOOKUP($I31,$A$20:$B$24,2,FALSE)-VLOOKUP($L31,$A$6:$B$17,2,FALSE) -> 9.9556138 | N31: =($J31-$M31)^2 -> 1.3354432
G32: 6 | H32: Back row | I32: Wian Conradie | J32: 16.1 | K32: Home | L32: DAL | M32: =VLOOKUP($K32,$F$3:$G$4,2,FALSE)+VLOOKUP($I32,$A$20:$B$24,2,FALSE)-VLOOKUP($L32,$A$6:$B$17,2,FALSE) -> 15.308004 | N32: =($J32-$M32)^2 -> 0.62725819
G33: 7 | H33: Back row | I33: Adriaan Booysen | J33: 13.5 | K33: Home | L33: TOR | M33: =VLOOKUP($K33,$F$3:$G$4,2,FALSE)+VLOOKUP($I33,$A$20:$B$24,2,FALSE)-VLOOKUP($L33,$A$6:$B$17,2,FALSE) -> 12.081225 | N33: =($J33-$M33)^2 -> 2.0129236
G34: 7 | H34: Back row | I34: Charles Elton | J34: 10.3 | K34: Away | L34: NOLA | M34: =VLOOKUP($K34,$F$3:$G$4,2,FALSE)+VLOOKUP($I34,$A$20:$B$24,2,FALSE)-VLOOKUP($L34,$A$6:$B$17,2,FALSE) -> 9.4993394 | N34: =($J34-$M34)^2 -> 0.64105742
G35: 7 | H35: Back row | I35: Jamason Fa'anana-Schultz | J35: 12.9 | K35: Away | L35: SD | M35: =VLOOKUP($K35,$F$3:$G$4,2,FALSE)+VLOOKUP($I35,$A$20:$B$24,2,FALSE)-VLOOKUP($L35,$A$6:$B$17,2,FALSE) -> 11.429207 | N35: =($J35-$M35)^2 -> 2.1632328
G36: 7 | H36: Back row | I36: Riekert Hattingh | J36: 5.9 | K36: Away | L36: NOLA | M36: =VLOOKUP($K36,$F$3:$G$4,2,FALSE)+VLOOKUP($I36,$A$20:$B$24,2,FALSE)-VLOOKUP($L36,$A$6:$B$17,2,FALSE) -> 12.974676 | N36: =($J36-$M36)^2 -> 50.051034
... G72: 17 | H72: Back row | I72: Charles Elton | J72: 15.5 | K72: Home | L72: NEFJ | M72: =VLOOKUP($K72,$F$3:$G$4,2,FALSE)+VLOOKUP($I72,$A$20:$B$24,2,FALSE)-VLOOKUP($L72,$A$6:$B$17,2,FALSE) -> 11.435891 | N72: =($J72-$M72)^2 -> 16.516984
G73: 18 | H73: Projection | I73: Wian Conradie | K73: Away | L73: NEFJ | M73: =VLOOKUP($K73,$F$3:$G$4,2,FALSE)+VLOOKUP($I73,$A$20:$B$24,2,FALSE)-VLOOKUP($L73,$A$6:$B$17,2,FALSE) -> 13.890091
I74: Jamason Fa'anana-Schultz | K74: Home | L74: TOR | M74: =VLOOKUP($K74,$F$3:$G$4,2,FALSE)+VLOOKUP($I74,$A$20:$B$24,2,FALSE)-VLOOKUP($L74,$A$6:$B$17,2,FALSE) -> 13.772547
I75: Adriaan Booysen | K75: Home | L75: OGDC | M75: =VLOOKUP($K75,$F$3:$G$4,2,FALSE)+VLOOKUP($I75,$A$20:$B$24,2,FALSE)-VLOOKUP($L75,$A$6:$B$17,2,FALSE) -> 13.322066
...

Sheet LouMaul
F1: 2024 Lou Maul Rankings
B2: 0
A3: Mean: | B3: =AVERAGE(B6:B15) -> 2.6693665e-07 | F3: Home Edge: | G3: n/a
O4: =SUM($O$6:$O300) -> 23411.623
A5: Team | B5: Power Rating | C5: Rank | G5: Rnd | H5: HomeTeam | I5: HomeScore | J5: AwayTeam | K5: AwayScore | M5: Home Margin | N5: Forecast | O5: Squared Error
A6: FB | B6: 33.576103 | C6: =RANK($B6,$B$6:$B$15,0) -> 1 | D6: Fighting Beavers | G6: 1 | H6: GS9 | I6: 19.6 | J6: LF | K6: 48 | M6: =$I6-$K6 -> -28.4 | N6: =VLOOKUP($H6,$A$6:$B$13,2,FALSE)-VLOOKUP($J6,$A$6:$B$13,2,FALSE) -> -29.281885 | O6: =($M6-$N6)^2 -> 0.77772139
A7: LF | B7: 10.656146 | C7: =RANK($B7,$B$6:$B$15,0) -> 2 | D7: Loose Forwards | G7: 1 | H7: Af7 | I7: 9.5 | J7: FB | K7: 84.9 | M7: =$I7-$K7 -> -75.4 | N7: =VLOOKUP($H7,$A$6:$B$13,2,FALSE)-VLOOKUP($J7,$A$6:$B$13,2,FALSE) -> -54.456498 | O7: =($M7-$N7)^2 -> 438.63028
A8: CC | B8: 9.8136785 | C8: =RANK($B8,$B$6:$B$15,0) -> 3 | D8: Chicago Carnivores | G8: 1 | H8: KK | I8: 33.1 | J8: CC | K8: 53.1 | M8: =$I8-$K8 -> -20 | N8: =VLOOKUP($H8,$A$6:$B$13,2,FALSE)-VLOOKUP($J8,$A$6:$B$13,2,FALSE) -> -7.773874 | O8: =($M8-$N8)^2 -> 149.47816
A9: KK | B9: 2.0398045 | C9: =RANK($B9,$B$6:$B$15,0) -> 4 | D9: Kankakee Kickers | G9: 1 | H9: PRC | I9: 57.7 | J9: BAC | K9: 49.9 | M9: =$I9-$K9 -> 7.8 | N9: =VLOOKUP($H9,$A$6:$B$13,2,FALSE)-VLOOKUP($J9,$A$6:$B$13,2,FALSE) -> -8.3734559 | O9: =($M9-$N9)^2 -> 261.58068
A10: BAC | B10: -4.1030697 | C10: =RANK($B10,$B$6:$B$15,0) -> 5 | D10: Bruins A.C. | G10: 2 | H10: GS9 | I10: 0 | J10: BAC | K10: 74.7 | M10: =$I10-$K10 -> -74.7 | N10: =VLOOKUP($H10,$A$6:$B$13,2,FALSE)-VLOOKUP($J10,$A$6:$B$13,2,FALSE) -> -14.522669 | O10: =($M10-$N10)^2 -> 3621.3111
A11: PRC | B11: -12.476526 | C11: =RANK($B11,$B$6:$B$15,0) -> 6 | D11: Petaluma Rugby Club | G11: 2 | H11: Af7 | I11: 0 | J11: LF | K11: 73.4 | M11: =$I11-$K11 -> -73.4 | N11: =VLOOKUP($H11,$A$6:$B$13,2,FALSE)-VLOOKUP($J11,$A$6:$B$13,2,FALSE) -> -31.536541 | O11: =($M11-$N11)^2 -> 1752.5492
A12: GS9 | B12: -18.625739 | C12: =RANK($B12,$B$6:$B$15,0) -> 7 | D12: GunslingerSunruns99 | G12: 2 | H12: KK | I12: 63.9 | J12: FB | K12: 109.9 | M12: =$I12-$K12 -> -46 | N12: =VLOOKUP($H12,$A$6:$B$13,2,FALSE)-VLOOKUP($J12,$A$6:$B$13,2,FALSE) -> -31.536298 | O12: =($M12-$N12)^2 -> 209.19867
A13: Af7 | B13: -20.880395 | C13: =RANK($B13,$B$6:$B$15,0) -> 8 | D13: Atlantafan07 | G13: 2 | H13: PRC | I13: 58.5 | J13: CC | K13: 66.8 | M13: =$I13-$K13 -> -8.3 | N13: =VLOOKUP($H13,$A$6:$B$13,2,FALSE)-VLOOKUP($J13,$A$6:$B$13,2,FALSE) -> -22.290204 | O13: =($M13-$N13)^2 -> 195.72581
G14: 3 | H14: GS9 | I14: 44.3 | J14: FB | K14: 91.6 | M14: =$I14-$K14 -> -47.3 | N14: =VLOOKUP($H14,$A$6:$B$13,2,FALSE)-VLOOKUP($J14,$A$6:$B$13,2,FALSE) -> -52.201842 | O14: =($M14-$N14)^2 -> 24.028053
G15: 3 | H15: Af7 | I15: 51.2 | J15: CC | K15: 77.5 | M15: =$I15-$K15 -> -26.3 | N15: =VLOOKUP($H15,$A$6:$B$13,2,FALSE)-VLOOKUP($J15,$A$6:$B$13,2,FALSE) -> -30.694074 | O15: =($M15-$N15)^2 -> 19.307884
B16: Last_rnk | C16: New_rnk | D16: Change | G16: 3 | H16: KK | I16: 80.3 | J16: BAC | K16: 55.6 | M16: =$I16-$K16 -> 24.7 | N16: =VLOOKUP($H16,$A$6:$B$13,2,FALSE)-VLOOKUP($J16,$A$6:$B$13,2,FALSE) -> 6.1428742 | O16: =($M16-$N16)^2 -> 344.36692
A17: Fighting Beavers | B17: 1 | C17: 1 | D17: =C17-B17 -> 0 | G17: 3 | H17: PRC | I17: 82.5 | J17: LF | K17: 61 | M17: =$I17-$K17 -> 21.5 | N17: =VLOOKUP($H17,$A$6:$B$13,2,FALSE)-VLOOKUP($J17,$A$6:$B$13,2,FALSE) -> -23.132672 | O17: =($M17-$N17)^2 -> 1992.0754
A18: Loose Forwards | B18: 2 | C18: 2 | D18: =C18-B18 -> 0 | G18: 4 | H18: CC | I18: 74.1 | J18: GS9 | K18: 59.7 | M18: =$I18-$K18 -> 14.4 | N18: =VLOOKUP($H18,$A$6:$B$13,2,FALSE)-VLOOKUP($J18,$A$6:$B$13,2,FALSE) -> 28.439418 | O18: =($M18-$N18)^2 -> 197.10525
A19: Chicago Carnivores | B19: 3 | C19: 3 | D19: =C19-B19 -> 0 | G19: 4 | H19: BAC | I19: 60.8 | J19: Af7 | K19: 60.8 | M19: =$I19-$K19 -> 0 | N19: =VLOOKUP($H19,$A$6:$B$13,2,FALSE)-VLOOKUP($J19,$A$6:$B$13,2,FALSE) -> 16.777326 | O19: =($M19-$N19)^2 -> 281.47865
A20: Kankakee Kickers | B20: 4 | C20: 4 | D20: =C20-B20 -> 0 | G20: 4 | H20: LF | I20: 72.5 | J20: KK | K20: 37.5 | M20: =$I20-$K20 -> 35 | N20: =VLOOKUP($H20,$A$6:$B$13,2,FALSE)-VLOOKUP($J20,$A$6:$B$13,2,FALSE) -> 8.6163415 | O20: =($M20-$N20)^2 -> 696.09744
A21: Bruins A.C. | B21: 5 | C21: 5 | D21: =C21-B21 -> 0 | G21: 4 | H21: FB | I21: 109.5 | J21: PRC | K21: 55.9 | M21: =$I21-$K21 -> 53.6 | N21: =VLOOKUP($H21,$A$6:$B$13,2,FALSE)-VLOOKUP($J21,$A$6:$B$13,2,FALSE) -> 46.052628 | O21: =($M21-$N21)^2 -> 56.96282
A22: Petaluma Rugby Club | B22: 6 | C22: 6 | D22: =C22-B22 -> 0 | G22: 5 | H22: CC | I22: 92.6 | J22: FB | K22: 90 | M22: =$I22-$K22 -> 2.6 | N22: =VLOOKUP($H22,$A$6:$B$13,2,FALSE)-VLOOKUP($J22,$A$6:$B$13,2,FALSE) -> -23.762424 | O22: =($M22-$N22)^2 -> 694.97741
A23: GunslingerSunruns99 | B23: 7 | C23: 7 | D23: =C23-B23 -> 0 | G23: 5 | H23: BAC | I23: 82.2 | J23: LF | K23: 68.1 | M23: =$I23-$K23 -> 14.1 | N23: =VLOOKUP($H23,$A$6:$B$13,2,FALSE)-VLOOKUP($J23,$A$6:$B$13,2,FALSE) -> -14.759216 | O23: =($M23-$N23)^2 -> 832.85433
A24: Atlantafan07 | B24: 8 | C24: 8 | D24: =C24-B24 -> 0 | G24: 5 | H24: GS9 | I24: 50.6 | J24: KK | K24: 17.5 | M24: =$I24-$K24 -> 33.1 | N24: =VLOOKUP($H24,$A$6:$B$13,2,FALSE)-VLOOKUP($J24,$A$6:$B$13,2,FALSE) -> -20.665544 | O24: =($M24-$N24)^2 -> 2890.7337
G25: 5 | H25: Af7 | I25: 18.2 | J25: PRC | K25: 35 | M25: =$I25-$K25 -> -16.8 | N25: =VLOOKUP($H25,$A$6:$B$13,2,FALSE)-VLOOKUP($J25,$A$6:$B$13,2,FALSE) -> -8.4038696 | O25: =($M25-$N25)^2 -> 70.495005
G26: 6 | H26: CC | I26: 100.8 | J26: Af7 | K26: 66.1 | M26: =$I26-$K26 -> 34.7 | N26: =VLOOKUP($H26,$A$6:$B$13,2,FALSE)-VLOOKUP($J26,$A$6:$B$13,2,FALSE) -> 30.694074 | O26: =($M26-$N26)^2 -> 16.047445
G27: 6 | H27: BAC | I27: 57.3 | J27: KK | K27: 116.8 | M27: =$I27-$K27 -> -59.5 | N27: =VLOOKUP($H27,$A$6:$B$13,2,FALSE)-VLOOKUP($J27,$A$6:$B$13,2,FALSE) -> -6.1428742 | O27: =($M27-$N27)^2 -> 2846.9829
G28: 6 | H28: LF | I28: 58 | J28: PRC | K28: 0 | M28: =$I28-$K28 -> 58 | N28: =VLOOKUP($H28,$A$6:$B$13,2,FALSE)-VLOOKUP($J28,$A$6:$B$13,2,FALSE) -> 23.132672 | O28: =($M28-$N28)^2 -> 1215.7306
G29: 6 | H29: FB | I29: 88.9 | J29: GS9 | K29: 19.3 | M29: =$I29-$K29 -> 69.6 | N29: =VLOOKUP($H29,$A$6:$B$13,2,FALSE)-VLOOKUP($J29,$A$6:$B$13,2,FALSE) -> 52.201842 | O29: =($M29-$N29)^2 -> 302.69591
G30: 7 | H30: GS9 | I30: 52.8 | J30: LF | K30: 62 | M30: =$I30-$K30 -> -9.2 | N30: =VLOOKUP($H30,$A$6:$B$13,2,FALSE)-VLOOKUP($J30,$A$6:$B$13,2,FALSE) -> -29.281885 | O30: =($M30-$N30)^2 -> 403.28211
G31: 7 | H31: Af7 | I31: 58.8 | J31: FB | K31: 87.7 | M31: =$I31-$K31 -> -28.9 | N31: =VLOOKUP($H31,$A$6:$B$13,2,FALSE)-VLOOKUP($J31,$A$6:$B$13,2,FALSE) -> -54.456498 | O31: =($M31-$N31)^2 -> 653.13459
G32: 7 | H32: KK | I32: 116.1 | J32: CC | K32: 91.2 | M32: =$I32-$K32 -> 24.9 | N32: =VLOOKUP($H32,$A$6:$B$13,2,FALSE)-VLOOKUP($J32,$A$6:$B$13,2,FALSE) -> -7.773874 | O32: =($M32-$N32)^2 -> 1067.582
G33: 7 | H33: PRC | I33: 45.3 | J33: BAC | K33: 86.5 | M33: =$I33-$K33 -> -41.2 | N33: =VLOOKUP($H33,$A$6:$B$13,2,FALSE)-VLOOKUP($J33,$A$6:$B$13,2,FALSE) -> -8.3734559 | O33: =($M33-$N33)^2 -> 1077.582
G34: 8 | H34: GS9 | I34: 54.4 | J34: CC | K34: 97.6 | M34: =$I34-$K34 -> -43.2 | N34: =VLOOKUP($H34,$A$6:$B$13,2,FALSE)-VLOOKUP($J34,$A$6:$B$13,2,FALSE) -> -28.439418 | O34: =($M34-$N34)^2 -> 217.87479
G35: 8 | H35: Af7 | I35: 73.3 | J35: BAC | K35: 83.4 | M35: =$I35-$K35 -> -10.1 | N35: =VLOOKUP($H35,$A$6:$B$13,2,FALSE)-VLOOKUP($J35,$A$6:$B$13,2,FALSE) -> -16.777326 | O35: =($M35-$N35)^2 -> 44.586677
G36: 8 | H36: KK | I36: 64.7 | J36: LF | K36: 72.4 | M36: =$I36-$K36 -> -7.7 | N36: =VLOOKUP($H36,$A$6:$B$13,2,FALSE)-VLOOKUP($J36,$A$6:$B$13,2,FALSE) -> -8.6163415 | O36: =($M36-$N36)^2 -> 0.83968173
... G41: 9.2058824 | H41: Af7 | I41: 59.7 | J41: PRC | K41: 46.3 | M41: =$I41-$K41 -> 13.4 | N41: =VLOOKUP($H41,$A$6:$B$13,2,FALSE)-VLOOKUP($J41,$A$6:$B$13,2,FALSE) -> -8.4038696 | O41: =($M41-$N41)^2 -> 475.40873
G42: 9.6764706
G43: 9.9117647
G44: 10.147059
...

Sheet TheoreticalLambdaHistory
A1: Revamped Pos vs Team | F1: 2023 Season Rankings
B2: 0
A3: Mean: | B3: =AVERAGE(B6:B17) -> 7.8676884e-08 | F3: Home | G3: 0.83257468
F4: Away | G4: =-G3 -> -0.83257468
A5: Team | B5: Rating | C5: Rank | N5: =SUM($N$7:$N301) -> 223.64711 | Q5: Lambda | R5: 0.9
A6: HOU | B6: -2.3098272 | C6: =RANK($B6,$B$6:$B$17,1) -> 1 | G6: Rnd | H6: Pos | I6: Player1 | J6: Player1_Points | K6: home | L6: Opp | M6: Forecast | N6: Squared Error
A7: OGDC | B7: -1.7595438 | C7: =RANK($B7,$B$6:$B$17,1) -> 2 | G7: 1 | H7: Back row | I7: Adriaan Booysen | J7: 19.6 | K7: Home | L7: HOU | M7: =VLOOKUP($K7,$F$3:$G$4,2,FALSE)+VLOOKUP($I7,$A$20:$B$24,2,FALSE)-VLOOKUP($L7,$A$6:$B$17,2,FALSE) -> 13.87235 | N7: =($J7-$M7)^2 -> 32.80598
A8: SEA | B8: -1.3291027 | C8: =RANK($B8,$B$6:$B$17,1) -> 3 | G8: 1 | H8: Back row | I8: Charles Elton | J8: 13.7 | K8: Home | L8: RUNY | M8: =VLOOKUP($K8,$F$3:$G$4,2,FALSE)+VLOOKUP($I8,$A$20:$B$24,2,FALSE)-VLOOKUP($L8,$A$6:$B$17,2,FALSE) -> 11.327387 | N8: =($J8-$M8)^2 -> 5.6292923 | R8: Weeks removed | S8: 1 | T8: 2 | U8: 3
A9: TOR | B9: -0.51870236 | C9: =RANK($B9,$B$6:$B$17,1) -> 4 | G9: 1 | H9: Back row | I9: Jamason Fa'anana-Schultz | J9: 9.9 | K9: Home | L9: CHI | M9: =VLOOKUP($K9,$F$3:$G$4,2,FALSE)+VLOOKUP($I9,$A$20:$B$24,2,FALSE)-VLOOKUP($L9,$A$6:$B$17,2,FALSE) -> 9.8379158 | N9: =($J9-$M9)^2 -> 0.0038544493
A10: ATL | B10: -0.052720192 | C10: =RANK($B10,$B$6:$B$17,1) -> 5 | G10: 1 | H10: Back row | I10: Riekert Hattingh | J10: 9.7 | K10: Home | L10: RUNY | M10: =VLOOKUP($K10,$F$3:$G$4,2,FALSE)+VLOOKUP($I10,$A$20:$B$24,2,FALSE)-VLOOKUP($L10,$A$6:$B$17,2,FALSE) -> 14.802723 | N10: =($J10-$M10)^2 -> 26.037784 | Q10: Proj. | R10: Week10 | S10: Week9 | T10: Week8 | U10: Week7 | V10: etc
A11: NEFJ | B11: 0.12546469 | C11: =RANK($B11,$B$6:$B$17,1) -> 6 | G11: 1 | H11: Back row | I11: Wian Conradie | J11: 11.9 | K11: Away | L11: NOLA | M11: =VLOOKUP($K11,$F$3:$G$4,2,FALSE)+VLOOKUP($I11,$A$20:$B$24,2,FALSE)-VLOOKUP($L11,$A$6:$B$17,2,FALSE) -> 13.618689 | N11: =($J11-$M11)^2 -> 2.9538927 | Q11: Player A | S11: =S$17*($R$5)^S$8 -> 8.82 | T11: =T$17*($R$5)^T$8 -> 4.05 | U11: =U$17*($R$5)^U$8 -> 18.225
A12: SD | B12: 0.15948816 | C12: =RANK($B12,$B$6:$B$17,1) -> 7 | G12: 2 | H12: Back row | I12: Adriaan Booysen | J12: 6.7 | K12: Away | L12: UTA | M12: =VLOOKUP($K12,$F$3:$G$4,2,FALSE)+VLOOKUP($I12,$A$20:$B$24,2,FALSE)-VLOOKUP($L12,$A$6:$B$17,2,FALSE) -> 8.6318939 | N12: =($J12-$M12)^2 -> 3.7322139
A13: RUNY | B13: 0.23396844 | C13: =RANK($B13,$B$6:$B$17,1) -> 8 | G13: 2 | H13: Back row | I13: Charles Elton | J13: 6 | K13: Home | L13: ATL | M13: =VLOOKUP($K13,$F$3:$G$4,2,FALSE)+VLOOKUP($I13,$A$20:$B$24,2,FALSE)-VLOOKUP($L13,$A$6:$B$17,2,FALSE) -> 11.614076 | N13: =($J13-$M13)^2 -> 31.517845
A14: DAL | B14: 0.37270166 | C14: =RANK($B14,$B$6:$B$17,1) -> 9 | G14: 2 | H14: Back row | I14: Riekert Hattingh | J14: 22.7 | K14: Home | L14: ATL | M14: =VLOOKUP($K14,$F$3:$G$4,2,FALSE)+VLOOKUP($I14,$A$20:$B$24,2,FALSE)-VLOOKUP($L14,$A$6:$B$17,2,FALSE) -> 15.089412 | N14: =($J14-$M14)^2 -> 57.921053
A15: NOLA | B15: 0.39686671 | C15: =RANK($B15,$B$6:$B$17,1) -> 10 | G15: 2 | H15: Back row | I15: Wian Conradie | J15: 14.7 | K15: Away | L15: SD | M15: =VLOOKUP($K15,$F$3:$G$4,2,FALSE)+VLOOKUP($I15,$A$20:$B$24,2,FALSE)-VLOOKUP($L15,$A$6:$B$17,2,FALSE) -> 13.856068 | N15: =($J15-$M15)^2 -> 0.71222155
A16: UTA | B16: 1.265479 | C16: =RANK($B16,$B$6:$B$17,1) -> 11 | G16: 3 | H16: Back row | I16: Adriaan Booysen | J16: 13.3 | K16: Home | L16: SEA | M16: =VLOOKUP($K16,$F$3:$G$4,2,FALSE)+VLOOKUP($I16,$A$20:$B$24,2,FALSE)-VLOOKUP($L16,$A$6:$B$17,2,FALSE) -> 12.891625 | N16: =($J16-$M16)^2 -> 0.16677021 | Q16: Real | S16: Week 9 | T16: Week 8 | U16: Week 7
A17: CHI | B17: 3.4159285 | C17: =RANK($B17,$B$6:$B$17,1) -> 12 | G17: 3 | H17: Back row | I17: Charles Elton | J17: 11.9 | K17: Away | L17: DAL | M17: =VLOOKUP($K17,$F$3:$G$4,2,FALSE)+VLOOKUP($I17,$A$20:$B$24,2,FALSE)-VLOOKUP($L17,$A$6:$B$17,2,FALSE) -> 9.5235044 | N17: =($J17-$M17)^2 -> 5.6477312 | Q17: Player A | S17: 9.8 | T17: 5 | U17: 25
G18: 3 | H18: Back row | I18: Jamason Fa'anana-Schultz | J18: 12 | K18: Away | L18: RUNY | M18: =VLOOKUP($K18,$F$3:$G$4,2,FALSE)+VLOOKUP($I18,$A$20:$B$24,2,FALSE)-VLOOKUP($L18,$A$6:$B$17,2,FALSE) -> 11.354726 | N18: =($J18-$M18)^2 -> 0.41637793
A19: Player | B19: Rating | G19: 3 | H19: Back row | I19: Riekert Hattingh | J19: 19.8 | K19: Away | L19: DAL | M19: =VLOOKUP($K19,$F$3:$G$4,2,FALSE)+VLOOKUP($I19,$A$20:$B$24,2,FALSE)-VLOOKUP($L19,$A$6:$B$17,2,FALSE) -> 12.998841 | N19: =($J19-$M19)^2 -> 46.255769
A20: Wian Conradie | B20: 14.848131 | G20: 4 | H20: Back row | I20: Adriaan Booysen | J20: 6.6 | K20: Away | L20: SD | M20: =VLOOKUP($K20,$F$3:$G$4,2,FALSE)+VLOOKUP($I20,$A$20:$B$24,2,FALSE)-VLOOKUP($L20,$A$6:$B$17,2,FALSE) -> 9.7378847 | N20: =($J20-$M20)^2 -> 9.8463206
A21: Riekert Hattingh | B21: 14.204117 | I21: Wian Conradie | K21: Home | L21: SD | M21: =VLOOKUP($K21,$F$3:$G$4,2,FALSE)+VLOOKUP($I21,$A$20:$B$24,2,FALSE)-VLOOKUP($L21,$A$6:$B$17,2,FALSE) -> 15.521217
A22: Jamason Fa'anana-Schultz | B22: 12.42127 | I22: Wian Conradie | K22: Away | L22: CHI | M22: =VLOOKUP($K22,$F$3:$G$4,2,FALSE)+VLOOKUP($I22,$A$20:$B$24,2,FALSE)-VLOOKUP($L22,$A$6:$B$17,2,FALSE) -> 10.599627
A23: Adriaan Booysen | B23: 10.729948 | I23: Riekert Hattingh | K23: Home | L23: NOLA | M23: =VLOOKUP($K23,$F$3:$G$4,2,FALSE)+VLOOKUP($I23,$A$20:$B$24,2,FALSE)-VLOOKUP($L23,$A$6:$B$17,2,FALSE) -> 14.639825
A24: Charles Elton | B24: 10.728781 | I24: Riekert Hattingh | K24: Away | L24: RUNY | M24: =VLOOKUP($K24,$F$3:$G$4,2,FALSE)+VLOOKUP($I24,$A$20:$B$24,2,FALSE)-VLOOKUP($L24,$A$6:$B$17,2,FALSE) -> 13.137574

Sheet Strength of Schedule
A5: Team | B5: Rating | G5: Date | H5: Visitor | I5: Visitor Score | J5: Home | K5: Home Score | M5: Visitor_Rating | N5: Home_rating
A6: HOU | B6: =Real24!$B6 -> 12.180326 | C6: =(SUMIF($J$6:$J$101, $A6, $M$6:$M$101)+SUMIF($H$6:$H$101, $A6, $N$6:$N$101))/18 -> 0.83712612 | G6: 45353 | H6: OGDC | I6: 6 | J6: NOLA | K6: 18 | M6: =VLOOKUP($H6,$A$6:$B$17,2,FALSE) -> -6.1462022 | N6: =VLOOKUP($J6,$A$6:$B$17,2,FALSE) -> -3.3224811
A7: SEA | B7: =Real24!$B7 -> 8.46717 | C7: =(SUMIF($J$6:$J$101, $A7, $M$6:$M$101)+SUMIF($H$6:$H$101, $A7, $N$6:$N$101))/18 -> 1.249699 | G7: 45353 | H7: UTA | I7: 15 | J7: HOU | K7: 22 | M7: =VLOOKUP($H7,$A$6:$B$17,2,FALSE) -> 4.4024108 | N7: =VLOOKUP($J7,$A$6:$B$17,2,FALSE) -> 12.180326
A8: SD | B8: =Real24!$B8 -> 8.372361 | C8: =(SUMIF($J$6:$J$101, $A8, $M$6:$M$101)+SUMIF($H$6:$H$101, $A8, $N$6:$N$101))/18 -> 1.2602334 | G8: 45353 | H8: SD | I8: 19 | J8: SEA | K8: 25 | M8: =VLOOKUP($H8,$A$6:$B$17,2,FALSE) -> 8.372361 | N8: =VLOOKUP($J8,$A$6:$B$17,2,FALSE) -> 8.46717
A9: UTA | B9: =Real24!$B9 -> 4.4024108 | C9: =(SUMIF($J$6:$J$101, $A9, $M$6:$M$101)+SUMIF($H$6:$H$101, $A9, $N$6:$N$101))/18 -> 1.7013389 | G9: 45354 | H9: CHI | I9: 23 | J9: MIA | K9: 19 | M9: =VLOOKUP($H9,$A$6:$B$17,2,FALSE) -> -5.8840587 | N9: =VLOOKUP($J9,$A$6:$B$17,2,FALSE) -> 0.24500384
A10: DAL | B10: =Real24!$B10 -> 3.9324623 | C10: =(SUMIF($J$6:$J$101, $A10, $M$6:$M$101)+SUMIF($H$6:$H$101, $A10, $N$6:$N$101))/18 -> 1.7535554 | G10: 45354 | H10: NEFJ | I10: 46 | J10: ARC | K10: 13 | M10: =VLOOKUP($H10,$A$6:$B$17,2,FALSE) -> 1.8330672 | N10: =VLOOKUP($J10,$A$6:$B$17,2,FALSE) -> -26.154251
A11: RFCLA | B11: =Real24!$B11 -> 2.0741921 | C11: =(SUMIF($J$6:$J$101, $A11, $M$6:$M$101)+SUMIF($H$6:$H$101, $A11, $N$6:$N$101))/18 -> 1.9600299 | G11: 45354 | H11: DAL | I11: 32 | J11: RFCLA | K11: 29 | M11: =VLOOKUP($H11,$A$6:$B$17,2,FALSE) -> 3.9324623 | N11: =VLOOKUP($J11,$A$6:$B$17,2,FALSE) -> 2.0741921
A12: NEFJ | B12: =Real24!$B12 -> 1.8330672 | C12: =(SUMIF($J$6:$J$101, $A12, $M$6:$M$101)+SUMIF($H$6:$H$101, $A12, $N$6:$N$101))/18 -> -2.3941698 | G12: 45360 | H12: OGDC | I12: 35 | J12: NEFJ | K12: 34 | M12: =VLOOKUP($H12,$A$6:$B$17,2,FALSE) -> -6.1462022 | N12: =VLOOKUP($J12,$A$6:$B$17,2,FALSE) -> 1.8330672
A13: MIA | B13: =Real24!$B13 -> 0.24500384 | C13: =(SUMIF($J$6:$J$101, $A13, $M$6:$M$101)+SUMIF($H$6:$H$101, $A13, $N$6:$N$101))/18 -> -2.2177183 | G13: 45360 | H13: ARC | I13: 19 | J13: NOLA | K13: 34 | M13: =VLOOKUP($H13,$A$6:$B$17,2,FALSE) -> -26.154251 | N13: =VLOOKUP($J13,$A$6:$B$17,2,FALSE) -> -3.3224811
A14: NOLA | B14: =Real24!$B14 -> -3.3224811 | C14: =(SUMIF($J$6:$J$101, $A14, $M$6:$M$101)+SUMIF($H$6:$H$101, $A14, $N$6:$N$101))/18 -> -1.8213311 | G14: 45360 | H14: CHI | I14: 15 | J14: UTA | K14: 29 | M14: =VLOOKUP($H14,$A$6:$B$17,2,FALSE) -> -5.8840587 | N14: =VLOOKUP($J14,$A$6:$B$17,2,FALSE) -> 4.4024108
A15: CHI | B15: =Real24!$B15 -> -5.8840587 | C15: =(SUMIF($J$6:$J$101, $A15, $M$6:$M$101)+SUMIF($H$6:$H$101, $A15, $N$6:$N$101))/18 -> -1.5367114 | G15: 45360 | H15: MIA | I15: 18 | J15: SEA | K15: 29 | M15: =VLOOKUP($H15,$A$6:$B$17,2,FALSE) -> 0.24500384 | N15: =VLOOKUP($J15,$A$6:$B$17,2,FALSE) -> 8.46717
A16: OGDC | B16: =Real24!$B16 -> -6.1462022 | C16: =(SUMIF($J$6:$J$101, $A16, $M$6:$M$101)+SUMIF($H$6:$H$101, $A16, $N$6:$N$101))/18 -> -1.5075843 | G16: 45361 | H16: SD | I16: 30 | J16: DAL | K16: 23 | M16: =VLOOKUP($H16,$A$6:$B$17,2,FALSE) -> 8.372361 | N16: =VLOOKUP($J16,$A$6:$B$17,2,FALSE) -> 3.9324623
A17: ARC | B17: =Real24!$B17 -> -26.154251 | C17: =(SUMIF($J$6:$J$101, $A17, $M$6:$M$101)+SUMIF($H$6:$H$101, $A17, $N$6:$N$101))/18 -> 0.71553225 | G17: 45361 | H17: HOU | I17: 27 | J17: RFCLA | K17: 12 | M17: =VLOOKUP($H17,$A$6:$B$17,2,FALSE) -> 12.180326 | N17: =VLOOKUP($J17,$A$6:$B$17,2,FALSE) -> 2.0741921
G18: 45367 | H18: NOLA | I18: 21 | J18: NEFJ | K18: 27 | M18: =VLOOKUP($H18,$A$6:$B$17,2,FALSE) -> -3.3224811 | N18: =VLOOKUP($J18,$A$6:$B$17,2,FALSE) -> 1.8330672
G19: 45367 | H19: CHI | I19: 22 | J19: OGDC | K19: 22 | M19: =VLOOKUP($H19,$A$6:$B$17,2,FALSE) -> -5.8840587 | N19: =VLOOKUP($J19,$A$6:$B$17,2,FALSE) -> -6.1462022
G20: 45367 | H20: MIA | I20: 19 | J20: HOU | K20: 30 | M20: =VLOOKUP($H20,$A$6:$B$17,2,FALSE) -> 0.24500384 | N20: =VLOOKUP($J20,$A$6:$B$17,2,FALSE) -> 12.180326
G21: 45367 | H21: SEA | I21: 23 | J21: UTA | K21: 13 | M21: =VLOOKUP($H21,$A$6:$B$17,2,FALSE) -> 8.46717 | N21: =VLOOKUP($J21,$A$6:$B$17,2,FALSE) -> 4.4024108
G22: 45367 | H22: RFCLA | I22: 18 | J22: SD | K22: 19 | M22: =VLOOKUP($H22,$A$6:$B$17,2,FALSE) -> 2.0741921 | N22: =VLOOKUP($J22,$A$6:$B$17,2,FALSE) -> 8.372361
G23: 45368 | H23: DAL | I23: 68 | J23: ARC | K23: 28 | M23: =VLOOKUP($H23,$A$6:$B$17,2,FALSE) -> 3.9324623 | N23: =VLOOKUP($J23,$A$6:$B$17,2,FALSE) -> -26.154251
G24: 45373 | H24: HOU | J24: SEA | M24: =VLOOKUP($H24,$A$6:$B$17,2,FALSE) -> 12.180326 | N24: =VLOOKUP($J24,$A$6:$B$17,2,FALSE) -> 8.46717
G25: 45374 | H25: SD | J25: OGDC | M25: =VLOOKUP($H25,$A$6:$B$17,2,FALSE) -> 8.372361 | N25: =VLOOKUP($J25,$A$6:$B$17,2,FALSE) -> -6.1462022
G26: 45374 | H26: ARC | J26: MIA | M26: =VLOOKUP($H26,$A$6:$B$17,2,FALSE) -> -26.154251 | N26: =VLOOKUP($J26,$A$6:$B$17,2,FALSE) -> 0.24500384
G27: 45374 | H27: NOLA | J27: DAL | M27: =VLOOKUP($H27,$A$6:$B$17,2,FALSE) -> -3.3224811 | N27: =VLOOKUP($J27,$A$6:$B$17,2,FALSE) -> 3.9324623
G28: 45375 | H28: NEFJ | J28: CHI | M28: =VLOOKUP($H28,$A$6:$B$17,2,FALSE) -> 1.8330672 | N28: =VLOOKUP($J28,$A$6:$B$17,2,FALSE) -> -5.8840587
G29: 45375 | H29: UTA | J29: RFCLA | M29: =VLOOKUP($H29,$A$6:$B$17,2,FALSE) -> 4.4024108 | N29: =VLOOKUP($J29,$A$6:$B$17,2,FALSE) -> 2.0741921
G30: 45380 | H30: HOU | J30: DAL | M30: =VLOOKUP($H30,$A$6:$B$17,2,FALSE) -> 12.180326 | N30: =VLOOKUP($J30,$A$6:$B$17,2,FALSE) -> 3.9324623
G31: 45381 | H31: SEA | J31: CHI | M31: =VLOOKUP($H31,$A$6:$B$17,2,FALSE) -> 8.46717 | N31: =VLOOKUP($J31,$A$6:$B$17,2,FALSE) -> -5.8840587
G32: 45381 | H32: OGDC | J32: ARC | M32: =VLOOKUP($H32,$A$6:$B$17,2,FALSE) -> -6.1462022 | N32: =VLOOKUP($J32,$A$6:$B$17,2,FALSE) -> -26.154251
G33: 45382 | H33: SD | J33: MIA | M33: =VLOOKUP($H33,$A$6:$B$17,2,FALSE) -> 8.372361 | N33: =VLOOKUP($J33,$A$6:$B$17,2,FALSE) -> 0.24500384
G34: 45387 | H34: ARC | J34: UTA | M34: =VLOOKUP($H34,$A$6:$B$17,2,FALSE) -> -26.154251 | N34: =VLOOKUP($J34,$A$6:$B$17,2,FALSE) -> 4.4024108
G35: 45387 | H35: DAL | J35: SEA | M35: =VLOOKUP($H35,$A$6:$B$17,2,FALSE) -> 3.9324623 | N35: =VLOOKUP($J35,$A$6:$B$17,2,FALSE) -> 8.46717
... G101: 45472 | H101: SEA | J101: SD | M101: =VLOOKUP($H101,$A$6:$B$17,2,FALSE) -> 8.46717 | N101: =VLOOKUP($J101,$A$6:$B$17,2,FALSE) -> 8.372361

Sheet Fantasy

Sheet Real24
F1: 2024 Season Rankings
B2: 0
A3: Mean: | B3: =AVERAGE(B6:B17) -> 0 | F3: Home Edge: | G3: -1.1629716
O4: =SUM($O$6:$O300) -> 2699.2823 | P4: Week | Q4: Rankings History | S4: (After Week X)
A5: Team | B5: Rating | C5: Rank | D5: Previous | E5: Change | G5: Date | H5: Visitor | I5: Visitor Score | J5: Home | K5: Home Score | M5: Home Margin | N5: Forecast | O5: Squared Error | R5: Week1 | S5: Week2 | T5: Week3 | U5: Week4 | V5: Week5 | W5: Week6 | X5: Week7 | Y5: Week8 | Z5: Week9 | AA5: Week10 | AB5: Week11 | AC5: Week12 | AD5: Week13 | AE5: Week14 | AF5: Week15 | AG5: Week16 | AH5: Week17 | AI5: Week18
A6: SEA | B6: 12.180326 | C6: =RANK($B6,$B$6:$B$17,0) -> 1 | D6: 1 | E6: =D6-C6 -> 0 | G6: 45353 | H6: OGDC | I6: 6 | J6: NOLA | K6: 18 | M6: =K6-I6 -> 12 | N6: =$G$3+VLOOKUP($J6,$A$6:$B$17,2,FALSE)-VLOOKUP($H6,$A$6:$B$17,2,FALSE) -> 1.6607495 | O6: =($M6-$N6)^2 -> 106.9001 | P6: 1 | Q6: ARC | R6: 11 | S6: 11 | T6: 12 | U6: 12 | V6: 12 | W6: 12 | X6: 12 | Y6: 12
A7: NEFJ | B7: 8.46717 | C7: =RANK($B7,$B$6:$B$17,0) -> 2 | D7: 2 | E7: =D7-C7 -> 0 | G7: 45353 | H7: UTA | I7: 15 | J7: HOU | K7: 22 | M7: =K7-I7 -> 7 | N7: =$G$3+VLOOKUP($J7,$A$6:$B$17,2,FALSE)-VLOOKUP($H7,$A$6:$B$17,2,FALSE) -> 5.1351973 | O7: =($M7-$N7)^2 -> 3.4774893 | P7: 1 | Q7: CHI | R7: 12 | S7: 12 | T7: 10 | U7: 10 | V7: 10 | W7: 7 | X7: 6 | Y7: 5
A8: HOU | B8: 8.372361 | C8: =RANK($B8,$B$6:$B$17,0) -> 3 | D8: 3 | E8: =D8-C8 -> 0 | G8: 45353 | H8: SD | I8: 19 | J8: SEA | K8: 25 | M8: =K8-I8 -> 6 | N8: =$G$3+VLOOKUP($J8,$A$6:$B$17,2,FALSE)-VLOOKUP($H8,$A$6:$B$17,2,FALSE) -> 6.6149437 | O8: =($M8-$N8)^2 -> 0.37815571 | P8: 1 | Q8: DAL | R8: 5 | S8: 5 | T8: 5 | U8: 6 | V8: 5 | W8: 6 | X8: 5 | Y8: 7
A9: SD | B9: 4.4024108 | C9: =RANK($B9,$B$6:$B$17,0) -> 4 | D9: 4 | E9: =D9-C9 -> 0 | G9: 45354 | H9: CHI | I9: 23 | J9: MIA | K9: 19 | M9: =K9-I9 -> -4 | N9: =$G$3+VLOOKUP($J9,$A$6:$B$17,2,FALSE)-VLOOKUP($H9,$A$6:$B$17,2,FALSE) -> -4.8504301 | O9: =($M9-$N9)^2 -> 0.72323135 | P9: 1 | Q9: HOU | R9: 1 | S9: 1 | T9: 1 | U9: 1 | V9: 1 | W9: 1 | X9: 3 | Y9: 3
A10: CHI | B10: 3.9324623 | C10: =RANK($B10,$B$6:$B$17,0) -> 5 | D10: 6 | E10: =D10-C10 -> 1 | G10: 45354 | H10: NEFJ | I10: 46 | J10: ARC | K10: 13 | M10: =K10-I10 -> -33 | N10: =$G$3+VLOOKUP($J10,$A$6:$B$17,2,FALSE)-VLOOKUP($H10,$A$6:$B$17,2,FALSE) -> -35.784393 | O10: =($M10-$N10)^2 -> 7.7528445 | P10: 1 | Q10: MIA | R10: 9 | S10: 9 | T10: 8 | U10: 9 | V10: 9 | W10: 10 | X10: 9 | Y10: 8
A11: UTA | B11: 2.0741921 | C11: =RANK($B11,$B$6:$B$17,0) -> 6 | D11: 7 | E11: =D11-C11 -> 1 | G11: 45354 | H11: DAL | I11: 32 | J11: RFCLA | K11: 29 | M11: =K11-I11 -> -3 | N11: =$G$3+VLOOKUP($J11,$A$6:$B$17,2,FALSE)-VLOOKUP($H11,$A$6:$B$17,2,FALSE) -> -8.8800975 | O11: =($M11-$N11)^2 -> 34.575547 | P11: 1 | Q11: NEFJ | R11: 7 | S11: 7 | T11: 7 | U11: 7 | V11: 7 | W11: 3 | X11: 2 | Y11: 2
A12: DAL | B12: 1.8330672 | C12: =RANK($B12,$B$6:$B$17,0) -> 7 | D12: 5 | E12: =D12-C12 -> -2 | G12: 45360 | H12: OGDC | I12: 35 | J12: NEFJ | K12: 34 | M12: =K12-I12 -> -1 | N12: =$G$3+VLOOKUP($J12,$A$6:$B$17,2,FALSE)-VLOOKUP($H12,$A$6:$B$17,2,FALSE) -> 13.450401 | O12: =($M12-$N12)^2 -> 208.81408 | P12: 2 | Q12: NOLA | R12: 4 | S12: 4 | T12: 9 | U12: 8 | V12: 8 | W12: 9 | X12: 8 | Y12: 9
A13: MIA | B13: 0.24500384 | C13: =RANK($B13,$B$6:$B$17,0) -> 8 | D13: 9 | E13: =D13-C13 -> 1 | G13: 45360 | H13: ARC | I13: 19 | J13: NOLA | K13: 34 | M13: =K13-I13 -> 15 | N13: =$G$3+VLOOKUP($J13,$A$6:$B$17,2,FALSE)-VLOOKUP($H13,$A$6:$B$17,2,FALSE) -> 21.668799 | O13: =($M13-$N13)^2 -> 44.472876 | P13: 2 | Q13: OGDC | R13: 10 | S13: 10 | T13: 11 | U13: 11 | V13: 11 | W13: 11 | X13: 11 | Y13: 11
A14: NOLA | B14: -3.3224811 | C14: =RANK($B14,$B$6:$B$17,0) -> 9 | D14: 8 | E14: =D14-C14 -> -1 | G14: 45360 | H14: CHI | I14: 15 | J14: UTA | K14: 29 | M14: =K14-I14 -> 14 | N14: =$G$3+VLOOKUP($J14,$A$6:$B$17,2,FALSE)-VLOOKUP($H14,$A$6:$B$17,2,FALSE) -> -3.0212418 | O14: =($M14-$N14)^2 -> 289.72267 | P14: 2 | Q14: RFCLA | R14: 2 | S14: 2 | T14: 6 | U14: 5 | V14: 6 | W14: 8 | X14: 10 | Y14: 10
A15: RFCLA | B15: -5.8840587 | C15: =RANK($B15,$B$6:$B$17,0) -> 10 | D15: 10 | E15: =D15-C15 -> 0 | G15: 45360 | H15: MIA | I15: 18 | J15: SEA | K15: 29 | M15: =K15-I15 -> 11 | N15: =$G$3+VLOOKUP($J15,$A$6:$B$17,2,FALSE)-VLOOKUP($H15,$A$6:$B$17,2,FALSE) -> 10.772351 | O15: =($M15-$N15)^2 -> 0.051824221 | P15: 2 | Q15: SD | R15: 8 | S15: 8 | T15: 3 | U15: 3 | V15: 3 | W15: 4 | X15: 4 | Y15: 4
A16: OGDC | B16: -6.1462022 | C16: =RANK($B16,$B$6:$B$17,0) -> 11 | D16: 11 | E16: =D16-C16 -> 0 | G16: 45361 | H16: SD | I16: 30 | J16: DAL | K16: 23 | M16: =K16-I16 -> -7 | N16: =$G$3+VLOOKUP($J16,$A$6:$B$17,2,FALSE)-VLOOKUP($H16,$A$6:$B$17,2,FALSE) -> -3.7323152 | O16: =($M16-$N16)^2 -> 10.677764 | P16: 2 | Q16: SEA | R16: 3 | S16: 3 | T16: 2 | U16: 2 | V16: 2 | W16: 2 | X16: 1 | Y16: 1
A17: ARC | B17: -26.154251 | C17: =RANK($B17,$B$6:$B$17,0) -> 12 | D17: 12 | E17: =D17-C17 -> 0 | G17: 45361 | H17: HOU | I17: 27 | J17: RFCLA | K17: 12 | M17: =K17-I17 -> -15 | N17: =$G$3+VLOOKUP($J17,$A$6:$B$17,2,FALSE)-VLOOKUP($H17,$A$6:$B$17,2,FALSE) -> -15.419391 | O17: =($M17-$N17)^2 -> 0.17588905 | P17: 2 | Q17: UTA | R17: 6 | S17: 6 | T17: 4 | U17: 4 | V17: 4 | W17: 5 | X17: 7 | Y17: 6
G18: 45367 | H18: NOLA | I18: 21 | J18: NEFJ | K18: 27 | M18: =K18-I18 -> 6 | N18: =$G$3+VLOOKUP($J18,$A$6:$B$17,2,FALSE)-VLOOKUP($H18,$A$6:$B$17,2,FALSE) -> 10.62668 | O18: =($M18-$N18)^2 -> 21.406163 | P18: 3
G19: 45367 | H19: CHI | I19: 22 | J19: OGDC | K19: 22 | M19: =K19-I19 -> 0 | N19: =$G$3+VLOOKUP($J19,$A$6:$B$17,2,FALSE)-VLOOKUP($H19,$A$6:$B$17,2,FALSE) -> -11.241636 | O19: =($M19-$N19)^2 -> 126.37438 | P19: 3
G20: 45367 | H20: MIA | I20: 19 | J20: HOU | K20: 30 | M20: =K20-I20 -> 11 | N20: =$G$3+VLOOKUP($J20,$A$6:$B$17,2,FALSE)-VLOOKUP($H20,$A$6:$B$17,2,FALSE) -> 6.9643856 | O20: =($M20-$N20)^2 -> 16.286184 | P20: 3
G21: 45367 | H21: SEA | I21: 23 | J21: UTA | K21: 13 | M21: =K21-I21 -> -10 | N21: =$G$3+VLOOKUP($J21,$A$6:$B$17,2,FALSE)-VLOOKUP($H21,$A$6:$B$17,2,FALSE) -> -11.269106 | O21: =($M21-$N21)^2 -> 1.610629 | P21: 3
G22: 45367 | H22: RFCLA | I22: 18 | J22: SD | K22: 19 | M22: =K22-I22 -> 1 | N22: =$G$3+VLOOKUP($J22,$A$6:$B$17,2,FALSE)-VLOOKUP($H22,$A$6:$B$17,2,FALSE) -> 9.1234979 | O22: =($M22-$N22)^2 -> 65.991218 | P22: 3
F23: Pick: | G23: 45368 | H23: DAL | I23: 68 | J23: ARC | K23: 28 | M23: =K23-I23 -> -40 | N23: =$G$3+VLOOKUP($J23,$A$6:$B$17,2,FALSE)-VLOOKUP($H23,$A$6:$B$17,2,FALSE) -> -29.15029 | O23: =($M23-$N23)^2 -> 117.7162 | P23: 3
E24: Y | F24: HOU | G24: 45373 | H24: HOU | I24: 42 | J24: SEA | K24: 40 | M24: =K24-I24 -> -2 | N24: =$G$3+VLOOKUP($J24,$A$6:$B$17,2,FALSE)-VLOOKUP($H24,$A$6:$B$17,2,FALSE) -> 2.6449935 | O24: =($M24-$N24)^2 -> 21.575964 | P24: 4
E25: Y | F25: SD | G25: 45374 | H25: SD | I25: 27 | J25: OGDC | K25: 11 | M25: =K25-I25 -> -16 | N25: =$G$3+VLOOKUP($J25,$A$6:$B$17,2,FALSE)-VLOOKUP($H25,$A$6:$B$17,2,FALSE) -> -11.711585 | O25: =($M25-$N25)^2 -> 18.390506 | P25: 4
E26: Y | F26: MIA | G26: 45374 | H26: ARC | I26: 21 | J26: MIA | K26: 50 | M26: =K26-I26 -> 29 | N26: =$G$3+VLOOKUP($J26,$A$6:$B$17,2,FALSE)-VLOOKUP($H26,$A$6:$B$17,2,FALSE) -> 25.236284 | O26: =($M26-$N26)^2 -> 14.165561 | P26: 4
E27: N | F27: DAL | G27: 45374 | H27: NOLA | I27: 35 | J27: DAL | K27: 22 | M27: =K27-I27 -> -13 | N27: =$G$3+VLOOKUP($J27,$A$6:$B$17,2,FALSE)-VLOOKUP($H27,$A$6:$B$17,2,FALSE) -> 3.9925767 | O27: =($M27-$N27)^2 -> 288.74766 | P27: 4
E28: Y | F28: NEFJ | G28: 45375 | H28: NEFJ | I28: 22 | J28: CHI | K28: 17 | M28: =K28-I28 -> -5 | N28: =$G$3+VLOOKUP($J28,$A$6:$B$17,2,FALSE)-VLOOKUP($H28,$A$6:$B$17,2,FALSE) -> -5.6976793 | O28: =($M28-$N28)^2 -> 0.48675637 | P28: 4
E29: N | F29: UTA | G29: 45375 | H29: UTA | I29: 32 | J29: RFCLA | K29: 36 | M29: =K29-I29 -> 4 | N29: =$G$3+VLOOKUP($J29,$A$6:$B$17,2,FALSE)-VLOOKUP($H29,$A$6:$B$17,2,FALSE) -> -9.1212224 | O29: =($M29-$N29)^2 -> 172.16648 | P29: 4
E30: Y | F30: HOU | G30: 45380 | H30: HOU | I30: 30 | J30: DAL | K30: 27 | M30: =K30-I30 -> -3 | N30: =$G$3+VLOOKUP($J30,$A$6:$B$17,2,FALSE)-VLOOKUP($H30,$A$6:$B$17,2,FALSE) -> -7.7022654 | O30: =($M30-$N30)^2 -> 22.1113 | P30: 5
E31: Y | F31: SEA | G31: 45381 | H31: SEA | I31: 34 | J31: CHI | K31: 26 | M31: =K31-I31 -> -8 | N31: =$G$3+VLOOKUP($J31,$A$6:$B$17,2,FALSE)-VLOOKUP($H31,$A$6:$B$17,2,FALSE) -> -9.4108354 | O31: =($M31-$N31)^2 -> 1.9904565 | P31: 5
E32: Y | F32: OGDC | G32: 45381 | H32: OGDC | I32: 46 | J32: ARC | K32: 32 | M32: =K32-I32 -> -14 | N32: =$G$3+VLOOKUP($J32,$A$6:$B$17,2,FALSE)-VLOOKUP($H32,$A$6:$B$17,2,FALSE) -> -21.171021 | O32: =($M32-$N32)^2 -> 51.423539 | P32: 5
E33: Y | F33: SD | G33: 45382 | H33: SD | I33: 22 | J33: MIA | K33: 21 | M33: =K33-I33 -> -1 | N33: =$G$3+VLOOKUP($J33,$A$6:$B$17,2,FALSE)-VLOOKUP($H33,$A$6:$B$17,2,FALSE) -> -5.3203786 | O33: =($M33-$N33)^2 -> 18.665671 | P33: 5
E34: Y | F34: UTA | G34: 45387 | H34: ARC | I34: 19 | J34: UTA | K34: 44 | M34: =K34-I34 -> 25 | N34: =$G$3+VLOOKUP($J34,$A$6:$B$17,2,FALSE)-VLOOKUP($H34,$A$6:$B$17,2,FALSE) -> 27.065472 | O34: =($M34-$N34)^2 -> 4.2661744 | P34: 6
E35: Y | F35: SEA | G35: 45387 | H35: DAL | I35: 32 | J35: SEA | K35: 34 | M35: =K35-I35 -> 2 | N35: =$G$3+VLOOKUP($J35,$A$6:$B$17,2,FALSE)-VLOOKUP($H35,$A$6:$B$17,2,FALSE) -> 9.1842873 | O35: =($M35-$N35)^2 -> 51.613984 | P35: 6
... E48: N | F48: SD | G48: 45403 | H48: UTA | I48: 33 | J48: SD | K48: 32 | M48: =K48-I48 -> -1 | N48: =$G$3+VLOOKUP($J48,$A$6:$B$17,2,FALSE)-VLOOKUP($H48,$A$6:$B$17,2,FALSE) -> 1.1652471 | O48: =($M48-$N48)^2 -> 4.6882949 | P48: 8
G49: 45408 | H49: OGDC | J49: UTA | M49: =K49-I49 -> 0 | N49: =$G$3+VLOOKUP($J49,$A$6:$B$17,2,FALSE)-VLOOKUP($H49,$A$6:$B$17,2,FALSE) -> 7.0574228 | P49: 9
G50: 45409 | H50: NOLA | J50: ARC | M50: =K50-I50 -> 0 | N50: =$G$3+VLOOKUP($J50,$A$6:$B$17,2,FALSE)-VLOOKUP($H50,$A$6:$B$17,2,FALSE) -> -23.994742 | P50: 9
G51: 45409 | H51: DAL | J51: MIA | M51: =K51-I51 -> 0 | N51: =$G$3+VLOOKUP($J51,$A$6:$B$17,2,FALSE)-VLOOKUP($H51,$A$6:$B$17,2,FALSE) -> -2.751035 | P51: 9
G52: 45409 | H52: SD | J52: HOU | M52: =K52-I52 -> 0 | N52: =$G$3+VLOOKUP($J52,$A$6:$B$17,2,FALSE)-VLOOKUP($H52,$A$6:$B$17,2,FALSE) -> 2.8069786 | P52: 9
...

Sheet Offense Defense
F1: Home edge | G1: -1.1629393
F2: mean | G2: 22.775368
B3: mean | D3: off_mean: | E3: =AVERAGE(E5:E16) -> -3.0420111e-14 | F3: def_mean: | G3: =AVERAGE(G5:G16) -> 1.2569576e-08 | P3: SSE
B4: Team | C4: Overall | D4: Offense Rank | E4: Offense | F4: Defense Rank | G4: Defense | P4: =SUM(P6:P277) -> 6983.3543
B5: SEA | C5: =E5-G5 -> 12.180072 | D5: =RANK(E5,$E$5:$E$16,0) -> 2 | E5: 6.3595695 | F5: =RANK(G5,$G$5:$G$16,1) -> 1 | G5: -5.8205023 | I5: GameNumber | J5: Home Team | K5: Away Team | L5: Home Points | M5: Away Points | N5: Home Prediction | O5: Away Prediction | P5: Squared Error
B6: NEFJ | C6: =E6-G6 -> 8.4669026 | D6: =RANK(E6,$E$5:$E$16,0) -> 5 | E6: 2.6948001 | F6: =RANK(G6,$G$5:$G$16,1) -> 2 | G6: -5.7721025 | I6: 45353 | J6: NOLA | K6: OGDC | L6: 18 | M6: 6 | N6: =IFERROR(mean+0.5*Home_edge+VLOOKUP(J6,$B$5:$G$16,4,FALSE)+VLOOKUP(K6,$B$5:$G$16,6,FALSE),"") -> 17.79402 | O6: =IFERROR(mean-0.5*Home_edge+VLOOKUP(K6,$B$5:$G$16,4,FALSE)+VLOOKUP(J6,$B$5:$G$16,6,FALSE),"") -> 16.13167 | P6: =IFERROR((N6-L6)^2+(O6-M6)^2,"") -> 102.69316
B7: HOU | C7: =E7-G7 -> 8.3724952 | D7: =RANK(E7,$E$5:$E$16,0) -> 1 | E7: 6.8816647 | F7: =RANK(G7,$G$5:$G$16,1) -> 6 | G7: -1.4908305 | I7: 45353 | J7: HOU | K7: UTA | L7: 22 | M7: 15 | N7: =IFERROR(mean+0.5*Home_edge+VLOOKUP(J7,$B$5:$G$16,4,FALSE)+VLOOKUP(K7,$B$5:$G$16,6,FALSE),"") -> 23.637759 | O7: =IFERROR(mean-0.5*Home_edge+VLOOKUP(K7,$B$5:$G$16,4,FALSE)+VLOOKUP(J7,$B$5:$G$16,6,FALSE),"") -> 18.500956 | P7: =IFERROR((N7-L7)^2+(O7-M7)^2,"") -> 14.938944
B8: SD | C8: =E8-G8 -> 4.404097 | D8: =RANK(E8,$E$5:$E$16,0) -> 6 | E8: 0.13057564 | F8: =RANK(G8,$G$5:$G$16,1) -> 4 | G8: -4.2735214 | I8: 45353 | J8: SEA | K8: SD | L8: 25 | M8: 19 | N8: =IFERROR(mean+0.5*Home_edge+VLOOKUP(J8,$B$5:$G$16,4,FALSE)+VLOOKUP(K8,$B$5:$G$16,6,FALSE),"") -> 24.279946 | O8: =IFERROR(mean-0.5*Home_edge+VLOOKUP(K8,$B$5:$G$16,4,FALSE)+VLOOKUP(J8,$B$5:$G$16,6,FALSE),"") -> 17.666911 | P8: =IFERROR((N8-L8)^2+(O8-M8)^2,"") -> 2.2956044
B9: CHI | C9: =E9-G9 -> 3.9328244 | D9: =RANK(E9,$E$5:$E$16,0) -> 3 | E9: 4.4013953 | F9: =RANK(G9,$G$5:$G$16,1) -> 9 | G9: 0.46857093 | I9: 45354 | J9: MIA | K9: CHI | L9: 19 | M9: 23 | N9: =IFERROR(mean+0.5*Home_edge+VLOOKUP(J9,$B$5:$G$16,4,FALSE)+VLOOKUP(K9,$B$5:$G$16,6,FALSE),"") -> 18.81525 | O9: =IFERROR(mean-0.5*Home_edge+VLOOKUP(K9,$B$5:$G$16,4,FALSE)+VLOOKUP(J9,$B$5:$G$16,6,FALSE),"") -> 23.667666 | P9: =IFERROR((N9-L9)^2+(O9-M9)^2,"") -> 0.47991069
B10: UTA | C10: =E10-G10 -> 2.0727532 | D10: =RANK(E10,$E$5:$E$16,0) -> 8 | E10: -3.3650511 | F10: =RANK(G10,$G$5:$G$16,1) -> 3 | G10: -5.4378042 | I10: 45354 | J10: ARC | K10: NEFJ | L10: 13 | M10: 46 | N10: =IFERROR(mean+0.5*Home_edge+VLOOKUP(J10,$B$5:$G$16,4,FALSE)+VLOOKUP(K10,$B$5:$G$16,6,FALSE),"") -> 13.406408 | O10: =IFERROR(mean-0.5*Home_edge+VLOOKUP(K10,$B$5:$G$16,4,FALSE)+VLOOKUP(J10,$B$5:$G$16,6,FALSE),"") -> 49.189327 | P10: =IFERROR((N10-L10)^2+(O10-M10)^2,"") -> 10.336977
B11: DAL | C11: =E11-G11 -> 1.8314841 | D11: =RANK(E11,$E$5:$E$16,0) -> 4 | E11: 3.6960678 | F11: =RANK(G11,$G$5:$G$16,1) -> 10 | G11: 1.8645837 | I11: 45354 | J11: RFCLA | K11: DAL | L11: 29 | M11: 32 | N11: =IFERROR(mean+0.5*Home_edge+VLOOKUP(J11,$B$5:$G$16,4,FALSE)+VLOOKUP(K11,$B$5:$G$16,6,FALSE),"") -> 20.668444 | O11: =IFERROR(mean-0.5*Home_edge+VLOOKUP(K11,$B$5:$G$16,4,FALSE)+VLOOKUP(J11,$B$5:$G$16,6,FALSE),"") -> 29.546055 | P11: =IFERROR((N11-L11)^2+(O11-M11)^2,"") -> 75.436669
B12: MIA | C12: =E12-G12 -> 0.24334748 | D12: =RANK(E12,$E$5:$E$16,0) -> 11 | E12: -3.847219 | F12: =RANK(G12,$G$5:$G$16,1) -> 5 | G12: -4.0905665 | I12: 45360 | J12: NEFJ | K12: OGDC | L12: 34 | M12: 35 | N12: =IFERROR(mean+0.5*Home_edge+VLOOKUP(J12,$B$5:$G$16,4,FALSE)+VLOOKUP(K12,$B$5:$G$16,6,FALSE),"") -> 24.310686 | O12: =IFERROR(mean-0.5*Home_edge+VLOOKUP(K12,$B$5:$G$16,4,FALSE)+VLOOKUP(J12,$B$5:$G$16,6,FALSE),"") -> 10.860223 | P12: =IFERROR((N12-L12)^2+(O12-M12)^2,"") -> 676.61165
B13: NOLA | C13: =E13-G13 -> -3.3212106 | D13: =RANK(E13,$E$5:$E$16,0) -> 10 | E13: -3.8218659 | F13: =RANK(G13,$G$5:$G$16,1) -> 8 | G13: -0.5006553 | I13: 45360 | J13: NOLA | K13: ARC | L13: 34 | M13: 19 | N13: =IFERROR(mean+0.5*Home_edge+VLOOKUP(J13,$B$5:$G$16,4,FALSE)+VLOOKUP(K13,$B$5:$G$16,6,FALSE),"") -> 41.509722 | O13: =IFERROR(mean-0.5*Home_edge+VLOOKUP(K13,$B$5:$G$16,4,FALSE)+VLOOKUP(J13,$B$5:$G$16,6,FALSE),"") -> 19.840795 | P13: =IFERROR((N13-L13)^2+(O13-M13)^2,"") -> 57.102862
B14: RFCLA | C14: =E14-G14 -> -5.8831879 | D14: =RANK(E14,$E$5:$E$16,0) -> 9 | E14: -3.3900378 | F14: =RANK(G14,$G$5:$G$16,1) -> 11 | G14: 2.4931501 | I14: 45360 | J14: UTA | K14: CHI | L14: 29 | M14: 15 | N14: =IFERROR(mean+0.5*Home_edge+VLOOKUP(J14,$B$5:$G$16,4,FALSE)+VLOOKUP(K14,$B$5:$G$16,6,FALSE),"") -> 19.297418 | O14: =IFERROR(mean-0.5*Home_edge+VLOOKUP(K14,$B$5:$G$16,4,FALSE)+VLOOKUP(J14,$B$5:$G$16,6,FALSE),"") -> 22.320428 | P14: =IFERROR((N14-L14)^2+(O14-M14)^2,"") -> 147.72877
B15: OGDC | C15: =E15-G15 -> -6.1465003 | D15: =RANK(E15,$E$5:$E$16,0) -> 12 | E15: -6.7245122 | F15: =RANK(G15,$G$5:$G$16,1) -> 7 | G15: -0.57801184 | I15: 45360 | J15: SEA | K15: MIA | L15: 29 | M15: 18 | N15: =IFERROR(mean+0.5*Home_edge+VLOOKUP(J15,$B$5:$G$16,4,FALSE)+VLOOKUP(K15,$B$5:$G$16,6,FALSE),"") -> 24.462901 | O15: =IFERROR(mean-0.5*Home_edge+VLOOKUP(K15,$B$5:$G$16,4,FALSE)+VLOOKUP(J15,$B$5:$G$16,6,FALSE),"") -> 13.689116 | P15: =IFERROR((N15-L15)^2+(O15-M15)^2,"") -> 39.168986
B16: ARC | C16: =E16-G16 -> -26.153077 | D16: =RANK(E16,$E$5:$E$16,0) -> 7 | E16: -3.0153872 | F16: =RANK(G16,$G$5:$G$16,1) -> 12 | G16: 23.13769 | I16: 45361 | J16: DAL | K16: SD | L16: 23 | M16: 30 | N16: =IFERROR(mean+0.5*Home_edge+VLOOKUP(J16,$B$5:$G$16,4,FALSE)+VLOOKUP(K16,$B$5:$G$16,6,FALSE),"") -> 21.616445 | O16: =IFERROR(mean-0.5*Home_edge+VLOOKUP(K16,$B$5:$G$16,4,FALSE)+VLOOKUP(J16,$B$5:$G$16,6,FALSE),"") -> 25.351997 | P16: =IFERROR((N16-L16)^2+(O16-M16)^2,"") -> 23.51816
I17: 45361 | J17: RFCLA | K17: HOU | L17: 12 | M17: 27 | N17: =IFERROR(mean+0.5*Home_edge+VLOOKUP(J17,$B$5:$G$16,4,FALSE)+VLOOKUP(K17,$B$5:$G$16,6,FALSE),"") -> 17.31303 | O17: =IFERROR(mean-0.5*Home_edge+VLOOKUP(K17,$B$5:$G$16,4,FALSE)+VLOOKUP(J17,$B$5:$G$16,6,FALSE),"") -> 32.731652 | P17: =IFERROR((N17-L17)^2+(O17-M17)^2,"") -> 61.080122
I18: 45367 | J18: NEFJ | K18: NOLA | L18: 27 | M18: 21 | N18: =IFERROR(mean+0.5*Home_edge+VLOOKUP(J18,$B$5:$G$16,4,FALSE)+VLOOKUP(K18,$B$5:$G$16,6,FALSE),"") -> 24.388043 | O18: =IFERROR(mean-0.5*Home_edge+VLOOKUP(K18,$B$5:$G$16,4,FALSE)+VLOOKUP(J18,$B$5:$G$16,6,FALSE),"") -> 13.762869 | P18: =IFERROR((N18-L18)^2+(O18-M18)^2,"") -> 59.198386
I19: 45367 | J19: OGDC | K19: CHI | L19: 22 | M19: 22 | N19: =IFERROR(mean+0.5*Home_edge+VLOOKUP(J19,$B$5:$G$16,4,FALSE)+VLOOKUP(K19,$B$5:$G$16,6,FALSE),"") -> 15.937957 | O19: =IFERROR(mean-0.5*Home_edge+VLOOKUP(K19,$B$5:$G$16,4,FALSE)+VLOOKUP(J19,$B$5:$G$16,6,FALSE),"") -> 27.180221 | P19: =IFERROR((N19-L19)^2+(O19-M19)^2,"") -> 63.583055
C20: Off | D20: Def | I20: 45367 | J20: HOU | K20: MIA | L20: 30 | M20: 19 | N20: =IFERROR(mean+0.5*Home_edge+VLOOKUP(J20,$B$5:$G$16,4,FALSE)+VLOOKUP(K20,$B$5:$G$16,6,FALSE),"") -> 24.984996 | O20: =IFERROR(mean-0.5*Home_edge+VLOOKUP(K20,$B$5:$G$16,4,FALSE)+VLOOKUP(J20,$B$5:$G$16,6,FALSE),"") -> 18.018788 | P20: =IFERROR((N20-L20)^2+(O20-M20)^2,"") -> 26.113039
B21: SEA | C21: 7.6176142 | D21: =-F21 -> 3.781188 | E21: 12 | F21: -3.781188 | I21: 45367 | J21: UTA | K21: SEA | L21: 13 | M21: 23 | N21: =IFERROR(mean+0.5*Home_edge+VLOOKUP(J21,$B$5:$G$16,4,FALSE)+VLOOKUP(K21,$B$5:$G$16,6,FALSE),"") -> 13.008345 | O21: =IFERROR(mean-0.5*Home_edge+VLOOKUP(K21,$B$5:$G$16,4,FALSE)+VLOOKUP(J21,$B$5:$G$16,6,FALSE),"") -> 24.278603 | P21: =IFERROR((N21-L21)^2+(O21-M21)^2,"") -> 1.6348944
B22: NEFJ | C22: 4.125742 | D22: =-F22 -> 4.4648575 | E22: 11 | F22: -4.4648575 | I22: 45367 | J22: SD | K22: RFCLA | L22: 19 | M22: 18 | N22: =IFERROR(mean+0.5*Home_edge+VLOOKUP(J22,$B$5:$G$16,4,FALSE)+VLOOKUP(K22,$B$5:$G$16,6,FALSE),"") -> 24.817624 | O22: =IFERROR(mean-0.5*Home_edge+VLOOKUP(K22,$B$5:$G$16,4,FALSE)+VLOOKUP(J22,$B$5:$G$16,6,FALSE),"") -> 15.693278 | P22: =IFERROR((N22-L22)^2+(O22-M22)^2,"") -> 39.165713
B23: HOU | C23: 7.2706174 | D23: =-F23 -> 0.098258676 | E23: 10 | F23: -0.098258676 | I23: 45368 | J23: ARC | K23: DAL | L23: 28 | M23: 68 | N23: =IFERROR(mean+0.5*Home_edge+VLOOKUP(J23,$B$5:$G$16,4,FALSE)+VLOOKUP(K23,$B$5:$G$16,6,FALSE),"") -> 21.043095 | O23: =IFERROR(mean-0.5*Home_edge+VLOOKUP(K23,$B$5:$G$16,4,FALSE)+VLOOKUP(J23,$B$5:$G$16,6,FALSE),"") -> 50.190595 | P23: =IFERROR((N23-L23)^2+(O23-M23)^2,"") -> 365.57344
B24: SD | C24: -0.21092123 | D24: =-F24 -> 5.4709737 | E24: 9 | F24: -5.4709737 | I24: 45373 | J24: SEA | K24: HOU | L24: 40 | M24: 42 | N24: =IFERROR(mean+0.5*Home_edge+VLOOKUP(J24,$B$5:$G$16,4,FALSE)+VLOOKUP(K24,$B$5:$G$16,6,FALSE),"") -> 27.062637 | O24: =IFERROR(mean-0.5*Home_edge+VLOOKUP(K24,$B$5:$G$16,4,FALSE)+VLOOKUP(J24,$B$5:$G$16,6,FALSE),"") -> 24.418 | P24: =IFERROR((N24-L24)^2+(O24-M24)^2,"") -> 476.50209
B25: DAL | C25: 5.628242 | D25: =-F25 -> -3.4434793 | E25: 8 | F25: 3.4434793 | I25: 45374 | J25: OGDC | K25: SD | L25: 11 | M25: 27 | N25: =IFERROR(mean+0.5*Home_edge+VLOOKUP(J25,$B$5:$G$16,4,FALSE)+VLOOKUP(K25,$B$5:$G$16,6,FALSE),"") -> 11.195865 | O25: =IFERROR(mean-0.5*Home_edge+VLOOKUP(K25,$B$5:$G$16,4,FALSE)+VLOOKUP(J25,$B$5:$G$16,6,FALSE),"") -> 22.909401 | P25: =IFERROR((N25-L25)^2+(O25-M25)^2,"") -> 16.771362
B26: CHI | C26: 2.2235963 | D26: =-F26 -> -0.40660526 | E26: 7 | F26: 0.40660526 | I26: 45374 | J26: MIA | K26: ARC | L26: 50 | M26: 21 | N26: =IFERROR(mean+0.5*Home_edge+VLOOKUP(J26,$B$5:$G$16,4,FALSE)+VLOOKUP(K26,$B$5:$G$16,6,FALSE),"") -> 41.484369 | O26: =IFERROR(mean-0.5*Home_edge+VLOOKUP(K26,$B$5:$G$16,4,FALSE)+VLOOKUP(J26,$B$5:$G$16,6,FALSE),"") -> 16.250884 | P26: =IFERROR((N26-L26)^2+(O26-M26)^2,"") -> 95.070077
B27: UTA | C27: -5.0941898 | D27: =-F27 -> 6.5880167 | E27: 6 | F27: -6.5880167 | I27: 45374 | J27: DAL | K27: NOLA | L27: 22 | M27: 35 | N27: =IFERROR(mean+0.5*Home_edge+VLOOKUP(J27,$B$5:$G$16,4,FALSE)+VLOOKUP(K27,$B$5:$G$16,6,FALSE),"") -> 25.389311 | O27: =IFERROR(mean-0.5*Home_edge+VLOOKUP(K27,$B$5:$G$16,4,FALSE)+VLOOKUP(J27,$B$5:$G$16,6,FALSE),"") -> 21.399555 | P27: =IFERROR((N27-L27)^2+(O27-M27)^2,"") -> 196.45953
B28: NOLA | C28: -4.8197491 | D28: =-F28 -> 3.2759514 | E28: 5 | F28: -3.2759514 | I28: 45375 | J28: CHI | K28: NEFJ | L28: 17 | M28: 22 | N28: =IFERROR(mean+0.5*Home_edge+VLOOKUP(J28,$B$5:$G$16,4,FALSE)+VLOOKUP(K28,$B$5:$G$16,6,FALSE),"") -> 20.823191 | O28: =IFERROR(mean-0.5*Home_edge+VLOOKUP(K28,$B$5:$G$16,4,FALSE)+VLOOKUP(J28,$B$5:$G$16,6,FALSE),"") -> 26.520208 | P28: =IFERROR((N28-L28)^2+(O28-M28)^2,"") -> 35.049072
B29: MIA | C29: -6.7667236 | D29: =-F29 -> 4.7834779 | E29: 4 | F29: -4.7834779 | I29: 45375 | J29: RFCLA | K29: UTA | L29: 36 | M29: 32 | N29: =IFERROR(mean+0.5*Home_edge+VLOOKUP(J29,$B$5:$G$16,4,FALSE)+VLOOKUP(K29,$B$5:$G$16,6,FALSE),"") -> 13.366056 | O29: =IFERROR(mean-0.5*Home_edge+VLOOKUP(K29,$B$5:$G$16,4,FALSE)+VLOOKUP(J29,$B$5:$G$16,6,FALSE),"") -> 22.484936 | P29: =IFERROR((N29-L29)^2+(O29-M29)^2,"") -> 602.83185
B30: RFCLA | C30: -3.8881188 | D30: =-F30 -> 0.41644588 | E30: 3 | F30: -0.41644588 | I30: 45380 | J30: DAL | K30: HOU | L30: 27 | M30: 30 | N30: =IFERROR(mean+0.5*Home_edge+VLOOKUP(J30,$B$5:$G$16,4,FALSE)+VLOOKUP(K30,$B$5:$G$16,6,FALSE),"") -> 24.399135 | O30: =IFERROR(mean-0.5*Home_edge+VLOOKUP(K30,$B$5:$G$16,4,FALSE)+VLOOKUP(J30,$B$5:$G$16,6,FALSE),"") -> 32.103086 | P30: =IFERROR((N30-L30)^2+(O30-M30)^2,"") -> 11.187467
B31: OGDC | C31: -4.7975683 | D31: =-F31 -> 0.017136625 | E31: 2 | F31: -0.017136625 | I31: 45381 | J31: CHI | K31: SEA | L31: 26 | M31: 34 | N31: =IFERROR(mean+0.5*Home_edge+VLOOKUP(J31,$B$5:$G$16,4,FALSE)+VLOOKUP(K31,$B$5:$G$16,6,FALSE),"") -> 20.774791 | O31: =IFERROR(mean-0.5*Home_edge+VLOOKUP(K31,$B$5:$G$16,4,FALSE)+VLOOKUP(J31,$B$5:$G$16,6,FALSE),"") -> 30.184978 | P31: =IFERROR((N31-L31)^2+(O31-M31)^2,"") -> 41.857202
B32: ARC | C32: -1.288541 | D32: =-F32 -> -25.046222 | E32: 1 | F32: 25.046222 | I32: 45381 | J32: ARC | K32: OGDC | L32: 32 | M32: 46 | N32: =IFERROR(mean+0.5*Home_edge+VLOOKUP(J32,$B$5:$G$16,4,FALSE)+VLOOKUP(K32,$B$5:$G$16,6,FALSE),"") -> 18.600499 | O32: =IFERROR(mean-0.5*Home_edge+VLOOKUP(K32,$B$5:$G$16,4,FALSE)+VLOOKUP(J32,$B$5:$G$16,6,FALSE),"") -> 39.770015 | P32: =IFERROR((N32-L32)^2+(O32-M32)^2,"") -> 218.35934
I33: 45382 | J33: MIA | K33: SD | L33: 21 | M33: 22 | N33: =IFERROR(mean+0.5*Home_edge+VLOOKUP(J33,$B$5:$G$16,4,FALSE)+VLOOKUP(K33,$B$5:$G$16,6,FALSE),"") -> 14.073158 | O33: =IFERROR(mean-0.5*Home_edge+VLOOKUP(K33,$B$5:$G$16,4,FALSE)+VLOOKUP(J33,$B$5:$G$16,6,FALSE),"") -> 19.396847 | P33: =IFERROR((N33-L33)^2+(O33-M33)^2,"") -> 54.757552
I34: 45387 | J34: UTA | K34: ARC | L34: 44 | M34: 19 | N34: =IFERROR(mean+0.5*Home_edge+VLOOKUP(J34,$B$5:$G$16,4,FALSE)+VLOOKUP(K34,$B$5:$G$16,6,FALSE),"") -> 41.966537 | O34: =IFERROR(mean-0.5*Home_edge+VLOOKUP(K34,$B$5:$G$16,4,FALSE)+VLOOKUP(J34,$B$5:$G$16,6,FALSE),"") -> 14.903646 | P34: =IFERROR((N34-L34)^2+(O34-M34)^2,"") -> 20.915089
I35: 45387 | J35: SEA | K35: DAL | L35: 34 | M35: 32 | N35: =IFERROR(mean+0.5*Home_edge+VLOOKUP(J35,$B$5:$G$16,4,FALSE)+VLOOKUP(K35,$B$5:$G$16,6,FALSE),"") -> 30.418051 | O35: =IFERROR(mean-0.5*Home_edge+VLOOKUP(K35,$B$5:$G$16,4,FALSE)+VLOOKUP(J35,$B$5:$G$16,6,FALSE),"") -> 21.232403 | P35: =IFERROR((N35-L35)^2+(O35-M35)^2,"") -> 128.7715
I36: 45388 | J36: NOLA | K36: CHI | L36: 21 | M36: 38 | N36: =IFERROR(mean+0.5*Home_edge+VLOOKUP(J36,$B$5:$G$16,4,FALSE)+VLOOKUP(K36,$B$5:$G$16,6,FALSE),"") -> 18.840603 | O36: =IFERROR(mean-0.5*Home_edge+VLOOKUP(K36,$B$5:$G$16,4,FALSE)+VLOOKUP(J36,$B$5:$G$16,6,FALSE),"") -> 27.257577 | P36: =IFERROR((N36-L36)^2+(O36-M36)^2,"") -> 120.06264
I37: 45388 | J37: NEFJ | K37: MIA | L37: 25 | M37: 3 | N37: =IFERROR(mean+0.5*Home_edge+VLOOKUP(J37,$B$5:$G$16,4,FALSE)+VLOOKUP(K37,$B$5:$G$16,6,FALSE),"") -> 20.798132 | O37: =IFERROR(mean-0.5*Home_edge+VLOOKUP(K37,$B$5:$G$16,4,FALSE)+VLOOKUP(J37,$B$5:$G$16,6,FALSE),"") -> 13.737516 | P37: =IFERROR((N37-L37)^2+(O37-M37)^2,"") -> 132.94994
