Workbook
Name _MailOriginal: 'Analytics to Publish'!$A$8
Name Home_edge: OffDef25!$G$1
Name mean: OffDef25!$G$2

Sheet OffDef25
F1: Home edge | G1: 3.6631115 | S1: Rankings History | U1: (After Week X)
F2: mean | G2: 22.775368 | T2: Preseason | U2: Week1 | V2: Week2 | W2: Week3 | X2: Week4 | Y2: Week5 | Z2: Week6 | AA2: Week7 | AB2: Week8 | AC2: Week9 | AD2: Week10 | AE2: Week11 | AF2: Week12 | AG2: Week13 | AH2: Week14 | AI2: Week15 | AJ2: Week16 | AK2: Week17 | AL2: Week18
B3: mean | D3: off_mean: | E3: =AVERAGE(E5:E14) -> -5.2693514e-08 | F3: def_mean: | G3: =AVERAGE(G5:G14) -> 1.7866242e-07 | P3: SSE | S3: ARC | T3: 11 | U3: 8 | V3: 11 | W3: 11 | X3: 11 | Y3: 11 | Z3: 11 | AA3: 11 | AB3: 11 | AC3: 11 | AD3: 11 | AE3: 11 | AF3: 11 | AG3: 11 | AH3: 11 | AI3: 11 | AJ3: 11 | AK3: 11
B4: Team | C4: Overall | D4: Offense Rank | E4: Offense | F4: Defense Rank | G4: Defense | P4: =SUM(P6:P277) -> 18273.42 | S4: CHI | T4: 4 | U4: 4 | V4: 2 | W4: 3 | X4: 4 | Y4: 4 | Z4: 4 | AA4: 3 | AB4: 3 | AC4: 2 | AD4: 3 | AE4: 4 | AF4: 3 | AG4: 4 | AH4: 4 | AI4: 4 | AJ4: 4 | AK4: 4
A5: 1 | B5: UTAH | C5: =E5-G5 -> 3.4176488 | D5: =RANK(E5,$E$5:$E$15,0) -> 1 | E5: 4.8535337 | F5: =RANK(G5,$G$5:$G$15,1) -> 6 | G5: 1.435885 | I5: Rnd | J5: Home Team | K5: Away Team | L5: Home Points | M5: Away Points | N5: Home Prediction | O5: Away Prediction | P5: Squared Error | S5: HOU | T5: 1 | U5: 7 | V5: 3 | W5: 5 | X5: 1 | Y5: 2 | Z5: 3 | AA5: 2 | AB5: 2 | AC5: 4 | AD5: 4 | AE5: 3 | AF5: 4 | AG5: 3 | AH5: 1 | AI5: 1 | AJ5: 3 | AK5: 2
A6: 2 | B6: HOU | C6: =E6-G6 -> 4.6010256 | D6: =RANK(E6,$E$5:$E$15,0) -> 4 | E6: 0.094130043 | F6: =RANK(G6,$G$5:$G$15,1) -> 2 | G6: -4.5068956 | I6: 1 | J6: MIA | K6: OGDC | L6: 29 | M6: 31 | N6: =IFERROR(mean+0.5*Home_edge+VLOOKUP(J6,$B$5:$G$15,4,FALSE)+VLOOKUP(K6,$B$5:$G$15,6,FALSE),"") -> 23.177632 | O6: =IFERROR(mean-0.5*Home_edge+VLOOKUP(K6,$B$5:$G$15,4,FALSE)+VLOOKUP(J6,$B$5:$G$15,6,FALSE),"") -> 21.340442 | P6: =IFERROR((N6-L6)^2+(O6-M6)^2,"") -> 127.20704 | S6: MIA | T6: 9 | U6: 6 | V6: 9 | W6: 8 | X6: 9 | Y6: 8 | Z6: 8 | AA6: 10 | AB6: 10 | AC6: 10 | AD6: 10 | AE6: 10 | AF6: 10 | AG6: 10 | AH6: 10 | AI6: 10 | AJ6: 9 | AK6: 10
A7: 3 | B7: NEFJ | C7: =E7-G7 -> 3.7860479 | D7: =RANK(E7,$E$5:$E$15,0) -> 7 | E7: -1.2736361 | F7: =RANK(G7,$G$5:$G$15,1) -> 1 | G7: -5.059684 | I7: 1 | J7: NOLA | K7: ARC | L7: 35 | M7: 14 | N7: =IFERROR(mean+0.5*Home_edge+VLOOKUP(J7,$B$5:$G$15,4,FALSE)+VLOOKUP(K7,$B$5:$G$15,6,FALSE),"") -> 36.040003 | O7: =IFERROR(mean-0.5*Home_edge+VLOOKUP(K7,$B$5:$G$15,4,FALSE)+VLOOKUP(J7,$B$5:$G$15,6,FALSE),"") -> 19.600699 | P7: =IFERROR((N7-L7)^2+(O7-M7)^2,"") -> 32.449434 | S7: NEFJ | T7: 3 | U7: 3 | V7: 5 | W7: 9 | X7: 7 | Y7: 9 | Z7: 9 | AA7: 5 | AB7: 5 | AC7: 3 | AD7: 2 | AE7: 2 | AF7: 2 | AG7: 1 | AH7: 2 | AI7: 3 | AJ7: 1 | AK7: 3
A8: 4 | B8: CHI | C8: =E8-G8 -> 2.2108853 | D8: =RANK(E8,$E$5:$E$15,0) -> 9 | E8: -1.964961 | F8: =RANK(G8,$G$5:$G$15,1) -> 3 | G8: -4.1758463 | I8: 1 | J8: HOU | K8: CHI | L8: 22 | M8: 25 | N8: =IFERROR(mean+0.5*Home_edge+VLOOKUP(J8,$B$5:$G$15,4,FALSE)+VLOOKUP(K8,$B$5:$G$15,6,FALSE),"") -> 20.525207 | O8: =IFERROR(mean-0.5*Home_edge+VLOOKUP(K8,$B$5:$G$15,4,FALSE)+VLOOKUP(J8,$B$5:$G$15,6,FALSE),"") -> 14.471955 | P8: =IFERROR((N8-L8)^2+(O8-M8)^2,"") -> 113.01474 | S8: NOLA | T8: 6 | U8: 1 | V8: 10 | W8: 7 | X8: 10 | Y8: 10 | Z8: 10 | AA8: 9 | AB8: 9 | AC8: 7 | AD8: 6 | AE8: 6 | AF8: 8 | AG8: 8 | AH8: 9 | AI8: 9 | AJ8: 10 | AK8: 9
A9: 5 | B9: SDL | C9: =E9-G9 -> 1.9052168 | D9: =RANK(E9,$E$5:$E$15,0) -> 3 | E9: 2.1899097 | F9: =RANK(G9,$G$5:$G$15,1) -> 5 | G9: 0.28469286 | I9: 1 | J9: SDL | K9: SEA | L9: 40 | M9: 26 | N9: =IFERROR(mean+0.5*Home_edge+VLOOKUP(J9,$B$5:$G$15,4,FALSE)+VLOOKUP(K9,$B$5:$G$15,6,FALSE),"") -> 25.99475 | O9: =IFERROR(mean-0.5*Home_edge+VLOOKUP(K9,$B$5:$G$15,4,FALSE)+VLOOKUP(J9,$B$5:$G$15,6,FALSE),"") -> 21.247827 | P9: =IFERROR((N9-L9)^2+(O9-M9)^2,"") -> 218.73018 | S9: OGDC | T9: 8 | U9: 5 | V9: 8 | W9: 6 | X9: 8 | Y9: 7 | Z9: 6 | AA9: 7 | AB9: 7 | AC9: 9 | AD9: 9 | AE9: 9 | AF9: 9 | AG9: 9 | AH9: 8 | AI9: 8 | AJ9: 8 | AK9: 8
A10: 6 | B10: SEA | C10: =E10-G10 -> 0.82140534 | D10: =RANK(E10,$E$5:$E$15,0) -> 5 | E10: 0.019322014 | F10: =RANK(G10,$G$5:$G$15,1) -> 4 | G10: -0.80208333 | I10: 1 | J10: RFCLA | K10: NEFJ | L10: 17 | M10: 24 | N10: =IFERROR(mean+0.5*Home_edge+VLOOKUP(J10,$B$5:$G$15,4,FALSE)+VLOOKUP(K10,$B$5:$G$15,6,FALSE),"") -> 23.39348 | O10: =IFERROR(mean-0.5*Home_edge+VLOOKUP(K10,$B$5:$G$15,4,FALSE)+VLOOKUP(J10,$B$5:$G$15,6,FALSE),"") -> 24.036738 | P10: =IFERROR((N10-L10)^2+(O10-M10)^2,"") -> 40.877935 | Q10: Home Team Offense Favorability | R10: Away Team Offense Favorability | S10: RFCLA | T10: 10 | U10: 9 | V10: 6 | W10: 10 | X10: 6 | Y10: 5 | Z10: 7 | AA10: 6 | AB10: 6 | AC10: 6 | AD10: 7 | AE10: 7 | AF10: 6 | AG10: 7 | AH10: 6 | AI10: 7 | AJ10: 5 | AK10: 7
A11: 7 | B11: RFCLA | C11: =E11-G11 -> -0.5203218 | D11: =RANK(E11,$E$5:$E$15,0) -> 2 | E11: 3.8462405 | F11: =RANK(G11,$G$5:$G$15,1) -> 10 | G11: 4.3665623 | I11: 2 | J11: ARC | K11: SDL | L11: 5 | M11: 52 | N11: =IFERROR(mean+0.5*Home_edge+VLOOKUP(J11,$B$5:$G$15,4,FALSE)+VLOOKUP(K11,$B$5:$G$15,6,FALSE),"") -> 20.034377 | O11: =IFERROR(mean-0.5*Home_edge+VLOOKUP(K11,$B$5:$G$15,4,FALSE)+VLOOKUP(J11,$B$5:$G$15,6,FALSE),"") -> 36.355433 | P11: =IFERROR((N11-L11)^2+(O11-M11)^2,"") -> 470.78497 | Q11: =VLOOKUP($J11,$B$5:$G$15,4, FALSE)+VLOOKUP($K11,$B$5:$G$15,6, FALSE) -> -4.5725462 | R11: =VLOOKUP($K11,$B$5:$G$15,4, FALSE)+VLOOKUP($J11,$B$5:$G$15,6, FALSE) -> 15.411621 | S11: SDL | T11: 5 | U11: 2 | V11: 4 | W11: 2 | X11: 3 | Y11: 1 | Z11: 1 | AA11: 1 | AB11: 1 | AC11: 5 | AD11: 5 | AE11: 5 | AF11: 5 | AG11: 5 | AH11: 5 | AI11: 5 | AJ11: 6 | AK11: 5
A12: 8 | B12: OGDC | C12: =E12-G12 -> -4.5466153 | D12: =RANK(E12,$E$5:$E$15,0) -> 6 | E12: -1.1741857 | F12: =RANK(G12,$G$5:$G$15,1) -> 8 | G12: 3.3724296 | I12: 2 | J12: MIA | K12: NOLA | L12: 30 | M12: 25 | N12: =IFERROR(mean+0.5*Home_edge+VLOOKUP(J12,$B$5:$G$15,4,FALSE)+VLOOKUP(K12,$B$5:$G$15,6,FALSE),"") -> 23.319328 | O12: =IFERROR(mean-0.5*Home_edge+VLOOKUP(K12,$B$5:$G$15,4,FALSE)+VLOOKUP(J12,$B$5:$G$15,6,FALSE),"") -> 20.725995 | P12: =IFERROR((N12-L12)^2+(O12-M12)^2,"") -> 62.898497 | Q12: =VLOOKUP($J12,$B$5:$G$15,4, FALSE)+VLOOKUP($K12,$B$5:$G$15,6, FALSE) -> -1.2875953 | R12: =VLOOKUP($K12,$B$5:$G$15,4, FALSE)+VLOOKUP($J12,$B$5:$G$15,6, FALSE) -> -0.21781721 | S12: SEA | T12: 2 | U12: 10 | V12: 7 | W12: 4 | X12: 5 | Y12: 6 | Z12: 5 | AA12: 8 | AB12: 8 | AC12: 8 | AD12: 8 | AE12: 8 | AF12: 7 | AG12: 6 | AH12: 7 | AI12: 6 | AJ12: 7 | AK12: 6
A13: 9 | B13: NOLA | C13: =E13-G13 -> -5.3027584 | D13: =RANK(E13,$E$5:$E$15,0) -> 8 | E13: -1.7886324 | F13: =RANK(G13,$G$5:$G$15,1) -> 9 | G13: 3.514126 | I13: 2 | J13: CHI | K13: UTAH | L13: 31 | M13: 45 | N13: =IFERROR(mean+0.5*Home_edge+VLOOKUP(J13,$B$5:$G$15,4,FALSE)+VLOOKUP(K13,$B$5:$G$15,6,FALSE),"") -> 24.077847 | O13: =IFERROR(mean-0.5*Home_edge+VLOOKUP(K13,$B$5:$G$15,4,FALSE)+VLOOKUP(J13,$B$5:$G$15,6,FALSE),"") -> 21.621499 | P13: =IFERROR((N13-L13)^2+(O13-M13)^2,"") -> 594.47048 | Q13: =VLOOKUP($J13,$B$5:$G$15,4, FALSE)+VLOOKUP($K13,$B$5:$G$15,6, FALSE) -> -0.52907599 | R13: =VLOOKUP($K13,$B$5:$G$15,4, FALSE)+VLOOKUP($J13,$B$5:$G$15,6, FALSE) -> 0.67768749 | S13: UTAH | T13: 7 | V13: 1 | W13: 1 | X13: 2 | Y13: 3 | Z13: 2 | AA13: 4 | AB13: 4 | AC13: 1 | AD13: 1 | AE13: 1 | AF13: 1 | AG13: 2 | AH13: 3 | AI13: 2 | AJ13: 2 | AK13: 1
A14: 10 | B14: MIA | C14: =E14-G14 -> -6.3725365 | D14: =RANK(E14,$E$5:$E$15,0) -> 10 | E14: -4.8017213 | F14: =RANK(G14,$G$5:$G$15,1) -> 7 | G14: 1.5708152 | I14: 2 | J14: RFCLA | K14: HOU | L14: 28 | M14: 45 | N14: =IFERROR(mean+0.5*Home_edge+VLOOKUP(J14,$B$5:$G$15,4,FALSE)+VLOOKUP(K14,$B$5:$G$15,6,FALSE),"") -> 23.946268 | O14: =IFERROR(mean-0.5*Home_edge+VLOOKUP(K14,$B$5:$G$15,4,FALSE)+VLOOKUP(J14,$B$5:$G$15,6,FALSE),"") -> 25.404504 | P14: =IFERROR((N14-L14)^2+(O14-M14)^2,"") -> 400.41619 | Q14: =VLOOKUP($J14,$B$5:$G$15,4, FALSE)+VLOOKUP($K14,$B$5:$G$15,6, FALSE) -> -0.66065508 | R14: =VLOOKUP($K14,$B$5:$G$15,4, FALSE)+VLOOKUP($J14,$B$5:$G$15,6, FALSE) -> 4.4606923
A15: 11 | B15: ARC | C15: =E15-G15 -> -18.078951 | D15: =RANK(E15,$E$5:$E$15,0) -> 11 | E15: -4.857239 | F15: =RANK(G15,$G$5:$G$15,1) -> 11 | G15: 13.221712 | I15: 3 | J15: ARC | K15: MIA | L15: 31 | M15: 32 | N15: =IFERROR(mean+0.5*Home_edge+VLOOKUP(J15,$B$5:$G$15,4,FALSE)+VLOOKUP(K15,$B$5:$G$15,6,FALSE),"") -> 21.3205 | O15: =IFERROR(mean-0.5*Home_edge+VLOOKUP(K15,$B$5:$G$15,4,FALSE)+VLOOKUP(J15,$B$5:$G$15,6,FALSE),"") -> 29.363802 | P15: =IFERROR((N15-L15)^2+(O15-M15)^2,"") -> 100.64227 | Q15: =VLOOKUP($J15,$B$5:$G$15,4, FALSE)+VLOOKUP($K15,$B$5:$G$15,6, FALSE) -> -3.2864238 | R15: =VLOOKUP($K15,$B$5:$G$15,4, FALSE)+VLOOKUP($J15,$B$5:$G$15,6, FALSE) -> 8.4199902 | T15: Log | AA15: Overall
I16: 3 | J16: UTAH | K16: NOLA | L16: 55 | M16: 21 | N16: =IFERROR(mean+0.5*Home_edge+VLOOKUP(J16,$B$5:$G$15,4,FALSE)+VLOOKUP(K16,$B$5:$G$15,6,FALSE),"") -> 32.974583 | O16: =IFERROR(mean-0.5*Home_edge+VLOOKUP(K16,$B$5:$G$15,4,FALSE)+VLOOKUP(J16,$B$5:$G$15,6,FALSE),"") -> 20.591065 | P16: =IFERROR((N16-L16)^2+(O16-M16)^2,"") -> 485.28621 | Q16: =VLOOKUP($J16,$B$5:$G$15,4, FALSE)+VLOOKUP($K16,$B$5:$G$15,6, FALSE) -> 8.3676598 | R16: =VLOOKUP($K16,$B$5:$G$15,4, FALSE)+VLOOKUP($J16,$B$5:$G$15,6, FALSE) -> -0.35274745 | T16: 1 | U16: OGDC | V16: 19.09785 | W16: 17.959618 | X16: MIA | Y16: Y | Z16: OGDC | AA16: Y | AB16: N
I17: 3 | J17: OGDC | K17: SDL | L17: 10 | M17: 26 | N17: =IFERROR(mean+0.5*Home_edge+VLOOKUP(J17,$B$5:$G$15,4,FALSE)+VLOOKUP(K17,$B$5:$G$15,6,FALSE),"") -> 23.717431 | O17: =IFERROR(mean-0.5*Home_edge+VLOOKUP(K17,$B$5:$G$15,4,FALSE)+VLOOKUP(J17,$B$5:$G$15,6,FALSE),"") -> 26.506151 | P17: =IFERROR((N17-L17)^2+(O17-M17)^2,"") -> 188.42409 | Q17: =VLOOKUP($J17,$B$5:$G$15,4, FALSE)+VLOOKUP($K17,$B$5:$G$15,6, FALSE) -> -0.88949281 | R17: =VLOOKUP($K17,$B$5:$G$15,4, FALSE)+VLOOKUP($J17,$B$5:$G$15,6, FALSE) -> 5.5623393 | U17: ARC | V17: 15.665113 | W17: 38.436466 | X17: NOLA | Y17: Y | Z17: NOLA | AA17: =COUNTIF(Y16:Y93,"Y") -> 47 | AB17: =COUNTIF(Y16:Y95, "N") -> 28
I18: 3 | J18: HOU | K18: SEA | L18: 24 | M18: 21 | N18: =IFERROR(mean+0.5*Home_edge+VLOOKUP(J18,$B$5:$G$15,4,FALSE)+VLOOKUP(K18,$B$5:$G$15,6,FALSE),"") -> 23.89897 | O18: =IFERROR(mean-0.5*Home_edge+VLOOKUP(K18,$B$5:$G$15,4,FALSE)+VLOOKUP(J18,$B$5:$G$15,6,FALSE),"") -> 16.456238 | P18: =IFERROR((N18-L18)^2+(O18-M18)^2,"") -> 20.655976 | Q18: =VLOOKUP($J18,$B$5:$G$15,4, FALSE)+VLOOKUP($K18,$B$5:$G$15,6, FALSE) -> -0.70795328 | R18: =VLOOKUP($K18,$B$5:$G$15,4, FALSE)+VLOOKUP($J18,$B$5:$G$15,6, FALSE) -> -4.4875736 | U18: CHI | V18: 18.801577 | W18: 25.447747 | X18: HOU | Y18: N | Z18: HOU
I19: 3 | J19: CHI | K19: NEFJ | L19: 36 | M19: 7 | N19: =IFERROR(mean+0.5*Home_edge+VLOOKUP(J19,$B$5:$G$15,4,FALSE)+VLOOKUP(K19,$B$5:$G$15,6,FALSE),"") -> 17.582278 | O19: =IFERROR(mean-0.5*Home_edge+VLOOKUP(K19,$B$5:$G$15,4,FALSE)+VLOOKUP(J19,$B$5:$G$15,6,FALSE),"") -> 15.49433 | P19: =IFERROR((N19-L19)^2+(O19-M19)^2,"") -> 411.3661 | Q19: =VLOOKUP($J19,$B$5:$G$15,4, FALSE)+VLOOKUP($K19,$B$5:$G$15,6, FALSE) -> -7.024645 | R19: =VLOOKUP($K19,$B$5:$G$15,4, FALSE)+VLOOKUP($J19,$B$5:$G$15,6, FALSE) -> -5.4494824 | U19: SEA | V19: 24.879673 | W19: 17.689527 | X19: SD | Y19: N | Z19: SEA | AA19: =COUNTIF(Y16:Y48, "Y") -> 24 | AB19: =COUNTIF(Y16:Y48, "N") -> 9
B20: Movers | I20: 4 | J20: UTAH | K20: HOU | L20: 17 | M20: 37 | N20: =IFERROR(mean+0.5*Home_edge+VLOOKUP(J20,$B$5:$G$15,4,FALSE)+VLOOKUP(K20,$B$5:$G$15,6,FALSE),"") -> 24.953562 | O20: =IFERROR(mean-0.5*Home_edge+VLOOKUP(K20,$B$5:$G$15,4,FALSE)+VLOOKUP(J20,$B$5:$G$15,6,FALSE),"") -> 22.473827 | P20: =IFERROR((N20-L20)^2+(O20-M20)^2,"") -> 274.26885 | Q20: =VLOOKUP($J20,$B$5:$G$15,4, FALSE)+VLOOKUP($K20,$B$5:$G$15,6, FALSE) -> 0.34663817 | R20: =VLOOKUP($K20,$B$5:$G$15,4, FALSE)+VLOOKUP($J20,$B$5:$G$15,6, FALSE) -> 1.530015 | U20: NEFJ | V20: 28.088044 | W20: 17.510607 | X20: RFCLA | Y20: Y | Z20: NEFJ | AA20: last few weeks
B21: Team | C21: LastRank | D21: Rank | E21: Change | F21: sum changes | I21: 4 | J21: OGDC | K21: ARC | L21: 26 | M21: 22 | N21: =IFERROR(mean+0.5*Home_edge+VLOOKUP(J21,$B$5:$G$15,4,FALSE)+VLOOKUP(K21,$B$5:$G$15,6,FALSE),"") -> 36.654449 | O21: =IFERROR(mean-0.5*Home_edge+VLOOKUP(K21,$B$5:$G$15,4,FALSE)+VLOOKUP(J21,$B$5:$G$15,6,FALSE),"") -> 19.459003 | P21: =IFERROR((N21-L21)^2+(O21-M21)^2,"") -> 119.97396 | Q21: =VLOOKUP($J21,$B$5:$G$15,4, FALSE)+VLOOKUP($K21,$B$5:$G$15,6, FALSE) -> 12.047526 | R21: =VLOOKUP($K21,$B$5:$G$15,4, FALSE)+VLOOKUP($J21,$B$5:$G$15,6, FALSE) -> -1.4848094 | T21: 2 | U21: ARC | V21: =IFERROR(mean+0.5*Home_edge+VLOOKUP(U21,$B$5:$G$14,4,FALSE)+VLOOKUP(X21,$B$5:$G$14,6,FALSE),"") | W21: =IFERROR(mean-0.5*Home_edge+VLOOKUP(X21,$B$5:$G$14,4,FALSE)+VLOOKUP(U21,$B$5:$G$14,6,FALSE),"") | X21: SDL | Y21: Y | Z21: SDL | AA21: =COUNTIF(Y49:Y94, "Y") -> 24 | AB21: =COUNTIF(Y49:Y94, "N") -> 19
B22: NEFJ | C22: 1 | D22: 3 | E22: =C22-D22 -> -2 | F22: =SUM(E22:E32) -> 0 | I22: 4 | J22: MIA | K22: CHI | L22: 18 | M22: 31 | N22: =IFERROR(mean+0.5*Home_edge+VLOOKUP(J22,$B$5:$G$15,4,FALSE)+VLOOKUP(K22,$B$5:$G$15,6,FALSE),"") -> 15.629356 | O22: =IFERROR(mean-0.5*Home_edge+VLOOKUP(K22,$B$5:$G$15,4,FALSE)+VLOOKUP(J22,$B$5:$G$15,6,FALSE),"") -> 20.549666 | P22: =IFERROR((N22-L22)^2+(O22-M22)^2,"") -> 114.82943 | Q22: =VLOOKUP($J22,$B$5:$G$15,4, FALSE)+VLOOKUP($K22,$B$5:$G$15,6, FALSE) -> -8.9775676 | R22: =VLOOKUP($K22,$B$5:$G$15,4, FALSE)+VLOOKUP($J22,$B$5:$G$15,6, FALSE) -> -0.39414576 | U22: MIA | V22: =IFERROR(mean+0.5*Home_edge+VLOOKUP(U22,$B$5:$G$14,4,FALSE)+VLOOKUP(X22,$B$5:$G$14,6,FALSE),"") -> 23.319328 | W22: =IFERROR(mean-0.5*Home_edge+VLOOKUP(X22,$B$5:$G$14,4,FALSE)+VLOOKUP(U22,$B$5:$G$14,6,FALSE),"") -> 20.725995 | X22: NOLA | Y22: N | Z22: NOLA
B23: UTAH | C23: 2 | D23: 1 | E23: =C23-D23 -> 1 | I23: 4 | J23: SDL | K23: RFCLA | L23: 36 | M23: 28 | N23: =IFERROR(mean+0.5*Home_edge+VLOOKUP(J23,$B$5:$G$15,4,FALSE)+VLOOKUP(K23,$B$5:$G$15,6,FALSE),"") -> 31.163395 | O23: =IFERROR(mean-0.5*Home_edge+VLOOKUP(K23,$B$5:$G$15,4,FALSE)+VLOOKUP(J23,$B$5:$G$15,6,FALSE),"") -> 25.074745 | P23: =IFERROR((N23-L23)^2+(O23-M23)^2,"") -> 31.949858 | Q23: =VLOOKUP($J23,$B$5:$G$15,4, FALSE)+VLOOKUP($K23,$B$5:$G$15,6, FALSE) -> 6.556472 | R23: =VLOOKUP($K23,$B$5:$G$15,4, FALSE)+VLOOKUP($J23,$B$5:$G$15,6, FALSE) -> 4.1309334 | U23: CHI | V23: =IFERROR(mean+0.5*Home_edge+VLOOKUP(U23,$B$5:$G$14,4,FALSE)+VLOOKUP(X23,$B$5:$G$14,6,FALSE),"") -> 24.077847 | W23: =IFERROR(mean-0.5*Home_edge+VLOOKUP(X23,$B$5:$G$14,4,FALSE)+VLOOKUP(U23,$B$5:$G$14,6,FALSE),"") -> 21.621499 | X23: UTAH | Y23: N | Z23: CHI
B24: HOU | C24: 3 | D24: 2 | E24: =C24-D24 -> 1 | I24: 4 | J24: SEA | K24: NEFJ | L24: 27 | M24: 24 | N24: =IFERROR(mean+0.5*Home_edge+VLOOKUP(J24,$B$5:$G$15,4,FALSE)+VLOOKUP(K24,$B$5:$G$15,6,FALSE),"") -> 19.566561 | O24: =IFERROR(mean-0.5*Home_edge+VLOOKUP(K24,$B$5:$G$15,4,FALSE)+VLOOKUP(J24,$B$5:$G$15,6,FALSE),"") -> 18.868092 | P24: =IFERROR((N24-L24)^2+(O24-M24)^2,"") -> 81.592483 | Q24: =VLOOKUP($J24,$B$5:$G$15,4, FALSE)+VLOOKUP($K24,$B$5:$G$15,6, FALSE) -> -5.040362 | R24: =VLOOKUP($K24,$B$5:$G$15,4, FALSE)+VLOOKUP($J24,$B$5:$G$15,6, FALSE) -> -2.0757195 | U24: RFCLA | V24: =IFERROR(mean+0.5*Home_edge+VLOOKUP(U24,$B$5:$G$14,4,FALSE)+VLOOKUP(X24,$B$5:$G$14,6,FALSE),"") -> 23.946268 | W24: =IFERROR(mean-0.5*Home_edge+VLOOKUP(X24,$B$5:$G$14,4,FALSE)+VLOOKUP(U24,$B$5:$G$14,6,FALSE),"") -> 25.404504 | X24: HOU | Y24: Y | Z24: HOU
B25: CHI | C25: 4 | D25: 4 | E25: =C25-D25 -> 0 | I25: 5 | J25: CHI | K25: OGDC | L25: 30 | M25: 26 | N25: =IFERROR(mean+0.5*Home_edge+VLOOKUP(J25,$B$5:$G$15,4,FALSE)+VLOOKUP(K25,$B$5:$G$15,6,FALSE),"") -> 26.014392 | O25: =IFERROR(mean-0.5*Home_edge+VLOOKUP(K25,$B$5:$G$15,4,FALSE)+VLOOKUP(J25,$B$5:$G$15,6,FALSE),"") -> 15.59378 | P25: =IFERROR((N25-L25)^2+(O25-M25)^2,"") -> 124.17448 | Q25: =VLOOKUP($J25,$B$5:$G$15,4, FALSE)+VLOOKUP($K25,$B$5:$G$15,6, FALSE) -> 1.4074687 | R25: =VLOOKUP($K25,$B$5:$G$15,4, FALSE)+VLOOKUP($J25,$B$5:$G$15,6, FALSE) -> -5.3500319 | T25: 3 | U25: ARC | V25: =IFERROR(mean+0.5*Home_edge+VLOOKUP(U25,$B$5:$G$15,4,FALSE)+VLOOKUP(X25,$B$5:$G$15,6,FALSE),"") -> 21.3205 | W25: =IFERROR(mean-0.5*Home_edge+VLOOKUP(X25,$B$5:$G$15,4,FALSE)+VLOOKUP(U25,$B$5:$G$15,6,FALSE),"") -> 29.363802 | X25: MIA | Y25: Y | Z25: MIA
B26: RFCLA | C26: 5 | D26: 7 | E26: =C26-D26 -> -2 | I26: 5 | J26: NEFJ | K26: NOLA | L26: 35 | M26: 31 | N26: =IFERROR(mean+0.5*Home_edge+VLOOKUP(J26,$B$5:$G$15,4,FALSE)+VLOOKUP(K26,$B$5:$G$15,6,FALSE),"") -> 26.847413 | O26: =IFERROR(mean-0.5*Home_edge+VLOOKUP(K26,$B$5:$G$15,4,FALSE)+VLOOKUP(J26,$B$5:$G$15,6,FALSE),"") -> 14.095495 | P26: =IFERROR((N26-L26)^2+(O26-M26)^2,"") -> 352.22694 | Q26: =VLOOKUP($J26,$B$5:$G$15,4, FALSE)+VLOOKUP($K26,$B$5:$G$15,6, FALSE) -> 2.2404899 | R26: =VLOOKUP($K26,$B$5:$G$15,4, FALSE)+VLOOKUP($J26,$B$5:$G$15,6, FALSE) -> -6.8483165 | U26: UTAH | V26: =IFERROR(mean+0.5*Home_edge+VLOOKUP(U26,$B$5:$G$15,4,FALSE)+VLOOKUP(X26,$B$5:$G$15,6,FALSE),"") -> 32.974583 | W26: =IFERROR(mean-0.5*Home_edge+VLOOKUP(X26,$B$5:$G$15,4,FALSE)+VLOOKUP(U26,$B$5:$G$15,6,FALSE),"") -> 20.591065 | X26: NOLA | Y26: Y | Z26: UTAH
B27: SDL | C27: 6 | D27: 5 | E27: =C27-D27 -> 1 | I27: 5 | J27: MIA | K27: UTAH | L27: 19 | M27: 36 | N27: =IFERROR(mean+0.5*Home_edge+VLOOKUP(J27,$B$5:$G$15,4,FALSE)+VLOOKUP(K27,$B$5:$G$15,6,FALSE),"") -> 21.241087 | O27: =IFERROR(mean-0.5*Home_edge+VLOOKUP(K27,$B$5:$G$15,4,FALSE)+VLOOKUP(J27,$B$5:$G$15,6,FALSE),"") -> 27.368161 | P27: =IFERROR((N27-L27)^2+(O27-M27)^2,"") -> 79.531117 | Q27: =VLOOKUP($J27,$B$5:$G$15,4, FALSE)+VLOOKUP($K27,$B$5:$G$15,6, FALSE) -> -3.3658364 | R27: =VLOOKUP($K27,$B$5:$G$15,4, FALSE)+VLOOKUP($J27,$B$5:$G$15,6, FALSE) -> 6.424349 | U27: OGDC | V27: =IFERROR(mean+0.5*Home_edge+VLOOKUP(U27,$B$5:$G$15,4,FALSE)+VLOOKUP(X27,$B$5:$G$15,6,FALSE),"") -> 23.717431 | W27: =IFERROR(mean-0.5*Home_edge+VLOOKUP(X27,$B$5:$G$15,4,FALSE)+VLOOKUP(U27,$B$5:$G$15,6,FALSE),"") -> 26.506151 | X27: SDL | Y27: Y | Z27: SDL
B28: SEA | C28: 7 | D28: 6 | E28: =C28-D28 -> 1 | I28: 5 | J28: RFCLA | K28: SEA | L28: 35 | M28: 29 | N28: =IFERROR(mean+0.5*Home_edge+VLOOKUP(J28,$B$5:$G$15,4,FALSE)+VLOOKUP(K28,$B$5:$G$15,6,FALSE),"") -> 27.651081 | O28: =IFERROR(mean-0.5*Home_edge+VLOOKUP(K28,$B$5:$G$15,4,FALSE)+VLOOKUP(J28,$B$5:$G$15,6,FALSE),"") -> 25.329696 | P28: =IFERROR((N28-L28)^2+(O28-M28)^2,"") -> 67.477745 | Q28: =VLOOKUP($J28,$B$5:$G$15,4, FALSE)+VLOOKUP($K28,$B$5:$G$15,6, FALSE) -> 3.0441572 | R28: =VLOOKUP($K28,$B$5:$G$15,4, FALSE)+VLOOKUP($J28,$B$5:$G$15,6, FALSE) -> 4.3858843 | U28: HOU | V28: =IFERROR(mean+0.5*Home_edge+VLOOKUP(U28,$B$5:$G$15,4,FALSE)+VLOOKUP(X28,$B$5:$G$15,6,FALSE),"") -> 23.89897 | W28: =IFERROR(mean-0.5*Home_edge+VLOOKUP(X28,$B$5:$G$15,4,FALSE)+VLOOKUP(U28,$B$5:$G$15,6,FALSE),"") -> 16.456238 | X28: SEA | Y28: Y | Z28: HOU | AC28: parlay analyzer
B29: OGDC | C29: 8 | D29: 8 | E29: =C29-D29 -> 0 | I29: 6 | J29: OGDC | K29: NEFJ | L29: 28 | M29: 15 | N29: =IFERROR(mean+0.5*Home_edge+VLOOKUP(J29,$B$5:$G$15,4,FALSE)+VLOOKUP(K29,$B$5:$G$15,6,FALSE),"") -> 18.373054 | O29: =IFERROR(mean-0.5*Home_edge+VLOOKUP(K29,$B$5:$G$15,4,FALSE)+VLOOKUP(J29,$B$5:$G$15,6,FALSE),"") -> 23.042605 | P29: =IFERROR((N29-L29)^2+(O29-M29)^2,"") -> 157.3616 | Q29: =VLOOKUP($J29,$B$5:$G$15,4, FALSE)+VLOOKUP($K29,$B$5:$G$15,6, FALSE) -> -6.2338697 | R29: =VLOOKUP($K29,$B$5:$G$15,4, FALSE)+VLOOKUP($J29,$B$5:$G$15,6, FALSE) -> 2.0987935 | U29: CHI | V29: =IFERROR(mean+0.5*Home_edge+VLOOKUP(U29,$B$5:$G$15,4,FALSE)+VLOOKUP(X29,$B$5:$G$15,6,FALSE),"") -> 17.582278 | W29: =IFERROR(mean-0.5*Home_edge+VLOOKUP(X29,$B$5:$G$15,4,FALSE)+VLOOKUP(U29,$B$5:$G$15,6,FALSE),"") -> 15.49433 | X29: NEFJ | Y29: Y | Z29: CHI | AC29: CHI | AD29: SDL | AE29: UTAH | AF29: CHI | AG29: SDL | AH29: UTAH
B30: MIA | C30: 9 | D30: 10 | E30: =C30-D30 -> -1 | I30: 6 | J30: ARC | K30: HOU | L30: 45 | M30: 46 | N30: =IFERROR(mean+0.5*Home_edge+VLOOKUP(J30,$B$5:$G$15,4,FALSE)+VLOOKUP(K30,$B$5:$G$15,6,FALSE),"") -> 15.242789 | O30: =IFERROR(mean-0.5*Home_edge+VLOOKUP(K30,$B$5:$G$15,4,FALSE)+VLOOKUP(J30,$B$5:$G$15,6,FALSE),"") -> 34.259654 | P30: =IFERROR((N30-L30)^2+(O30-M30)^2,"") -> 1023.3273 | Q30: =VLOOKUP($J30,$B$5:$G$15,4, FALSE)+VLOOKUP($K30,$B$5:$G$15,6, FALSE) -> -9.3641346 | R30: =VLOOKUP($K30,$B$5:$G$15,4, FALSE)+VLOOKUP($J30,$B$5:$G$15,6, FALSE) -> 13.315842 | T30: 4 | U30: UTAH | V30: =IFERROR(mean+0.5*Home_edge+VLOOKUP(U30,$B$5:$G$15,4,FALSE)+VLOOKUP(X30,$B$5:$G$15,6,FALSE),"") -> 24.953562 | W30: =IFERROR(mean-0.5*Home_edge+VLOOKUP(X30,$B$5:$G$15,4,FALSE)+VLOOKUP(U30,$B$5:$G$15,6,FALSE),"") -> 22.473827 | X30: HOU | Y30: N | Z30: UTAH | AC30: W | AD30: W | AE30: W | AF30: =IF(AC30="W", 18.69, 0) -> 18.69 | AG30: =IF(AD30="W", 18.69, 0) -> 18.69 | AH30: =IF(AE30="W", 19.52, 0) -> 19.52
B31: NOLA | C31: 10 | D31: 9 | E31: =C31-D31 -> 1 | I31: 6 | J31: NOLA | K31: RFCLA | L31: 24 | M31: 31 | N31: =IFERROR(mean+0.5*Home_edge+VLOOKUP(J31,$B$5:$G$15,4,FALSE)+VLOOKUP(K31,$B$5:$G$15,6,FALSE),"") -> 27.184853 | O31: =IFERROR(mean-0.5*Home_edge+VLOOKUP(K31,$B$5:$G$15,4,FALSE)+VLOOKUP(J31,$B$5:$G$15,6,FALSE),"") -> 28.304178 | P31: =IFERROR((N31-L31)^2+(O31-M31)^2,"") -> 17.410745 | Q31: =VLOOKUP($J31,$B$5:$G$15,4, FALSE)+VLOOKUP($K31,$B$5:$G$15,6, FALSE) -> 2.5779299 | R31: =VLOOKUP($K31,$B$5:$G$15,4, FALSE)+VLOOKUP($J31,$B$5:$G$15,6, FALSE) -> 7.3603665 | U31: OGDC | V31: =IFERROR(mean+0.5*Home_edge+VLOOKUP(U31,$B$5:$G$15,4,FALSE)+VLOOKUP(X31,$B$5:$G$15,6,FALSE),"") -> 36.654449 | W31: =IFERROR(mean-0.5*Home_edge+VLOOKUP(X31,$B$5:$G$15,4,FALSE)+VLOOKUP(U31,$B$5:$G$15,6,FALSE),"") -> 19.459003 | X31: ARC | Y31: Y | Z31: OGDC | AC31: W | AD31: W | AE31: L | AF31: =IF(AC31="W", 18.69, 0) -> 18.69 | AG31: =IF(AD31="W", 18.69, 0) -> 18.69 | AH31: =IF(AE31="W", 19.52, 0) -> 0
B32: ARC | C32: 11 | D32: 11 | E32: =C32-D32 -> 0 | I32: 6 | J32: SDL | K32: MIA | L32: 31 | M32: 12 | N32: =IFERROR(mean+0.5*Home_edge+VLOOKUP(J32,$B$5:$G$15,4,FALSE)+VLOOKUP(K32,$B$5:$G$15,6,FALSE),"") -> 28.367648 | O32: =IFERROR(mean-0.5*Home_edge+VLOOKUP(K32,$B$5:$G$15,4,FALSE)+VLOOKUP(J32,$B$5:$G$15,6,FALSE),"") -> 16.426783 | P32: =IFERROR((N32-L32)^2+(O32-M32)^2,"") -> 26.525687 | Q32: =VLOOKUP($J32,$B$5:$G$15,4, FALSE)+VLOOKUP($K32,$B$5:$G$15,6, FALSE) -> 3.7607249 | R32: =VLOOKUP($K32,$B$5:$G$15,4, FALSE)+VLOOKUP($J32,$B$5:$G$15,6, FALSE) -> -4.5170285 | U32: MIA | V32: =IFERROR(mean+0.5*Home_edge+VLOOKUP(U32,$B$5:$G$15,4,FALSE)+VLOOKUP(X32,$B$5:$G$15,6,FALSE),"") -> 15.629356 | W32: =IFERROR(mean-0.5*Home_edge+VLOOKUP(X32,$B$5:$G$15,4,FALSE)+VLOOKUP(U32,$B$5:$G$15,6,FALSE),"") -> 20.549666 | X32: CHI | Y32: Y | Z32: CHI | AC32: L | AD32: W | AE32: W | AF32: =IF(AC32="W", 18.69, 0) -> 0 | AG32: =IF(AD32="W", 18.69, 0) -> 18.69 | AH32: =IF(AE32="W", 19.52, 0) -> 19.52
I33: 6 | J33: SEA | K33: UTAH | L33: 27 | M33: 30 | N33: =IFERROR(mean+0.5*Home_edge+VLOOKUP(J33,$B$5:$G$15,4,FALSE)+VLOOKUP(K33,$B$5:$G$15,6,FALSE),"") -> 26.06213 | O33: =IFERROR(mean-0.5*Home_edge+VLOOKUP(K33,$B$5:$G$15,4,FALSE)+VLOOKUP(J33,$B$5:$G$15,6,FALSE),"") -> 24.995262 | P33: =IFERROR((N33-L33)^2+(O33-M33)^2,"") -> 25.926998 | Q33: =VLOOKUP($J33,$B$5:$G$15,4, FALSE)+VLOOKUP($K33,$B$5:$G$15,6, FALSE) -> 1.455207 | R33: =VLOOKUP($K33,$B$5:$G$15,4, FALSE)+VLOOKUP($J33,$B$5:$G$15,6, FALSE) -> 4.0514504 | U33: SDL | V33: =IFERROR(mean+0.5*Home_edge+VLOOKUP(U33,$B$5:$G$15,4,FALSE)+VLOOKUP(X33,$B$5:$G$15,6,FALSE),"") -> 31.163395 | W33: =IFERROR(mean-0.5*Home_edge+VLOOKUP(X33,$B$5:$G$15,4,FALSE)+VLOOKUP(U33,$B$5:$G$15,6,FALSE),"") -> 25.074745 | X33: RFCLA | Y33: Y | Z33: SDL | AC33: W | AD33: L | AE33: W | AF33: =IF(AC33="W", 18.69, 0) -> 18.69 | AG33: =IF(AD33="W", 18.69, 0) -> 0 | AH33: =IF(AE33="W", 19.52, 0) -> 19.52
I34: 7 | J34: NOLA | K34: CHI | L34: 18 | M34: 20 | N34: =IFERROR(mean+0.5*Home_edge+VLOOKUP(J34,$B$5:$G$15,4,FALSE)+VLOOKUP(K34,$B$5:$G$15,6,FALSE),"") -> 18.642445 | O34: =IFERROR(mean-0.5*Home_edge+VLOOKUP(K34,$B$5:$G$15,4,FALSE)+VLOOKUP(J34,$B$5:$G$15,6,FALSE),"") -> 22.492977 | P34: =IFERROR((N34-L34)^2+(O34-M34)^2,"") -> 6.6276698 | Q34: =VLOOKUP($J34,$B$5:$G$15,4, FALSE)+VLOOKUP($K34,$B$5:$G$15,6, FALSE) -> -5.9644787 | R34: =VLOOKUP($K34,$B$5:$G$15,4, FALSE)+VLOOKUP($J34,$B$5:$G$15,6, FALSE) -> 1.5491651 | U34: SEA | V34: =IFERROR(mean+0.5*Home_edge+VLOOKUP(U34,$B$5:$G$15,4,FALSE)+VLOOKUP(X34,$B$5:$G$15,6,FALSE),"") -> 19.566561 | W34: =IFERROR(mean-0.5*Home_edge+VLOOKUP(X34,$B$5:$G$15,4,FALSE)+VLOOKUP(U34,$B$5:$G$15,6,FALSE),"") -> 18.868092 | X34: NEFJ | Y34: Y | Z34: SEA | AC34: W | AD34: L | AE34: L | AF34: =IF(AC34="W", 18.69, 0) -> 18.69 | AG34: =IF(AD34="W", 18.69, 0) -> 0 | AH34: =IF(AE34="W", 19.52, 0) -> 0
I35: 7 | J35: HOU | K35: SDL | L35: 34 | M35: 14 | N35: =IFERROR(mean+0.5*Home_edge+VLOOKUP(J35,$B$5:$G$15,4,FALSE)+VLOOKUP(K35,$B$5:$G$15,6,FALSE),"") -> 24.985746 | O35: =IFERROR(mean-0.5*Home_edge+VLOOKUP(K35,$B$5:$G$15,4,FALSE)+VLOOKUP(J35,$B$5:$G$15,6,FALSE),"") -> 18.626826 | P35: =IFERROR((N35-L35)^2+(O35-M35)^2,"") -> 102.66429 | Q35: =VLOOKUP($J35,$B$5:$G$15,4, FALSE)+VLOOKUP($K35,$B$5:$G$15,6, FALSE) -> 0.3788229 | R35: =VLOOKUP($K35,$B$5:$G$15,4, FALSE)+VLOOKUP($J35,$B$5:$G$15,6, FALSE) -> -2.3169859 | T35: 5 | U35: CHI | V35: =IFERROR(mean+0.5*Home_edge+VLOOKUP(U35,$B$5:$G$15,4,FALSE)+VLOOKUP(X35,$B$5:$G$15,6,FALSE),"") -> 26.014392 | W35: =IFERROR(mean-0.5*Home_edge+VLOOKUP(X35,$B$5:$G$15,4,FALSE)+VLOOKUP(U35,$B$5:$G$15,6,FALSE),"") -> 15.59378 | X35: OGDC | Y35: Y | Z35: CHI | AC35: L | AD35: W | AE35: L | AF35: =IF(AC35="W", 18.69, 0) -> 0 | AG35: =IF(AD35="W", 18.69, 0) -> 18.69 | AH35: =IF(AE35="W", 19.52, 0) -> 0
I36: 7 | J36: SEA | K36: ARC | L36: 25 | M36: 17 | N36: =IFERROR(mean+0.5*Home_edge+VLOOKUP(J36,$B$5:$G$15,4,FALSE)+VLOOKUP(K36,$B$5:$G$15,6,FALSE),"") -> 37.847957 | O36: =IFERROR(mean-0.5*Home_edge+VLOOKUP(K36,$B$5:$G$15,4,FALSE)+VLOOKUP(J36,$B$5:$G$15,6,FALSE),"") -> 15.28449 | P36: =IFERROR((N36-L36)^2+(O36-M36)^2,"") -> 168.01298 | Q36: =VLOOKUP($J36,$B$5:$G$15,4, FALSE)+VLOOKUP($K36,$B$5:$G$15,6, FALSE) -> 13.241034 | R36: =VLOOKUP($K36,$B$5:$G$15,4, FALSE)+VLOOKUP($J36,$B$5:$G$15,6, FALSE) -> -5.6593224 | U36: NEFJ | V36: =IFERROR(mean+0.5*Home_edge+VLOOKUP(U36,$B$5:$G$15,4,FALSE)+VLOOKUP(X36,$B$5:$G$15,6,FALSE),"") -> 26.847413 | W36: =IFERROR(mean-0.5*Home_edge+VLOOKUP(X36,$B$5:$G$15,4,FALSE)+VLOOKUP(U36,$B$5:$G$15,6,FALSE),"") -> 14.095495 | X36: NOLA | Y36: Y | Z36: NEFJ | AC36: L | AD36: L | AE36: W | AF36: =IF(AC36="W", 18.69, 0) -> 0 | AG36: =IF(AD36="W", 18.69, 0) -> 0 | AH36: =IF(AE36="W", 19.52, 0) -> 19.52
I37: 7 | J37: UTAH | K37: NEFJ | L37: 26 | M37: 33 | N37: =IFERROR(mean+0.5*Home_edge+VLOOKUP(J37,$B$5:$G$15,4,FALSE)+VLOOKUP(K37,$B$5:$G$15,6,FALSE),"") -> 24.400773 | O37: =IFERROR(mean-0.5*Home_edge+VLOOKUP(K37,$B$5:$G$15,4,FALSE)+VLOOKUP(J37,$B$5:$G$15,6,FALSE),"") -> 21.106061 | P37: =IFERROR((N37-L37)^2+(O37-M37)^2,"") -> 144.02332 | Q37: =VLOOKUP($J37,$B$5:$G$15,4, FALSE)+VLOOKUP($K37,$B$5:$G$15,6, FALSE) -> -0.2061503 | R37: =VLOOKUP($K37,$B$5:$G$15,4, FALSE)+VLOOKUP($J37,$B$5:$G$15,6, FALSE) -> 0.16224882 | U37: MIA | V37: =IFERROR(mean+0.5*Home_edge+VLOOKUP(U37,$B$5:$G$15,4,FALSE)+VLOOKUP(X37,$B$5:$G$15,6,FALSE),"") -> 21.241087 | W37: =IFERROR(mean-0.5*Home_edge+VLOOKUP(X37,$B$5:$G$15,4,FALSE)+VLOOKUP(U37,$B$5:$G$15,6,FALSE),"") -> 27.368161 | X37: UTAH | Y37: Y | Z37: UTAH | AC37: L | AD37: L | AE37: L | AF37: =IF(AC37="W", 18.69, 0) -> 0 | AG37: =IF(AD37="W", 18.69, 0) -> 0 | AH37: =IF(AE37="W", 19.52, 0) -> 0
I38: 7 | J38: RFCLA | K38: OGDC | L38: 54 | M38: 44 | N38: =IFERROR(mean+0.5*Home_edge+VLOOKUP(J38,$B$5:$G$15,4,FALSE)+VLOOKUP(K38,$B$5:$G$15,6,FALSE),"") -> 31.825594 | O38: =IFERROR(mean-0.5*Home_edge+VLOOKUP(K38,$B$5:$G$15,4,FALSE)+VLOOKUP(J38,$B$5:$G$15,6,FALSE),"") -> 24.136189 | P38: =IFERROR((N38-L38)^2+(O38-M38)^2,"") -> 886.2753 | Q38: =VLOOKUP($J38,$B$5:$G$15,4, FALSE)+VLOOKUP($K38,$B$5:$G$15,6, FALSE) -> 7.2186701 | R38: =VLOOKUP($K38,$B$5:$G$15,4, FALSE)+VLOOKUP($J38,$B$5:$G$15,6, FALSE) -> 3.1923766 | U38: RFCLA | V38: =IFERROR(mean+0.5*Home_edge+VLOOKUP(U38,$B$5:$G$15,4,FALSE)+VLOOKUP(X38,$B$5:$G$15,6,FALSE),"") -> 27.651081 | W38: =IFERROR(mean-0.5*Home_edge+VLOOKUP(X38,$B$5:$G$15,4,FALSE)+VLOOKUP(U38,$B$5:$G$15,6,FALSE),"") -> 25.329696 | X38: SEA | Y38: N | Z38: SEA
I39: 8 | J39: OGDC | K39: SEA | L39: 29 | M39: 12 | N39: =IFERROR(mean+0.5*Home_edge+VLOOKUP(J39,$B$5:$G$15,4,FALSE)+VLOOKUP(K39,$B$5:$G$15,6,FALSE),"") -> 22.630654 | O39: =IFERROR(mean-0.5*Home_edge+VLOOKUP(K39,$B$5:$G$15,4,FALSE)+VLOOKUP(J39,$B$5:$G$15,6,FALSE),"") -> 24.335564 | P39: =IFERROR((N39-L39)^2+(O39-M39)^2,"") -> 192.73469 | Q39: =VLOOKUP($J39,$B$5:$G$15,4, FALSE)+VLOOKUP($K39,$B$5:$G$15,6, FALSE) -> -1.976269 | R39: =VLOOKUP($K39,$B$5:$G$15,4, FALSE)+VLOOKUP($J39,$B$5:$G$15,6, FALSE) -> 3.3917517 | T39: 6 | U39: OGDC | V39: 13.804044 | W39: 13.067094 | X39: NEFJ | Y39: Y | Z39: OGDC
I40: 8 | J40: ARC | K40: NOLA | L40: 19 | M40: 33 | N40: =IFERROR(mean+0.5*Home_edge+VLOOKUP(J40,$B$5:$G$15,4,FALSE)+VLOOKUP(K40,$B$5:$G$15,6,FALSE),"") -> 23.26381 | O40: =IFERROR(mean-0.5*Home_edge+VLOOKUP(K40,$B$5:$G$15,4,FALSE)+VLOOKUP(J40,$B$5:$G$15,6,FALSE),"") -> 32.376891 | P40: =IFERROR((N40-L40)^2+(O40-M40)^2,"") -> 18.568344 | Q40: =VLOOKUP($J40,$B$5:$G$15,4, FALSE)+VLOOKUP($K40,$B$5:$G$15,6, FALSE) -> -1.343113 | R40: =VLOOKUP($K40,$B$5:$G$15,4, FALSE)+VLOOKUP($J40,$B$5:$G$15,6, FALSE) -> 11.433079 | U40: ARC | V40: 5.9253455 | W40: 42.955169 | X40: HOU | Y40: Y | Z40: HOU
...

Sheet PlayerIDs
A1: Abe Turpen | B1: 811
A2: Adriaan Carelse | B2: 4
A3: Aidan King | B3: 812
A4: AJ Alatimu | B4: 6
A5: Aki Seiuli | B5: 858
A6: Albert O'Shannessey | B6: 527
A7: Alec McDonnell | B7: 8
A8: Alejandro Martinez Tapia | B8: 827
A9: Alesana Pohla | B9: 687
A10: Alessandro Heaney | B10: 589
A11: Alex Lopeti | B11: 7
A12: Alex Maughan | B12: 14
... A433: Zurab Zhvania | B433: 546

Sheet FRvsDef
A1: FR vs Def 2025 | F1: Finished Week: | G1: 13
B2: 0
A3: Mean: | B3: =AVERAGE(B6:B49) -> 6.1036242e-09 | F3: Home | G3: 0.076396245
A4: (highest rank is most helpful matchup) | F4: Away | G4: =-G3 -> -0.076396245
A5: Team | B5: Rating | C5: Rank | Q5: =SUM($Q$7:$Q1000) -> 2470.0599
A6: SDL | B6: 1.4302 | C6: =RANK($B6,$B$6:$B$16,0) -> 1 | J6: Rnd | K6: Team | L6: Player | M6: Points | N6: home | O6: Opp | P6: Forecast | Q6: Squared Error | R6: GroupRnk | T6: Remaining Games for ROFS Calc
A7: ARC | B7: 0.56968285 | C7: =RANK($B7,$B$6:$B$16,0) -> 2 | J7: 1 | K7: NOLA | L7: Pat O'Toole | M7: 15.2 | N7: Home | O7: ARC | P7: =VLOOKUP($N7,$F$3:$G$4,2,FALSE)+VLOOKUP($L7,$B$20:$C$150,2,FALSE)+VLOOKUP($O7,$A$6:$B$16,2,FALSE) -> 11.693074 | Q7: =IFERROR(($M7-$P7)^2,"") -> 12.298529 | R7: {=SUMPRODUCT((J7=$J$7:$J$1000)*(P7<$P$7:$P$1000))+1} -> 1 | T7: {=_xlfn._xlws.FILTER($J$7:$P$10000,($J$7:$J$10000>$G$1)*($J$7:$J$10000<18))} -> 14 | U7: ARC | V7: Alex Maughan | W7: NULL | X7: Home | Y7: OGDC | Z7: 2.8843747
A8: LA | B8: 0.36202543 | C8: =RANK($B8,$B$6:$B$16,0) -> 3 | J8: 1 | K8: NEFJ | L8: Kaleb Geiger | M8: 8.6 | N8: Away | O8: LA | P8: =VLOOKUP($N8,$F$3:$G$4,2,FALSE)+VLOOKUP($L8,$B$20:$C$150,2,FALSE)+VLOOKUP($O8,$A$6:$B$16,2,FALSE) -> 5.9737489 | Q8: =IFERROR(($M8-$P8)^2,"") -> 6.897195 | R8: {=SUMPRODUCT((J8=$J$7:$J$1000)*(P8<$P$7:$P$1000))+1} -> 7 | T8: 14 | U8: ARC | V8: Alexander Hernandez | W8: NULL | X8: Home | Y8: OGDC | Z8: 1.3514586
A9: NEFJ | B9: 0.22713605 | C9: =RANK($B9,$B$6:$B$16,0) -> 4 | J9: 1 | K9: SEA | L9: Cameron Orr | M9: 7.7 | N9: Away | O9: SDL | P9: =VLOOKUP($N9,$F$3:$G$4,2,FALSE)+VLOOKUP($L9,$B$20:$C$150,2,FALSE)+VLOOKUP($O9,$A$6:$B$16,2,FALSE) -> 6.9103973 | Q9: =IFERROR(($M9-$P9)^2,"") -> 0.62347246 | R9: {=SUMPRODUCT((J9=$J$7:$J$1000)*(P9<$P$7:$P$1000))+1} -> 4 | T9: 14 | U9: ARC | V9: Connor Robinson | W9: NULL | X9: Home | Y9: OGDC | Z9: 5.0191906
A10: HOU | B10: 0.1496193 | C10: =RANK($B10,$B$6:$B$16,0) -> 5 | J10: 1 | K10: NEFJ | L10: Andrew Quattrin | M10: 7.6 | N10: Away | O10: LA | P10: =VLOOKUP($N10,$F$3:$G$4,2,FALSE)+VLOOKUP($L10,$B$20:$C$150,2,FALSE)+VLOOKUP($O10,$A$6:$B$16,2,FALSE) -> 6.4561451 | Q10: =IFERROR(($M10-$P10)^2,"") -> 1.3084039 | R10: {=SUMPRODUCT((J10=$J$7:$J$1000)*(P10<$P$7:$P$1000))+1} -> 6 | T10: 14 | U10: ARC | V10: Dan Hanson | W10: NULL | X10: Home | Y10: OGDC | Z10: 1.435512
A11: NOLA | B11: 0.070668616 | C11: =RANK($B11,$B$6:$B$16,0) -> 6 | J11: 1 | K11: CHI | L11: Dylan Fawsitt | M11: 7.2 | N11: Away | O11: HOU | P11: =VLOOKUP($N11,$F$3:$G$4,2,FALSE)+VLOOKUP($L11,$B$20:$C$150,2,FALSE)+VLOOKUP($O11,$A$6:$B$16,2,FALSE) -> 7.8761386 | Q11: =IFERROR(($M11-$P11)^2,"") -> 0.45716337 | R11: {=SUMPRODUCT((J11=$J$7:$J$1000)*(P11<$P$7:$P$1000))+1} -> 2 | T11: 14 | U11: ARC | V11: Ethan Howard | W11: NULL | X11: Home | Y11: OGDC | Z11: 5.2756223
A12: CHI | B12: -0.028426274 | C12: =RANK($B12,$B$6:$B$16,0) -> 7 | J12: 1 | K12: MIA | L12: Ma'ake Muti | M12: 6.6 | N12: Home | O12: OGDC | P12: =VLOOKUP($N12,$F$3:$G$4,2,FALSE)+VLOOKUP($L12,$B$20:$C$150,2,FALSE)+VLOOKUP($O12,$A$6:$B$16,2,FALSE) -> 2.3146356 | Q12: =IFERROR(($M12-$P12)^2,"") -> 18.364348 | R12: {=SUMPRODUCT((J12=$J$7:$J$1000)*(P12<$P$7:$P$1000))+1} -> 26 | T12: 14 | U12: ARC | V12: Jake Turnbull | W12: NULL | X12: Home | Y12: OGDC | Z12: 3.0778227
A13: MIA | B13: -0.26375398 | C13: =RANK($B13,$B$6:$B$16,0) -> 8 | J13: 1 | K13: CHI | L13: Charlie Abel | M13: 5.3 | N13: Away | O13: HOU | P13: =VLOOKUP($N13,$F$3:$G$4,2,FALSE)+VLOOKUP($L13,$B$20:$C$150,2,FALSE)+VLOOKUP($O13,$A$6:$B$16,2,FALSE) -> 3.7295944 | Q13: =IFERROR(($M13-$P13)^2,"") -> 2.4661736 | R13: {=SUMPRODUCT((J13=$J$7:$J$1000)*(P13<$P$7:$P$1000))+1} -> 18 | T13: 14 | U13: ARC | V13: Joe Apikotoa | W13: NULL | X13: Home | Y13: OGDC | Z13: 4.4938413
A14: SEA | B14: -0.52755576 | C14: =RANK($B14,$B$6:$B$16,0) -> 9 | J14: 1 | K14: OGDC | L14: Facundo Gattas | M14: 4.7 | N14: Away | O14: MIA | P14: =VLOOKUP($N14,$F$3:$G$4,2,FALSE)+VLOOKUP($L14,$B$20:$C$150,2,FALSE)+VLOOKUP($O14,$A$6:$B$16,2,FALSE) -> 5.0533443 | Q14: =IFERROR(($M14-$P14)^2,"") -> 0.12485219 | R14: {=SUMPRODUCT((J14=$J$7:$J$1000)*(P14<$P$7:$P$1000))+1} -> 10 | T14: 14 | U14: ARC | V14: Stephan Bernal-Wendt | W14: NULL | X14: Home | Y14: OGDC | Z14: 2.4237843
A15: OGDC | B15: -0.63922174 | C15: =RANK($B15,$B$6:$B$16,0) -> 10 | J15: 1 | K15: HOU | L15: Pono Davis | M15: 4.1 | N15: Home | O15: CHI | P15: =VLOOKUP($N15,$F$3:$G$4,2,FALSE)+VLOOKUP($L15,$B$20:$C$150,2,FALSE)+VLOOKUP($O15,$A$6:$B$16,2,FALSE) -> 3.204212 | Q15: =IFERROR(($M15-$P15)^2,"") -> 0.8024361 | R15: {=SUMPRODUCT((J15=$J$7:$J$1000)*(P15<$P$7:$P$1000))+1} -> 21 | T15: 14 | U15: CHI | V15: Charlie Abel | W15: NULL | X15: Home | Y15: LA | Z15: 4.0947931
A16: UTAH | B16: -1.3503744 | C16: =RANK($B16,$B$6:$B$16,0) -> 11 | J16: 1 | K16: HOU | L16: Seth Smith | M16: 4 | N16: Home | O16: CHI | P16: =VLOOKUP($N16,$F$3:$G$4,2,FALSE)+VLOOKUP($L16,$B$20:$C$150,2,FALSE)+VLOOKUP($O16,$A$6:$B$16,2,FALSE) -> 5.7124413 | Q16: =IFERROR(($M16-$P16)^2,"") -> 2.9324552 | R16: {=SUMPRODUCT((J16=$J$7:$J$1000)*(P16<$P$7:$P$1000))+1} -> 9 | T16: 14 | U16: CHI | V16: Dylan Fawsitt | W16: NULL | X16: Home | Y16: LA | Z16: 8.2413372
J17: 1 | K17: LA | L17: Alessandro Heaney | M17: 4 | N17: Home | O17: NEFJ | P17: =VLOOKUP($N17,$F$3:$G$4,2,FALSE)+VLOOKUP($L17,$B$20:$C$150,2,FALSE)+VLOOKUP($O17,$A$6:$B$16,2,FALSE) -> 3.7835866 | Q17: =IFERROR(($M17-$P17)^2,"") -> 0.04683475 | R17: {=SUMPRODUCT((J17=$J$7:$J$1000)*(P17<$P$7:$P$1000))+1} -> 17 | T17: 14 | U17: CHI | V17: Faka'osi Pifeleti | W17: NULL | X17: Home | Y17: LA | Z17: 2.807155
J18: 1 | K18: SDL | L18: Hugh Roach | M18: 3.9 | N18: Home | O18: SEA | P18: =VLOOKUP($N18,$F$3:$G$4,2,FALSE)+VLOOKUP($L18,$B$20:$C$150,2,FALSE)+VLOOKUP($O18,$A$6:$B$16,2,FALSE) -> 6.9577449 | Q18: =IFERROR(($M18-$P18)^2,"") -> 9.3498039 | R18: {=SUMPRODUCT((J18=$J$7:$J$1000)*(P18<$P$7:$P$1000))+1} -> 3 | T18: 14 | U18: CHI | V18: Ignacio Peculo | W18: NULL | X18: Home | Y18: LA | Z18: 5.9127591
A19: PlayerID | B19: Player | C19: OverallRating | D19: OverallRank | E19: WeeklyRating | F19: WeeklyRank | G19: ROFSRating | H19: ROFSRank | I19: Last5GamesStart% | J19: 1 | K19: NEFJ | L19: Malakai Hala-Ngatai | M19: 3.7 | N19: Away | O19: LA | P19: =VLOOKUP($N19,$F$3:$G$4,2,FALSE)+VLOOKUP($L19,$B$20:$C$150,2,FALSE)+VLOOKUP($O19,$A$6:$B$16,2,FALSE) -> 2.2794781 | Q19: =IFERROR(($M19-$P19)^2,"") -> 2.0178825 | R19: {=SUMPRODUCT((J19=$J$7:$J$1000)*(P19<$P$7:$P$1000))+1} -> 28 | T19: 14 | U19: CHI | V19: Janus Venter | W19: NULL | X19: Home | Y19: LA | Z19: 4.5467103
A20: =VLOOKUP($B20, PlayerIDs!$A$1:$B$1000, 2, FALSE) -> 32 | B20: Ben Strang | C20: 11.05214 | D20: =RANK($C20,$C$20:$C$106) -> 1 | E20: {=IFERROR(VLOOKUP($B20,_xlfn._xlws.FILTER($L$7:$P$10000,$J$7:$J$10000=G$1+1),5, FALSE), 0)} -> 10.947317 | F20: =RANK(E20,$E$20:$E$150) -> 1 | G20: =SUMIF(V:Z,$B20,Z:Z) -> 32.148621 | H20: =RANK($G20,$G$20:$G$106) -> 1 | I20: {=COUNT(_xlfn._xlws.FILTER($J$7:$J$10000,($L$7:$L$10000=B20)*($M$7:$M$10000<>"NULL")*($J$7:$J$10000 >= ($G$1-4))))/5} -> 0.2 | J20: 1 | K20: SDL | L20: Darcy Breen | M20: 3.6 | N20: Home | O20: SEA | P20: =VLOOKUP($N20,$F$3:$G$4,2,FALSE)+VLOOKUP($L20,$B$20:$C$150,2,FALSE)+VLOOKUP($O20,$A$6:$B$16,2,FALSE) -> 3.6377643 | Q20: =IFERROR(($M20-$P20)^2,"") -> 0.0014261433 | R20: {=SUMPRODUCT((J20=$J$7:$J$1000)*(P20<$P$7:$P$1000))+1} -> 19 | T20: 14 | U20: CHI | V20: Paddy Ryan | W20: NULL | X20: Home | Y20: LA | Z20: 2.8635043
A21: =VLOOKUP($B21, PlayerIDs!$A$1:$B$1000, 2, FALSE) -> 343 | B21: Pat O'Toole | C21: 11.046995 | D21: =RANK($C21,$C$20:$C$106) -> 2 | E21: {=IFERROR(VLOOKUP($B21,_xlfn._xlws.FILTER($L$7:$P$10000,$J$7:$J$10000=G$1+1),5, FALSE), 0)} -> 0 | F21: =RANK(E21,$E$20:$E$150) -> 74 | G21: =SUMIF(V:Z,$B21,Z:Z) -> 20.71519 | H21: =RANK($G21,$G$20:$G$106) -> 8 | I21: {=COUNT(_xlfn._xlws.FILTER($J$7:$J$10000,($L$7:$L$10000=B21)*($M$7:$M$10000<>"NULL")*($J$7:$J$10000 >= ($G$1-4))))/5} -> 0 | J21: 1 | K21: SDL | L21: Payton Telea-Ilalio | M21: 3.6 | N21: Home | O21: SEA | P21: =VLOOKUP($N21,$F$3:$G$4,2,FALSE)+VLOOKUP($L21,$B$20:$C$150,2,FALSE)+VLOOKUP($O21,$A$6:$B$16,2,FALSE) -> 4.1520716 | Q21: =IFERROR(($M21-$P21)^2,"") -> 0.30478309 | R21: {=SUMPRODUCT((J21=$J$7:$J$1000)*(P21<$P$7:$P$1000))+1} -> 15 | T21: 14 | U21: CHI | V21: Zurab Zhvania | W21: NULL | X21: Home | Y21: LA | Z21: 6.4203012
A22: =VLOOKUP($B22, PlayerIDs!$A$1:$B$1000, 2, FALSE) -> 726 | B22: Shilo Klein | C22: 10.747806 | D22: =RANK($C22,$C$20:$C$106) -> 3 | E22: {=IFERROR(VLOOKUP($B22,_xlfn._xlws.FILTER($L$7:$P$10000,$J$7:$J$10000=G$1+1),5, FALSE), 0)} -> 10.143854 | F22: =RANK(E22,$E$20:$E$150) -> 2 | G22: =SUMIF(V:Z,$B22,Z:Z) -> 20.55151 | H22: =RANK($G22,$G$20:$G$106) -> 9 | I22: {=COUNT(_xlfn._xlws.FILTER($J$7:$J$10000,($L$7:$L$10000=B22)*($M$7:$M$10000<>"NULL")*($J$7:$J$10000 >= ($G$1-4))))/5} -> 0.2 | J22: 1 | K22: SEA | L22: Juan Pablo Zeiss | M22: 3.6 | N22: Away | O22: SDL | P22: =VLOOKUP($N22,$F$3:$G$4,2,FALSE)+VLOOKUP($L22,$B$20:$C$150,2,FALSE)+VLOOKUP($O22,$A$6:$B$16,2,FALSE) -> 4.3102084 | Q22: =IFERROR(($M22-$P22)^2,"") -> 0.50439602 | R22: {=SUMPRODUCT((J22=$J$7:$J$1000)*(P22<$P$7:$P$1000))+1} -> 14 | T22: 14 | U22: HOU | V22: Ezekiel Lindenmuth | W22: NULL | X22: Home | Y22: UTAH | Z22: 2.765179
A23: =VLOOKUP($B23, PlayerIDs!$A$1:$B$1000, 2, FALSE) -> 738 | B23: Liam Coltman | C23: 9.2229621 | D23: =RANK($C23,$C$20:$C$106) -> 4 | E23: {=IFERROR(VLOOKUP($B23,_xlfn._xlws.FILTER($L$7:$P$10000,$J$7:$J$10000=G$1+1),5, FALSE), 0)} -> 9.2961852 | F23: =RANK(E23,$E$20:$E$150) -> 3 | G23: =SUMIF(V:Z,$B23,Z:Z) -> 28.382461 | H23: =RANK($G23,$G$20:$G$106) -> 2 | I23: {=COUNT(_xlfn._xlws.FILTER($J$7:$J$10000,($L$7:$L$10000=B23)*($M$7:$M$10000<>"NULL")*($J$7:$J$10000 >= ($G$1-4))))/5} -> 0.8 | J23: 1 | K23: ARC | L23: Ethan Howard | M23: 3.5 | N23: Away | O23: NOLA | P23: =VLOOKUP($N23,$F$3:$G$4,2,FALSE)+VLOOKUP($L23,$B$20:$C$150,2,FALSE)+VLOOKUP($O23,$A$6:$B$16,2,FALSE) -> 5.8327202 | Q23: =IFERROR(($M23-$P23)^2,"") -> 5.4415835 | R23: {=SUMPRODUCT((J23=$J$7:$J$1000)*(P23<$P$7:$P$1000))+1} -> 8 | T23: 14 | U23: HOU | V23: Michael Scott | W23: NULL | X23: Home | Y23: UTAH | Z23: 0.61396838
A24: =VLOOKUP($B24, PlayerIDs!$A$1:$B$1000, 2, FALSE) -> 696 | B24: Pita Anae-Ah Sue | C24: 8.7451072 | D24: =RANK($C24,$C$20:$C$106) -> 5 | E24: {=IFERROR(VLOOKUP($B24,_xlfn._xlws.FILTER($L$7:$P$10000,$J$7:$J$10000=G$1+1),5, FALSE), 0)} -> 7.471129 | F24: =RANK(E24,$E$20:$E$150) -> 8 | G24: =SUMIF(V:Z,$B24,Z:Z) -> 15.612284 | H24: =RANK($G24,$G$20:$G$106) -> 22 | I24: {=COUNT(_xlfn._xlws.FILTER($J$7:$J$10000,($L$7:$L$10000=B24)*($M$7:$M$10000<>"NULL")*($J$7:$J$10000 >= ($G$1-4))))/5} -> 0.8 | J24: 1 | K24: OGDC | L24: Jack Iscaro | M24: 2.9 | N24: Away | O24: MIA | P24: =VLOOKUP($N24,$F$3:$G$4,2,FALSE)+VLOOKUP($L24,$B$20:$C$150,2,FALSE)+VLOOKUP($O24,$A$6:$B$16,2,FALSE) -> 4.4895056 | Q24: =IFERROR(($M24-$P24)^2,"") -> 2.5265279 | R24: {=SUMPRODUCT((J24=$J$7:$J$1000)*(P24<$P$7:$P$1000))+1} -> 13 | T24: 14 | U24: HOU | V24: Pita Anae-Ah Sue | W24: NULL | X24: Home | Y24: UTAH | Z24: 7.471129
A25: =VLOOKUP($B25, PlayerIDs!$A$1:$B$1000, 2, FALSE) -> 124 | B25: Dylan Fawsitt | C25: 7.8029155 | D25: =RANK($C25,$C$20:$C$106) -> 6 | E25: {=IFERROR(VLOOKUP($B25,_xlfn._xlws.FILTER($L$7:$P$10000,$J$7:$J$10000=G$1+1),5, FALSE), 0)} -> 8.2413372 | F25: =RANK(E25,$E$20:$E$150) -> 4 | G25: =SUMIF(V:Z,$B25,Z:Z) -> 24.48752 | H25: =RANK($G25,$G$20:$G$106) -> 3 | I25: {=COUNT(_xlfn._xlws.FILTER($J$7:$J$10000,($L$7:$L$10000=B25)*($M$7:$M$10000<>"NULL")*($J$7:$J$10000 >= ($G$1-4))))/5} -> 0.8 | J25: 1 | K25: ARC | L25: Jake Turnbull | M25: 2.8 | N25: Away | O25: NOLA | P25: =VLOOKUP($N25,$F$3:$G$4,2,FALSE)+VLOOKUP($L25,$B$20:$C$150,2,FALSE)+VLOOKUP($O25,$A$6:$B$16,2,FALSE) -> 3.6349205 | Q25: =IFERROR(($M25-$P25)^2,"") -> 0.69709231 | R25: {=SUMPRODUCT((J25=$J$7:$J$1000)*(P25<$P$7:$P$1000))+1} -> 20 | T25: 14 | U25: HOU | V25: Pono Davis | W25: NULL | X25: Home | Y25: UTAH | Z25: 1.8822639
A26: =VLOOKUP($B26, PlayerIDs!$A$1:$B$1000, 2, FALSE) -> 679 | B26: Phil Bradford | C26: 7.7498686 | D26: =RANK($C26,$C$20:$C$106) -> 7 | E26: {=IFERROR(VLOOKUP($B26,_xlfn._xlws.FILTER($L$7:$P$10000,$J$7:$J$10000=G$1+1),5, FALSE), 0)} -> 7.8230916 | F26: =RANK(E26,$E$20:$E$150) -> 6 | G26: =SUMIF(V:Z,$B26,Z:Z) -> 23.96318 | H26: =RANK($G26,$G$20:$G$106) -> 5 | I26: {=COUNT(_xlfn._xlws.FILTER($J$7:$J$10000,($L$7:$L$10000=B26)*($M$7:$M$10000<>"NULL")*($J$7:$J$10000 >= ($G$1-4))))/5} -> 0.2 | J26: 1 | K26: HOU | L26: Val Lee-Lo | M26: 2.6 | N26: Home | O26: CHI | P26: =VLOOKUP($N26,$F$3:$G$4,2,FALSE)+VLOOKUP($L26,$B$20:$C$150,2,FALSE)+VLOOKUP($O26,$A$6:$B$16,2,FALSE) -> 2.2835865 | Q26: =IFERROR(($M26-$P26)^2,"") -> 0.10011752 | R26: {=SUMPRODUCT((J26=$J$7:$J$1000)*(P26<$P$7:$P$1000))+1} -> 27 | T26: 14 | U26: HOU | V26: Seth Smith | W26: NULL | X26: Home | Y26: UTAH | Z26: 4.3904932
A27: =VLOOKUP($B27, PlayerIDs!$A$1:$B$1000, 2, FALSE) -> 642 | B27: Martin Vaca | C27: 7.7272766 | D27: =RANK($C27,$C$20:$C$106) -> 8 | E27: {=IFERROR(VLOOKUP($B27,_xlfn._xlws.FILTER($L$7:$P$10000,$J$7:$J$10000=G$1+1),5, FALSE), 0)} -> 8.2205632 | F27: =RANK(E27,$E$20:$E$150) -> 5 | G27: =SUMIF(V:Z,$B27,Z:Z) -> 24.264278 | H27: =RANK($G27,$G$20:$G$106) -> 4 | I27: {=COUNT(_xlfn._xlws.FILTER($J$7:$J$10000,($L$7:$L$10000=B27)*($M$7:$M$10000<>"NULL")*($J$7:$J$10000 >= ($G$1-4))))/5} -> 0.2 | J27: 1 | K27: NOLA | L27: Paul Mullen | M27: 2.6 | N27: Home | O27: ARC | P27: =VLOOKUP($N27,$F$3:$G$4,2,FALSE)+VLOOKUP($L27,$B$20:$C$150,2,FALSE)+VLOOKUP($O27,$A$6:$B$16,2,FALSE) -> 3.8580744 | Q27: =IFERROR(($M27-$P27)^2,"") -> 1.5827513 | R27: {=SUMPRODUCT((J27=$J$7:$J$1000)*(P27<$P$7:$P$1000))+1} -> 16 | T27: 14 | U27: HOU | V27: Val Lee-Lo | W27: NULL | X27: Home | Y27: UTAH | Z27: 0.96163835
A28: =VLOOKUP($B28, PlayerIDs!$A$1:$B$1000, 2, FALSE) -> 868 | B28: Justus Tavai | C28: 7.6533041 | D28: =RANK($C28,$C$20:$C$106) -> 9 | E28: {=IFERROR(VLOOKUP($B28,_xlfn._xlws.FILTER($L$7:$P$10000,$J$7:$J$10000=G$1+1),5, FALSE), 0)} -> 7.5484815 | F28: =RANK(E28,$E$20:$E$150) -> 7 | G28: =SUMIF(V:Z,$B28,Z:Z) -> 21.952114 | H28: =RANK($G28,$G$20:$G$106) -> 7 | I28: {=COUNT(_xlfn._xlws.FILTER($J$7:$J$10000,($L$7:$L$10000=B28)*($M$7:$M$10000<>"NULL")*($J$7:$J$10000 >= ($G$1-4))))/5} -> 0.2 | J28: 1 | K28: SEA | L28: Dewald Kotze | M28: 2.5 | N28: Away | O28: SDL | P28: =VLOOKUP($N28,$F$3:$G$4,2,FALSE)+VLOOKUP($L28,$B$20:$C$150,2,FALSE)+VLOOKUP($O28,$A$6:$B$16,2,FALSE) -> 6.6389312 | Q28: =IFERROR(($M28-$P28)^2,"") -> 17.130751 | R28: {=SUMPRODUCT((J28=$J$7:$J$1000)*(P28<$P$7:$P$1000))+1} -> 5 | T28: 14 | U28: LA | V28: Alessandro Heaney | W28: NULL | X28: Away | Y28: CHI | Z28: 3.3752318
A29: =VLOOKUP($B29, PlayerIDs!$A$1:$B$1000, 2, FALSE) -> 171 | B29: Hugh Roach | C29: 7.4089044 | D29: =RANK($C29,$C$20:$C$106) -> 10 | E29: {=IFERROR(VLOOKUP($B29,_xlfn._xlws.FILTER($L$7:$P$10000,$J$7:$J$10000=G$1+1),5, FALSE), 0)} -> 6.8049524 | F29: =RANK(E29,$E$20:$E$150) -> 12 | G29: =SUMIF(V:Z,$B29,Z:Z) -> 13.873707 | H29: =RANK($G29,$G$20:$G$106) -> 29 | I29: {=COUNT(_xlfn._xlws.FILTER($J$7:$J$10000,($L$7:$L$10000=B29)*($M$7:$M$10000<>"NULL")*($J$7:$J$10000 >= ($G$1-4))))/5} -> 1 | J29: 1 | K29: OGDC | L29: Cali Martinez | M29: 2.3 | N29: Away | O29: MIA | P29: =VLOOKUP($N29,$F$3:$G$4,2,FALSE)+VLOOKUP($L29,$B$20:$C$150,2,FALSE)+VLOOKUP($O29,$A$6:$B$16,2,FALSE) -> 2.9488127 | Q29: =IFERROR(($M29-$P29)^2,"") -> 0.42095794 | R29: {=SUMPRODUCT((J29=$J$7:$J$1000)*(P29<$P$7:$P$1000))+1} -> 23 | T29: 14 | U29: LA | V29: Ben Strang | W29: NULL | X29: Away | Y29: CHI | Z29: 10.947317
A30: =VLOOKUP($B30, PlayerIDs!$A$1:$B$1000, 2, FALSE) -> 801 | B30: Declan Leaney | C30: 7.1502017 | D30: =RANK($C30,$C$20:$C$106) -> 11 | E30: {=IFERROR(VLOOKUP($B30,_xlfn._xlws.FILTER($L$7:$P$10000,$J$7:$J$10000=G$1+1),5, FALSE), 0)} -> 7.0453792 | F30: =RANK(E30,$E$20:$E$150) -> 10 | G30: =SUMIF(V:Z,$B30,Z:Z) -> 20.442807 | H30: =RANK($G30,$G$20:$G$106) -> 10 | I30: {=COUNT(_xlfn._xlws.FILTER($J$7:$J$10000,($L$7:$L$10000=B30)*($M$7:$M$10000<>"NULL")*($J$7:$J$10000 >= ($G$1-4))))/5} -> 0.2 | J30: 1 | K30: LA | L30: Ben Sugars | M30: 1.9 | N30: Home | O30: NEFJ | P30: =VLOOKUP($N30,$F$3:$G$4,2,FALSE)+VLOOKUP($L30,$B$20:$C$150,2,FALSE)+VLOOKUP($O30,$A$6:$B$16,2,FALSE) -> 5.0056938 | Q30: =IFERROR(($M30-$P30)^2,"") -> 9.6453339 | R30: {=SUMPRODUCT((J30=$J$7:$J$1000)*(P30<$P$7:$P$1000))+1} -> 12 | T30: 14 | U30: LA | V30: Ben Sugars | W30: NULL | X30: Away | Y30: CHI | Z30: 4.597339
A31: =VLOOKUP($B31, PlayerIDs!$A$1:$B$1000, 2, FALSE) -> 787 | B31: Connal McInerney | C31: 7.1275856 | D31: =RANK($C31,$C$20:$C$106) -> 12 | E31: {=IFERROR(VLOOKUP($B31,_xlfn._xlws.FILTER($L$7:$P$10000,$J$7:$J$10000=G$1+1),5, FALSE), 0)} -> 6.7874354 | F31: =RANK(E31,$E$20:$E$150) -> 14 | G31: =SUMIF(V:Z,$B31,Z:Z) -> 20.028622 | H31: =RANK($G31,$G$20:$G$106) -> 11 | I31: {=COUNT(_xlfn._xlws.FILTER($J$7:$J$10000,($L$7:$L$10000=B31)*($M$7:$M$10000<>"NULL")*($J$7:$J$10000 >= ($G$1-4))))/5} -> 0 | J31: 1 | K31: MIA | L31: Sean McNulty | M31: 1.8 | N31: Home | O31: OGDC | P31: =VLOOKUP($N31,$F$3:$G$4,2,FALSE)+VLOOKUP($L31,$B$20:$C$150,2,FALSE)+VLOOKUP($O31,$A$6:$B$16,2,FALSE) -> 2.7087205 | Q31: =IFERROR(($M31-$P31)^2,"") -> 0.82577286 | R31: {=SUMPRODUCT((J31=$J$7:$J$1000)*(P31<$P$7:$P$1000))+1} -> 24 | T31: 14 | U31: LA | V31: Cronan Gleeson | W31: NULL | X31: Away | Y31: CHI | Z31: 0.20497369
... A103: =VLOOKUP($B103, PlayerIDs!$A$1:$B$1000, 2, FALSE) -> 641 | B103: Joe Wrafter | C103: -2.7317218 | D103: =RANK($C103,$C$20:$C$106) -> 84 | E103: {=IFERROR(VLOOKUP($B103,_xlfn._xlws.FILTER($L$7:$P$10000,$J$7:$J$10000=G$1+1),5, FALSE), 0)} -> -2.2384352 | F103: =RANK(E103,$E$20:$E$150) -> 84 | G103: =SUMIF(V:Z,$B103,Z:Z) -> -7.1127173 | H103: =RANK($G103,$G$20:$G$106) -> 84 | I103: {=COUNT(_xlfn._xlws.FILTER($J$7:$J$10000,($L$7:$L$10000=B103)*($M$7:$M$10000<>"NULL")*($J$7:$J$10000 >= ($G$1-4))))/5} -> 0 | J103: 4 | K103: SDL | L103: Darcy Breen | M103: 4.4 | N103: Home | O103: LA | P103: =VLOOKUP($N103,$F$3:$G$4,2,FALSE)+VLOOKUP($L103,$B$20:$C$150,2,FALSE)+VLOOKUP($O103,$A$6:$B$16,2,FALSE) -> 4.5273455 | Q103: =IFERROR(($M103-$P103)^2,"") -> 0.016216875 | R103: {=SUMPRODUCT((J103=$J$7:$J$1000)*(P103<$P$7:$P$1000))+1} -> 13 | T103: 15 | U103: HOU | V103: Val Lee-Lo | W103: NULL | X103: Away | Y103: SEA | Z103: 1.6316645
J104: 4 | K104: ARC | L104: Jake Turnbull | M104: 4.2 | N104: Away | O104: OGDC | P104: =VLOOKUP($N104,$F$3:$G$4,2,FALSE)+VLOOKUP($L104,$B$20:$C$150,2,FALSE)+VLOOKUP($O104,$A$6:$B$16,2,FALSE) -> 2.9250302 | Q104: =IFERROR(($M104-$P104)^2,"") -> 1.625548 | R104: {=SUMPRODUCT((J104=$J$7:$J$1000)*(P104<$P$7:$P$1000))+1} -> 21 | T104: 15 | U104: LA | V104: Alessandro Heaney | W104: NULL | X104: Home | Y104: MIA | Z104: 3.2926966
J105: 4 | K105: SEA | L105: Kerron van Vuuren | M105: 3.7 | N105: Home | O105: NEFJ | P105: =VLOOKUP($N105,$F$3:$G$4,2,FALSE)+VLOOKUP($L105,$B$20:$C$150,2,FALSE)+VLOOKUP($O105,$A$6:$B$16,2,FALSE) -> 4.8333719 | Q105: =IFERROR(($M105-$P105)^2,"") -> 1.2845319 | R105: {=SUMPRODUCT((J105=$J$7:$J$1000)*(P105<$P$7:$P$1000))+1} -> 12 | T105: 15 | U105: LA | V105: Ben Strang | W105: NULL | X105: Home | Y105: MIA | Z105: 10.864782
J106: 4 | K106: ARC | L106: Alex Maughan | M106: 3.6 | N106: Away | O106: OGDC | P106: =VLOOKUP($N106,$F$3:$G$4,2,FALSE)+VLOOKUP($L106,$B$20:$C$150,2,FALSE)+VLOOKUP($O106,$A$6:$B$16,2,FALSE) -> 2.7315822 | Q106: =IFERROR(($M106-$P106)^2,"") -> 0.75414947 | R106: {=SUMPRODUCT((J106=$J$7:$J$1000)*(P106<$P$7:$P$1000))+1} -> 22 | T106: 15 | U106: LA | V106: Ben Sugars | W106: NULL | X106: Home | Y106: MIA | Z106: 4.5148038
J107: 4 | K107: HOU | L107: Pono Davis | M107: 3.3 | N107: Away | O107: UTAH | P107: =VLOOKUP($N107,$F$3:$G$4,2,FALSE)+VLOOKUP($L107,$B$20:$C$150,2,FALSE)+VLOOKUP($O107,$A$6:$B$16,2,FALSE) -> 1.7294714 | Q107: =IFERROR(($M107-$P107)^2,"") -> 2.46656 | R107: {=SUMPRODUCT((J107=$J$7:$J$1000)*(P107<$P$7:$P$1000))+1} -> 24 | T107: 15 | U107: LA | V107: Cronan Gleeson | W107: NULL | X107: Home | Y107: MIA | Z107: 0.12243848
J108: 4 | K108: LA | L108: Maliu Niuafe | M108: 3.2 | N108: Away | O108: SDL | P108: =VLOOKUP($N108,$F$3:$G$4,2,FALSE)+VLOOKUP($L108,$B$20:$C$150,2,FALSE)+VLOOKUP($O108,$A$6:$B$16,2,FALSE) -> 3.6210704 | Q108: =IFERROR(($M108-$P108)^2,"") -> 0.17730027 | R108: {=SUMPRODUCT((J108=$J$7:$J$1000)*(P108<$P$7:$P$1000))+1} -> 18 | T108: 15 | U108: LA | V108: Dane Zander | W108: NULL | X108: Home | Y108: MIA | Z108: -1.1409229
J109: 4 | K109: HOU | L109: Val Lee-Lo | M109: 2.9 | N109: Away | O109: UTAH | P109: =VLOOKUP($N109,$F$3:$G$4,2,FALSE)+VLOOKUP($L109,$B$20:$C$150,2,FALSE)+VLOOKUP($O109,$A$6:$B$16,2,FALSE) -> 0.80884586 | Q109: =IFERROR(($M109-$P109)^2,"") -> 4.3729256 | R109: {=SUMPRODUCT((J109=$J$7:$J$1000)*(P109<$P$7:$P$1000))+1} -> 26 | T109: 15 | U109: LA | V109: Declan Leaney | W109: NULL | X109: Home | Y109: MIA | Z109: 6.962844
J110: 4 | K110: CHI | L110: Janus Venter | M110: 2.8 | N110: Away | O110: MIA | P110: =VLOOKUP($N110,$F$3:$G$4,2,FALSE)+VLOOKUP($L110,$B$20:$C$150,2,FALSE)+VLOOKUP($O110,$A$6:$B$16,2,FALSE) -> 3.7681384 | Q110: =IFERROR(($M110-$P110)^2,"") -> 0.93729197 | R110: {=SUMPRODUCT((J110=$J$7:$J$1000)*(P110<$P$7:$P$1000))+1} -> 16 | T110: 15 | U110: LA | V110: Franco van den Berg | W110: NULL | X110: Home | Y110: MIA | Z110: 2.2061847
J111: 4 | K111: CHI | L111: Faka'osi Pifeleti | M111: 2.7 | N111: Away | O111: MIA | P111: =VLOOKUP($N111,$F$3:$G$4,2,FALSE)+VLOOKUP($L111,$B$20:$C$150,2,FALSE)+VLOOKUP($O111,$A$6:$B$16,2,FALSE) -> 2.0285831 | Q111: =IFERROR(($M111-$P111)^2,"") -> 0.45080069 | R111: {=SUMPRODUCT((J111=$J$7:$J$1000)*(P111<$P$7:$P$1000))+1} -> 23 | T111: 15 | U111: LA | V111: Justus Tavai | W111: NULL | X111: Home | Y111: MIA | Z111: 7.4659463
...

Sheet SRvsDef
A1: SR vs Def 2025 | F1: Finished Week: | G1: 12
B2: 0
A3: Mean: | B3: =AVERAGE(B6:B49) -> 2.8834744e-08 | F3: Home | G3: 0.0072205678
A4: (highest rank is most helpful matchup) | F4: Away | G4: =-G3 -> -0.0072205678
A5: Team | B5: Rating | C5: Rank | Q5: =SUM($Q$7:$Q1000) -> 1908.2806
A6: ARC | B6: 0.80302206 | C6: =RANK($B6,$B$6:$B$16,0) -> 1 | J6: Rnd | K6: Team | L6: Player | M6: Points | N6: home | O6: Opp | P6: Forecast | Q6: Squared Error | R6: GroupRnk | T6: Remaining Games for ROFS Calc | AA6: Players | AB6: Rnd
A7: OGDC | B7: 0.60834287 | C7: =RANK($B7,$B$6:$B$16,0) -> 2 | J7: 1 | K7: MIA | L7: Mauro Rebussone | M7: 15.3 | N7: Home | O7: OGDC | P7: =VLOOKUP($N7,$F$3:$G$4,2,FALSE)+VLOOKUP($L7,$B$20:$C$150,2,FALSE)+VLOOKUP($O7,$A$6:$B$16,2,FALSE) -> 5.7876544 | Q7: =IFERROR(($M7-$P7)^2,"") -> 90.484719 | R7: {=SUMPRODUCT((J7=$J$7:$J$1000)*(P7<$P$7:$P$1000))+1} -> 3 | T7: {=_xlfn._xlws.FILTER($J$7:$P$10000,($J$7:$J$10000>$G$1)*($J$7:$J$10000<18))} -> 13 | U7: ARC | V7: Alejandro Martinez Tapia | W7: NULL | X7: Away | Y7: LA | Z7: 5.7267055 | AA7: {=_xlfn._xlws.SORT(_xlfn.UNIQUE($L$7:$L$10000))} -> Alejandro Martinez Tapia | AB7: {=COUNT(_xlfn._xlws.FILTER($J$7:$J$10000,($L$7:$L$10000=AA7)*($M$7:$M$10000<>"NULL")*($J$7:$J$10000 >= ($G$1-5))))/5} -> 0.6
A8: SDL | B8: 0.58397849 | C8: =RANK($B8,$B$6:$B$16,0) -> 3 | J8: 1 | K8: SDL | L8: Jed Holloway | M8: 12.9 | N8: Home | O8: SEA | P8: =VLOOKUP($N8,$F$3:$G$4,2,FALSE)+VLOOKUP($L8,$B$20:$C$150,2,FALSE)+VLOOKUP($O8,$A$6:$B$16,2,FALSE) -> 8.1535589 | Q8: =IFERROR(($M8-$P8)^2,"") -> 22.528703 | R8: {=SUMPRODUCT((J8=$J$7:$J$1000)*(P8<$P$7:$P$1000))+1} -> 1 | T8: 13 | U8: ARC | V8: Javon Camp Villalovos | W8: NULL | X8: Away | Y8: LA | Z8: 2.5835745 | AA8: Bill Whiteside | AB8: {=COUNT(_xlfn._xlws.FILTER($J$7:$J$10000,($L$7:$L$10000=AA8)*($M$7:$M$10000<>"NULL")*($J$7:$J$10000 >= ($G$1-5))))/5} -> 0.4
A9: SEA | B9: 0.18479679 | C9: =RANK($B9,$B$6:$B$16,0) -> 4 | J9: 1 | K9: CHI | L9: James Scott | M9: 11 | N9: Away | O9: HOU | P9: =VLOOKUP($N9,$F$3:$G$4,2,FALSE)+VLOOKUP($L9,$B$20:$C$150,2,FALSE)+VLOOKUP($O9,$A$6:$B$16,2,FALSE) -> 5.1375299 | Q9: =IFERROR(($M9-$P9)^2,"") -> 34.368556 | R9: {=SUMPRODUCT((J9=$J$7:$J$1000)*(P9<$P$7:$P$1000))+1} -> 7 | T9: 13 | U9: ARC | V9: Javon Camp Villalovos | W9: NULL | X9: Away | Y9: SDL | Z9: 3.1678253 | AA9: Braemar Murray | AB9: {=COUNT(_xlfn._xlws.FILTER($J$7:$J$10000,($L$7:$L$10000=AA9)*($M$7:$M$10000<>"NULL")*($J$7:$J$10000 >= ($G$1-5))))/5} -> 0.4
A10: CHI | B10: 0.1265176 | C10: =RANK($B10,$B$6:$B$16,0) -> 5 | J10: 1 | K10: NEFJ | L10: Sam Caird | M10: 9.3 | N10: Away | O10: LA | P10: =VLOOKUP($N10,$F$3:$G$4,2,FALSE)+VLOOKUP($L10,$B$20:$C$150,2,FALSE)+VLOOKUP($O10,$A$6:$B$16,2,FALSE) -> 5.0081578 | Q10: =IFERROR(($M10-$P10)^2,"") -> 18.41991 | R10: {=SUMPRODUCT((J10=$J$7:$J$1000)*(P10<$P$7:$P$1000))+1} -> 8 | T10: 13 | U10: ARC | V10: Mikey Grandy | W10: NULL | X10: Away | Y10: LA | Z10: 4.5574912 | AA10: Brandon Harvey | AB10: {=COUNT(_xlfn._xlws.FILTER($J$7:$J$10000,($L$7:$L$10000=AA10)*($M$7:$M$10000<>"NULL")*($J$7:$J$10000 >= ($G$1-5))))/5} -> 0.4
A11: LA | B11: -0.00027227026 | C11: =RANK($B11,$B$6:$B$16,0) -> 6 | J11: 1 | K11: LA | L11: Jason Damm | M11: 8.4 | N11: Home | O11: NEFJ | P11: =VLOOKUP($N11,$F$3:$G$4,2,FALSE)+VLOOKUP($L11,$B$20:$C$150,2,FALSE)+VLOOKUP($O11,$A$6:$B$16,2,FALSE) -> 7.4958213 | Q11: =IFERROR(($M11-$P11)^2,"") -> 0.81753904 | R11: {=SUMPRODUCT((J11=$J$7:$J$1000)*(P11<$P$7:$P$1000))+1} -> 2 | T11: 13 | U11: ARC | V11: Sam Golla | W11: NULL | X11: Away | Y11: LA | Z11: 6.3414277 | AA11: Callum Botchar | AB11: {=COUNT(_xlfn._xlws.FILTER($J$7:$J$10000,($L$7:$L$10000=AA11)*($M$7:$M$10000<>"NULL")*($J$7:$J$10000 >= ($G$1-5))))/5} -> 0.2
A12: HOU | B12: -0.017425638 | C12: =RANK($B12,$B$6:$B$16,0) -> 7 | J12: 1 | K12: NEFJ | L12: Piers von Dadelszen | M12: 7.2 | N12: Away | O12: LA | P12: =VLOOKUP($N12,$F$3:$G$4,2,FALSE)+VLOOKUP($L12,$B$20:$C$150,2,FALSE)+VLOOKUP($O12,$A$6:$B$16,2,FALSE) -> 3.929463 | Q12: =IFERROR(($M12-$P12)^2,"") -> 10.696412 | R12: {=SUMPRODUCT((J12=$J$7:$J$1000)*(P12<$P$7:$P$1000))+1} -> 13 | T12: 13 | U12: ARC | V12: Shawn Clark | W12: NULL | X12: Away | Y12: LA | Z12: 3.1315344 | AA12: Cam Dolan | AB12: {=COUNT(_xlfn._xlws.FILTER($J$7:$J$10000,($L$7:$L$10000=AA12)*($M$7:$M$10000<>"NULL")*($J$7:$J$10000 >= ($G$1-5))))/5} -> 0.8
A13: NEFJ | B13: -0.12054481 | C13: =RANK($B13,$B$6:$B$16,0) -> 8 | J13: 1 | K13: SEA | L13: Rhyno Herbst | M13: 5.3 | N13: Away | O13: SDL | P13: =VLOOKUP($N13,$F$3:$G$4,2,FALSE)+VLOOKUP($L13,$B$20:$C$150,2,FALSE)+VLOOKUP($O13,$A$6:$B$16,2,FALSE) -> 4.9861334 | Q13: =IFERROR(($M13-$P13)^2,"") -> 0.098512222 | R13: {=SUMPRODUCT((J13=$J$7:$J$1000)*(P13<$P$7:$P$1000))+1} -> 9 | T13: 13 | U13: ARC | V13: Viliami Vuli | W13: NULL | X13: Away | Y13: LA | Z13: 4.946202 | AA13: Charlie Hewitt | AB13: {=COUNT(_xlfn._xlws.FILTER($J$7:$J$10000,($L$7:$L$10000=AA13)*($M$7:$M$10000<>"NULL")*($J$7:$J$10000 >= ($G$1-5))))/5} -> 0.4
A14: MIA | B14: -0.5956791 | C14: =RANK($B14,$B$6:$B$16,0) -> 9 | J14: 1 | K14: HOU | L14: Nathan Den Hoedt | M14: 4 | N14: Home | O14: CHI | P14: =VLOOKUP($N14,$F$3:$G$4,2,FALSE)+VLOOKUP($L14,$B$20:$C$150,2,FALSE)+VLOOKUP($O14,$A$6:$B$16,2,FALSE) -> 5.4080251 | Q14: =IFERROR(($M14-$P14)^2,"") -> 1.9825346 | R14: {=SUMPRODUCT((J14=$J$7:$J$1000)*(P14<$P$7:$P$1000))+1} -> 6 | T14: 13 | U14: CHI | V14: Hamish Bain | W14: NULL | X14: Away | Y14: NEFJ | Z14: 4.1432377 | AA14: Chase Jones | AB14: {=COUNT(_xlfn._xlws.FILTER($J$7:$J$10000,($L$7:$L$10000=AA14)*($M$7:$M$10000<>"NULL")*($J$7:$J$10000 >= ($G$1-5))))/5} -> 0.4
A15: UTAH | B15: -0.76631347 | C15: =RANK($B15,$B$6:$B$16,0) -> 10 | J15: 1 | K15: MIA | L15: Federico Gutíerrez | M15: 3.9 | N15: Home | O15: OGDC | P15: =VLOOKUP($N15,$F$3:$G$4,2,FALSE)+VLOOKUP($L15,$B$20:$C$150,2,FALSE)+VLOOKUP($O15,$A$6:$B$16,2,FALSE) -> 3.7582235 | Q15: =IFERROR(($M15-$P15)^2,"") -> 0.02010059 | R15: {=SUMPRODUCT((J15=$J$7:$J$1000)*(P15<$P$7:$P$1000))+1} -> 14 | T15: 13 | U15: CHI | V15: James Scott | W15: NULL | X15: Away | Y15: NEFJ | Z15: 5.0344107 | AA15: Conor Keys | AB15: {=COUNT(_xlfn._xlws.FILTER($J$7:$J$10000,($L$7:$L$10000=AA15)*($M$7:$M$10000<>"NULL")*($J$7:$J$10000 >= ($G$1-5))))/5} -> 0
A16: NOLA | B16: -0.80642221 | C16: =RANK($B16,$B$6:$B$16,0) -> 11 | J16: 1 | K16: OGDC | L16: Tevita Naqali | M16: 3.3 | N16: Away | O16: MIA | P16: =VLOOKUP($N16,$F$3:$G$4,2,FALSE)+VLOOKUP($L16,$B$20:$C$150,2,FALSE)+VLOOKUP($O16,$A$6:$B$16,2,FALSE) -> 5.5202493 | Q16: =IFERROR(($M16-$P16)^2,"") -> 4.929507 | R16: {=SUMPRODUCT((J16=$J$7:$J$1000)*(P16<$P$7:$P$1000))+1} -> 5 | T16: 13 | U16: CHI | V16: Mason Flesch | W16: NULL | X16: Away | Y16: NEFJ | Z16: 5.20125 | AA16: Federico Gutíerrez | AB16: {=COUNT(_xlfn._xlws.FILTER($J$7:$J$10000,($L$7:$L$10000=AA16)*($M$7:$M$10000<>"NULL")*($J$7:$J$10000 >= ($G$1-5))))/5} -> 0.2
J17: 1 | K17: ARC | L17: Sam Golla | M17: 2.5 | N17: Away | O17: NOLA | P17: =VLOOKUP($N17,$F$3:$G$4,2,FALSE)+VLOOKUP($L17,$B$20:$C$150,2,FALSE)+VLOOKUP($O17,$A$6:$B$16,2,FALSE) -> 5.5352777 | Q17: =IFERROR(($M17-$P17)^2,"") -> 9.2129109 | R17: {=SUMPRODUCT((J17=$J$7:$J$1000)*(P17<$P$7:$P$1000))+1} -> 4 | T17: 13 | U17: HOU | V17: Johan Momsen | W17: NULL | X17: Away | Y17: SDL | Z17: 6.1758772 | AA17: Frank Lochore | AB17: {=COUNT(_xlfn._xlws.FILTER($J$7:$J$10000,($L$7:$L$10000=AA17)*($M$7:$M$10000<>"NULL")*($J$7:$J$10000 >= ($G$1-5))))/5} -> 0.8
J18: 1 | K18: OGDC | L18: Rob Harley | M18: 2.5 | N18: Away | O18: MIA | P18: =VLOOKUP($N18,$F$3:$G$4,2,FALSE)+VLOOKUP($L18,$B$20:$C$150,2,FALSE)+VLOOKUP($O18,$A$6:$B$16,2,FALSE) -> 3.6748017 | Q18: =IFERROR(($M18-$P18)^2,"") -> 1.380159 | R18: {=SUMPRODUCT((J18=$J$7:$J$1000)*(P18<$P$7:$P$1000))+1} -> 15 | T18: 13 | U18: HOU | V18: Justin Basson | W18: NULL | X18: Away | Y18: SDL | Z18: 3.0066136 | AA18: Gavin Thornbury | AB18: {=COUNT(_xlfn._xlws.FILTER($J$7:$J$10000,($L$7:$L$10000=AA18)*($M$7:$M$10000<>"NULL")*($J$7:$J$10000 >= ($G$1-5))))/5} -> 0.4
